Workbook

Sheet README
B1: Market Row | Refinance Underwriting Workbook
B2: Prepared September 1, 2026 | As of August 31, 2026 | Fictional evaluation material
B4: Color legend
B5: Yellow | C5: Editable assumption — change these to re-run the model.
B6: Green | C6: Computed output driven by formulas.
B7: Blue header | C7: Section header.
B9: Sheet map
B10: Assumptions | C10: All editable inputs. Change cap rate, sizing rate, EGI drivers, opex, reserves, loan terms here.
B11: Rent Roll | C11: Rent roll with authoritative amendment applied to Unit 101.
B12: T12 | C12: Trailing 12-month historical actuals (Sep-25 to Aug-26).
B13: Underwriting | C13: Underwritten EGI, opex, NOI, NCF — all live formulas from Assumptions.
B14: Loan Sizing | C14: LTV / DSCR / Debt Yield constraints, binding max, sources & uses, first-year DS.
B15: Sensitivity | C15: Combined downside (EGI -5% AND sizing +100 bps) and cap-rate +50 bps sensitivity.
B16: Fields | C16: Requested reporting fields with sources.
B20: Key output locations
B21: Cap rate | C21: Assumptions!C7
B22: Sizing rate (computed) | C22: Assumptions!C22
B23: Underwritten EGI | C23: Underwriting!C11
B24: Underwritten NOI (before reserves) | C24: Underwriting!C21
B25: Underwritten NCF | C25: Underwriting!C23
B26: Indicative value (cap rate) | C26: Loan Sizing!C7
B27: Maximum loan (binding) | C27: Loan Sizing!C18
B28: Cash to / (from) borrower | C28: Loan Sizing!C33
B31: Notes
B32: All figures derive from the supplied packet. Unit 101 monthly rent reflects the executed First Amendment (effective 8/1/2026) at $7,500. Insurance uses the fictional renewal quote of $27,600. This workbook is an internal-review underwriting model, not a lender commitment.

Sheet Assumptions
B1: MARKET ROW — EDITABLE ASSUMPTIONS
B3: Property
B4: Total rentable SF | C4: 23000 | D4: Sum of rent roll areas.
B5: Occupied SF | C5: 20200 | D5: Sum of 7 occupied units.
B6: Valuation
B7: Cap rate | C7: 0.065 | D7: Applied to UW NOI BEFORE reserves.
B8: Cap rate sensitivity delta (bps) | C8: 0.005 | D8: +50 bps stress case (workbook only).
B9: Underwriting — revenue
B10: Gross potential base rent (annual) | C10: 657600 | D10: Property plan — supplied scenario.
B11: Combined revenue loss % | C11: 0.06 | D11: Vacancy + concessions + bad debt.
B12: Other income / recoveries (annual) | C12: 150000 | D12: Add after revenue loss.
B13: Underwriting — operating expenses
B14: Real estate taxes | C14: 90000 | D14: Plan: $90,000.
B15: Property insurance | C15: 27600 | D15: Fictional renewal quote 8/25/2026.
B16: Utilities | C16: 19200 | D16: Use T12 actual.
B17: Repairs & maintenance | C17: 24000 | D17: T12 $28,800 less $4,800 one-time casualty cleanup.
B18: Payroll / contract labor | C18: 18000 | D18: Use T12 actual.
B19: Administrative / legal | C19: 14400 | D19: Use T12 actual.
B20: Management fee — T12 actual (floor) | C20: 24000 | D20: Greater of T12 actual and 4% of EGI.
B21: Management fee — % of EGI | C21: 0.04 | D21: Greater of T12 actual and 4% of EGI.
B22: Reserves
B23: Replacement reserves ($/SF/yr) | C23: 0.2 | D23: Plan: $0.20/SF; deducted after NOI.
B24: Loan terms — lender
B25: Contract rate (annual) | C25: 0.0625 | D25: Fixed contractual rate.
B26: Sizing rate floor | C26: 0.065 | D26: Greater of contract rate and floor.
B27: Sizing rate stress delta (bps) | C27: 0.01 | D27: +100 bps for combined downside.
B28: Amortization (years) | C28: 25 | D28: Monthly payments.
B29: Interest-only period (months) | C29: 0 | D29: Underwriting DSCR still uses amortizing DS.
B30: Maturity (months) | C30: 60 | D30: 5-year term.
B31: Origination fee | C31: 0.01 | D31: % of actual initial principal.
B32: Constraints
B33: Max LTV | C33: 0.65 | D33: Loan / indicative value.
B34: Min DSCR | C34: 1.25 | D34: NCF (after reserves) / amortizing DS at sizing rate.
B35: Min debt yield | C35: 0.09 | D35: NOI (before reserves) / loan.
B36: EGI downside % | C36: -0.05 | D36: For combined downside.
B37: Sources & Uses
B38: Existing debt payoff | C38: 3400000 | D38: Property plan.
B39: Fixed closing costs | C39: 48000 | D39: Property plan.
B41: Derived (formulas)
B42: Sizing rate (greater of contract & floor) | C42: =MAX(C25,C26)
...

Sheet Rent Roll
B1: RENT ROLL — as of 2026-08-31 (Unit 101 reflects executed First Amendment)
B3: Unit | C3: Tenant | D3: Area SF | E3: Status | F3: Rent Roll Monthly | G3: Effective Monthly* | H3: Market Monthly | I3: Lease Expiry
B4: 101 | C4: Tenant A LLC | D4: 1800 | E4: Occupied | F4: 7000 | G4: 7500 | H4: 7000 | I4: 2031-08-31
B5: 102 | C5: Tenant B LLC | D5: 2200 | E5: Occupied | F5: 5500 | G5: 5500 | H5: 5500 | I5: 2028-08-31
B6: 103 | C6: Tenant C LLC | D6: 2500 | E6: Occupied | F6: 6000 | G6: 6000 | H6: 6000 | I6: 2029-08-31
B7: 104 | C7: Tenant D LLC | D7: 3200 | E7: Occupied | F7: 7200 | G7: 7200 | H7: 7200 | I7: 2030-08-31
B8: 105 | C8: Tenant E LLC | D8: 4000 | E8: Occupied | F8: 9000 | G8: 9000 | H8: 9000 | I8: 2031-08-31
B9: 106 | C9: Tenant F LLC | D9: 5000 | E9: Occupied | F9: 10500 | G9: 10500 | H9: 10500 | I9: 2027-08-31
B10: 107 | C10: Tenant G LLC | D10: 1500 | E10: Occupied | F10: 3400 | G10: 3400 | H10: 3400 | I10: 2028-08-31
B11: 108 | C11: Vacant | D11: 2800 | E11: Vacant | F11: 0 | G11: 0 | H11: 5200
B12: TOTAL | D12: =SUM(D4:D11) | F12: =SUM(F4:F11) | G12: =SUM(G4:G11)
B14: Rent roll summary
B15: Space count (units) | C15: =COUNTA(B4:B11)
B16: Occupied count | C16: =COUNTIF(E4:E11,"Occupied")
B17: Total rentable SF | C17: =SUM(D4:D11)
B18: Occupied SF | C18: =SUMIF(E4:E11,"Occupied",D4:D11)
B19: Occupancy by count % | C19: =COUNTIF(E4:E11,"Occupied")/COUNTA(B4:B11)
B20: Occupancy by area % | C20: =SUMIF(E4:E11,"Occupied",D4:D11)/SUM(D4:D11)
B21: Rent roll monthly base (as printed) | C21: =SUM(F4:F11)
B22: Effective monthly base (post-amendment) | C22: =SUM(G4:G11)
B23: Effective annual base | C23: =SUM(G4:G11)*12
B24: * Effective Monthly for Unit 101 reflects executed First Amendment (8/1/2026: $7,500).

Sheet T12
B1: TRAILING 12-MONTH ACTUALS — September 2025 through August 2026
B3: Revenue
B4: Gross potential base rent | C4: 645600 | D4: T12 statement, Annual column
B5: Vacancy loss | C5: -46800 | D5: T12 statement
B6: Concessions | C6: -14400 | D6: T12 statement
B7: Bad debt | C7: -3600 | D7: T12 statement
B8: Other income / recoveries | C8: 142800 | D8: T12 statement
B9: Effective Gross Income (EGI) | C9: =SUM(C4:C8)
B11: Operating expenses
B12: Real estate taxes | C12: 86400
B13: Property insurance | C13: 25200
B14: Utilities | C14: 19200
B15: Repairs & maintenance | C15: 28800
B16: Payroll / contract labor | C16: 18000
B17: Administrative / legal | C17: 14400
B18: Management fee | C18: 24000
B19: Total operating expenses | C19: =SUM(C12:C18)
B21: NOI before replacement reserves | C21: =C9-C19
B22: Replacement reserves | C22: 9200
B23: NCF after reserves | C23: =C21-C22
B25: Memo — below NOI/NCF (not opex)
B26: Capital improvements | C26: 98000
B27: Loan P&I (existing) | C27: 294000
B28: Depreciation (noncash) | C28: 180000

Sheet Underwriting
B1: UNDERWRITING — Sept 2026 forward (live formulas from Assumptions)
B3: Revenue
B4: Gross potential base rent | C4: =Assumptions!C10
B5: Less: combined revenue loss (vacancy/conc/bad debt) | C5: =-Assumptions!C10*Assumptions!C11
B6: Effective gross rent | C6: =SUM(C4:C5)
B7: Other income / recoveries | C7: =Assumptions!C12
B8: Effective Gross Income (EGI) | C8: =C6+C7
B10: Operating expenses
B11: Real estate taxes | C11: =Assumptions!C14
B12: Property insurance (renewal quote) | C12: =Assumptions!C15
B13: Utilities | C13: =Assumptions!C16
B14: Repairs & maintenance (normalized) | C14: =Assumptions!C17
B15: Payroll / contract labor | C15: =Assumptions!C18
B16: Administrative / legal | C16: =Assumptions!C19
B17: Management fee (max of T12 & 4% EGI) | C17: =MAX(Assumptions!C20,Assumptions!C21*C8)
B18: Total operating expenses | C18: =SUM(C11:C17)
B20: NOI before replacement reserves | C20: =C8-C18
B21: Replacement reserves ($/SF × total SF) | C21: =Assumptions!C23*Assumptions!C4
B22: NCF after reserves | C22: =C20-C21

Sheet Loan Sizing
B1: LOAN SIZING — LTV / DSCR / Debt Yield (live formulas)
B3: Rates & valuation
B4: Contract rate | C4: =Assumptions!C25
B5: Sizing rate (greater of contract & floor) | C5: =MAX(Assumptions!C25,Assumptions!C26)
B6: Cap rate | C6: =Assumptions!C7
B7: Indicative value = UW NOI (before reserves) / cap rate | C7: =Underwriting!C20/C6
B9: Debt constants
B10: Amortization (months) | C10: =Assumptions!C28*12
B11: Monthly PMT per $1 principal at sizing rate | C11: =(C5/12)/(1-(1+C5/12)^-C10)
B12: Annual debt constant at sizing rate | C12: =C11*12
B13: Annual debt constant at contract rate | C13: =((C4/12)/(1-(1+C4/12)^-C10))*12
B15: Constraint maxima
B16: Max under LTV = value × max LTV | C16: =C7*Assumptions!C33
B17: Max under DSCR = NCF / (min DSCR × ADC sizing) | C17: =Underwriting!C22/(Assumptions!C34*C12)
B18: Max under Debt Yield = NOI / min DY | C18: =Underwriting!C20/Assumptions!C35
B19: MAXIMUM LOAN (min of three) | C19: =MIN(C16:C18)
B20: Binding constraint | C20: =IF(C19=C16,"LTV",IF(C19=C17,"DSCR","Debt yield"))
B22: Debt-service checks
B23: Sizing annual debt service (at sizing rate) | C23: =C19*C12
B24: Sizing DSCR (NCF / sizing DS) | C24: =Underwriting!C22/C23
B25: Sizing debt yield (NOI / loan) | C25: =Underwriting!C20/C19
B26: First-year contractual debt service (at contract rate, IO = 0) | C26: =C19*C13
B27: First-year contractual DSCR (NCF / first-year DS) | C27: =Underwriting!C22/C26
B29: Sources & Uses
B30: Loan proceeds (max loan) | C30: =C19
B31: Less: existing debt payoff | C31: =-Assumptions!C38
B32: Less: origination fee (% of loan) | C32: =-C19*Assumptions!C31
B33: Less: fixed closing costs | C33: =-Assumptions!C39
B34: Cash to / (from) borrower | C34: =SUM(C30:C33)

Sheet Sensitivity
B1: SENSITIVITY — Combined downside & cap-rate stress
C3: Base Case | D3: EGI -5% (mgmt recalc) | E3: Combined (EGI-5% + rate+100bps)
B4: EGI | C4: =Underwriting!C8 | D4: =C4*(1+Assumptions!C36) | E4: =C4*(1+Assumptions!C36)
B5: Management fee (max of T12 & 4% EGI) | C5: =MAX(Assumptions!C20,Assumptions!C21*C4) | D5: =MAX(Assumptions!C20,Assumptions!C21*D4) | E5: =MAX(Assumptions!C20,Assumptions!C21*E4)
B6: All other operating expenses (unchanged) | C6: =Assumptions!C14+Assumptions!C15+Assumptions!C16+Assumptions!C17+Assumptions!C18+Assumptions!C19 | D6: =Assumptions!C14+Assumptions!C15+Assumptions!C16+Assumptions!C17+Assumptions!C18+Assumptions!C19 | E6: =Assumptions!C14+Assumptions!C15+Assumptions!C16+Assumptions!C17+Assumptions!C18+Assumptions!C19
B7: Total operating expenses | C7: =C5+C6 | D7: =D5+D6 | E7: =E5+E6
B8: NOI before reserves | C8: =C4-C7 | D8: =D4-D7 | E8: =E4-E7
B9: Replacement reserves | C9: =Assumptions!C23*Assumptions!C4 | D9: =Assumptions!C23*Assumptions!C4 | E9: =Assumptions!C23*Assumptions!C4
B10: NCF after reserves | C10: =C8-C9 | D10: =D8-D9 | E10: =E8-E9
B12: Sizing rate | C12: =MAX(Assumptions!C25,Assumptions!C26) | D12: =MAX(Assumptions!C25,Assumptions!C26) | E12: =MAX(Assumptions!C25,Assumptions!C26)+Assumptions!C27
B13: Annual debt constant | C13: =((C12/12)/(1-(1+C12/12)^-(Assumptions!C28*12)))*12 | D13: =((D12/12)/(1-(1+D12/12)^-(Assumptions!C28*12)))*12 | E13: =((E12/12)/(1-(1+E12/12)^-(Assumptions!C28*12)))*12
B14: Cap rate (unchanged in combined downside) | C14: =Assumptions!C7 | D14: =Assumptions!C7 | E14: =Assumptions!C7
B15: Indicative value | C15: =C8/C14 | D15: =D8/D14 | E15: =E8/E14
B16: Max under LTV | C16: =C15*Assumptions!C33 | D16: =D15*Assumptions!C33 | E16: =E15*Assumptions!C33
B17: Max under DSCR | C17: =C10/(Assumptions!C34*C13) | D17: =D10/(Assumptions!C34*D13) | E17: =E10/(Assumptions!C34*E13)
B18: Max under Debt Yield | C18: =C8/Assumptions!C35 | D18: =D8/Assumptions!C35 | E18: =E8/Assumptions!C35
B19: MAXIMUM LOAN | C19: =MIN(C16,C17,C18) | D19: =MIN(D16,D17,D18) | E19: =MIN(E16,E17,E18)
B20: Binding constraint | C20: =IF(C19=C16,"LTV",IF(C19=C17,"DSCR","Debt yield")) | D20: =IF(D19=D16,"LTV",IF(D19=D17,"DSCR","Debt yield")) | E20: =IF(E19=E16,"LTV",IF(E19=E17,"DSCR","Debt yield"))
B22: Separate case — cap rate +50 bps (all other assumptions unchanged)
B23: Stressed cap rate | C23: =Assumptions!C7+Assumptions!C8
B24: Indicative value (stressed cap) | C24: =Underwriting!C20/C23
B25: Max under LTV (stressed cap) | C25: =C24*Assumptions!C33
B26: Max under DSCR (base rate) | C26: =Underwriting!C22/(Assumptions!C34*'Loan Sizing'!C12)
B27: Max under Debt Yield (base) | C27: =Underwriting!C20/Assumptions!C35
B28: MAXIMUM LOAN (cap +50 bps) | C28: =MIN(C25,C26,C27)
B29: Binding constraint | C29: =IF(C28=C25,"LTV",IF(C28=C26,"DSCR","Debt yield"))

Sheet Fields
B1: REQUESTED REPORTING FIELDS
B3: Field ID | C3: Value / formula | D3: Source
B4: space_count | C4: ='Rent Roll'!C15 | D4: Rent-Roll.xlsx, Rent Roll sheet
B5: occupied_count | C5: ='Rent Roll'!C16 | D5: Rent-Roll.xlsx, Rent Roll sheet
B6: total_area_sf | C6: ='Rent Roll'!C17 | D6: Rent-Roll.xlsx
B7: occupied_area_sf | C7: ='Rent Roll'!C18 | D7: Rent-Roll.xlsx
B8: occupancy_count_pct | C8: ='Rent Roll'!C19*100 | D8: Derived
B9: occupancy_area_pct | C9: ='Rent Roll'!C20*100 | D9: Derived
B10: rent_roll_monthly_base | C10: 48600 | D10: Rent-Roll.xlsx sum as printed (Unit 101 $7,000)
B11: effective_monthly_base | C11: ='Rent Roll'!C22 | D11: Rent-Roll.xlsx + Lease-File.pdf p.2 First Amendment ($7,500)
B12: t12_egi | C12: =T12!C9 | D12: T12-Statement.pdf Annual column
B13: t12_operating_expenses | C13: =T12!C19 | D13: T12-Statement.pdf
B14: t12_noi_before_reserves | C14: =T12!C21 | D14: Derived
B15: t12_reserves | C15: =T12!C22 | D15: T12-Statement.pdf
B16: t12_ncf | C16: =T12!C21-T12!C22 | D16: Derived
B17: uw_egi | C17: =Underwriting!C8 | D17: Property-and-Plan.pdf p.2
B18: uw_management_fee | C18: =Underwriting!C17 | D18: Plan: greater of T12 & 4% EGI
B19: uw_operating_expenses | C19: =Underwriting!C18 | D19: Derived
B20: uw_noi_before_reserves | C20: =Underwriting!C20 | D20: Derived
B21: uw_reserves | C21: =Assumptions!C23*Assumptions!C4 | D21: Plan: $0.20/SF × total SF
B22: uw_ncf | C22: =Underwriting!C22 | D22: Derived
B23: capitalization_value | C23: ='Loan Sizing'!C7 | D23: =UW NOI / cap rate
B24: contract_rate | C24: ='Loan Sizing'!C4 | D24: Lender-Terms.pdf
B25: sizing_rate | C25: ='Loan Sizing'!C5 | D25: Lender-Terms.pdf
B26: annual_debt_constant | C26: ='Loan Sizing'!C12 | D26: Derived
B27: ltv_limit | C27: ='Loan Sizing'!C16 | D27: Derived
B28: dscr_limit | C28: ='Loan Sizing'!C17 | D28: Derived
B29: debt_yield_limit | C29: ='Loan Sizing'!C18 | D29: Derived
B30: maximum_loan | C30: ='Loan Sizing'!C19 | D30: Min of three
B31: binding_constraint | C31: ='Loan Sizing'!C20 | D31: Derived
B32: sizing_annual_debt_service | C32: ='Loan Sizing'!C23 | D32: Derived
B33: sizing_dscr | C33: ='Loan Sizing'!C24 | D33: Derived
B34: sizing_debt_yield | C34: ='Loan Sizing'!C25 | D34: Derived
B35: first_year_debt_service | C35: ='Loan Sizing'!C26 | D35: Contract rate × ADC(contract) × loan
B36: cash_to_borrower | C36: ='Loan Sizing'!C34 | D36: Derived
B37: stress_uw_noi | C37: =Sensitivity!D8 | D37: EGI -5%, mgmt recalc — NOI before reserves
B38: stress_maximum_loan | C38: =Sensitivity!E19 | D38: EGI -5% AND sizing +100 bps
B39: subject_lease_monthly_rent | C39: 7500 | D39: Lease-File.pdf p.2 First Amendment
B40: subject_lease_expiry | C40: 2031-08-31 | D40: Lease-File.pdf §2 (renewal not exercised)
B41: subject_lease_deposit | C41: 15000 | D41: Lease-File.pdf §4
...
