Workbook

Sheet Inputs
A1: Market Row | Underwriting Inputs
A3: Income assumptions
A4: Gross potential base rent (annual) | B4: 624720
A5: Revenue loss % of GPR | B5: 0.06
A6: Other income (annual) | B6: 142500
A8: Management assumptions
A9: T12 management fee (annual) | B9: 24000
A10: Management fee % of EGI | B10: 0.04
A12: Operating expenses (UW)
A13: Real estate taxes (annual) | B13: 90000
A14: Property insurance (annual) | B14: 27600
A15: Utilities | B15: 19200
A16: Repairs and maintenance (UW) | B16: 24000
A17: Payroll / contract labor | B17: 18000
A18: Administrative / legal | B18: 14400
A20: Reserves and area
A21: Total rentable SF | B21: 23000
A22: Reserves $/SF/year | B22: 0.2
A24: Rates and sizing
A25: Cap rate | B25: 0.065
A26: Debt yield minimum | B26: 0.09
A27: Contract rate | B27: 0.0625
A28: Sizing rate | B28: 0.065
A29: Amortization years | B29: 25
A30: Interest-only months | B30: 0
A32: Transaction costs
A33: Existing debt payoff | B33: 3400000
A34: Fixed closing costs | B34: 48000
A35: Origination fee % of loan | B35: 0.01
A37: Evidence inputs
A38: Verified renewal insurance (annual) | B38: 27600

Sheet T12
A1: Market Row | Trailing twelve months (Sep 2025 - Aug 2026)
A3: Gross potential base rent | B3: 645600
A4: Vacancy loss | B4: -46800
A5: Concessions | B5: -14400
A6: Bad debt | B6: -3600
A7: Other income / recoveries | B7: 142800
A8: Effective gross income (EGI) | B8: =SUM(B3:B7) -> 723600
A10: Operating expenses (above NOI)
A11: Real estate taxes | B11: 86400
A12: Property insurance | B12: 25200
A13: Utilities | B13: 19200
A14: Repairs and maintenance | B14: 28800
A15: Payroll / contract labor | B15: 18000
A16: Administrative / legal | B16: 14400
A17: Management fee | B17: 24000
A18: Total operating expenses | B18: =SUM(B11:B17) -> 216000
A20: NOI before reserves | B20: =B8-B18 -> 507600
A21: Replacement reserves (T12) | B21: 9200
A22: NCF after reserves | B22: =B20-B21 -> 498400

Sheet Underwriting
A1: Market Row | Underwriting (Sep 2026 forward)
A3: Gross potential base rent (annual)
A4: =Inputs!B4 -> 624720
A5: Revenue loss % of GPR
A6: =Inputs!B5 -> 0.06
A7: Other income (annual)
A8: =Inputs!B6 -> 142500
A9: Effective gross income (EGI)
A10: =A4 - (A4*A6) + A8 -> 729736.8
A12: Operating expenses (UW)
A13: Real estate taxes
A14: =Inputs!B13 -> 90000
A15: Property insurance
A16: =Inputs!B14 -> 27600
A17: Utilities
A18: =Inputs!B15 -> 19200
A19: Repairs and maintenance
A20: =Inputs!B16 -> 24000
A21: Payroll / contract labor
A22: =Inputs!B17 -> 18000
A23: Administrative / legal
A24: =Inputs!B18 -> 14400
A25: Subtotal opex ex mgmt
A26: =SUM(A14,A16,A18,A20,A22,A24) -> 193200
A27: Management fee % of EGI
A28: =Inputs!B10 -> 0.04
A29: T12 management fee (actual)
A30: =Inputs!B9 -> 24000
A31: Calculated mgmt @ % of EGI
A32: =A10*A28 -> 29189.472
A33: Management fee (greater of)
A34: =MAX(A30,A32) -> 29189.472
A35: Total operating expenses
A36: =A26+A34 -> 222389.47
A37: NOI before reserves
A38: =A10-A36 -> 507347.33
A39: Reserves $/SF/year
A40: =Inputs!B22 -> 0.2
A41: Total rentable SF
A42: =Inputs!B21 -> 23000
...

Sheet Value & Sizing
A1: Market Row | Valuation and Loan Sizing
A3: Cap rate
A4: =Inputs!B25 -> 0.065
A5: Indicative value (NOI/cap)
A6: =Underwriting!A38/A4 -> 7805343.5
A7: LTV limit (65%)
A8: =0.65*A6 -> 5073473.3
A10: Debt yield minimum
A11: =Inputs!B26 -> 0.09
A12: Debt yield limit
A13: =Underwriting!A38/A11 -> 5637192.5
A15: Sizing rate
A16: =Inputs!B28 -> 0.065
A17: Amortization years
A18: =Inputs!B29 -> 25
A19: Annual debt constant
A20: =-12*PMT(A16/12,A18*12,1) -> 0.081024859
A22: NCF after reserves
A23: =Underwriting!A46 -> 502747.33
A24: DSCR minimum
A25: 1.25
A26: DSCR limit
A27: =A23/(A25*A20) -> 4963882.3
A29: Maximum loan (min of constraints)
A30: =MIN(A8,A13,A27) -> 4963882.3
A31: Binding constraint
A32: =IF(A30=A27,"DSCR",IF(A30=A8,"LTV","Debt yield")) -> DSCR
A34: Sizing annual debt service
A35: =A20*A30 -> 402197.86
A36: Sizing DSCR
A37: =A23/A35 -> 1.25
A38: Sizing debt yield
A39: =Underwriting!A38/A30 -> 0.10220777
A41: Contract rate
A42: =Inputs!B27 -> 0.0625
A43: First-year annual debt service (contract rate)
A44: =-12*PMT(A42/12,A18*12,A30) -> 392942.54
A46: Cash to/from borrower
A47: Origination fee % of loan
A48: =Inputs!B35 -> 0.01
...

Sheet Sensitivity
A1: Market Row | Sensitivity
A3: Base EGI | B3: =Underwriting!A10 -> 729736.8
A4: EGI down 5% | B4: =B3*0.95 -> 693249.96
A6: Mgmt % of EGI | B6: =Inputs!B10 -> 0.04
A7: T12 mgmt actual | B7: =Inputs!B9 -> 24000
A8: Opex ex mgmt (UW) | B8: =Underwriting!A26 -> 193200
A9: Mgmt fee (stress) | B9: =MAX(B7,B6*B4) -> 27729.998
A10: NOI before reserves (stress) | B10: =B4-(B8+B9) -> 472319.96
A11: Reserves (same $/SF) | B11: =Underwriting!A44 -> 4600
A12: NCF after reserves (stress) | B12: =B10-B11 -> 467719.96
A14: Cap rate | B14: =Inputs!B25 -> 0.065
A15: Value at cap (stress EGI) | B15: =B10/B14 -> 7266460.9
A16: LTV limit (65%) | B16: =0.65*B15 -> 4723199.6
A18: Debt yield minimum | B18: =Inputs!B26 -> 0.09
A19: Debt yield limit (stress) | B19: =B10/B18 -> 5247999.6
A21: Sizing rate (base +100 bps) | B21: =Inputs!B28+0.01 -> 0.075
A22: Annual debt constant (stress) | B22: =-12*PMT(B21/12,Inputs!B29*12,1) -> 0.088678941
A23: DSCR minimum | B23: 1.25
A24: DSCR limit (stress) | B24: =B12/(B23*B22) -> 4219445.6
A26: Maximum loan (combined downside) | B26: =MIN(B16,B19,B24) -> 4219445.6
A28: Value at cap +50 bps (for context) | B28: =Underwriting!A38/(Inputs!B25+0.005) -> 7247819
