Workbook
Name TotalSF: Assumptions!$B$3
Name UnitCount: Assumptions!$B$4
Name OccUnits: Assumptions!$B$5
Name OccSF: Assumptions!$B$6
Name T_GPR: Assumptions!$B$9
Name T_VAC: Assumptions!$B$10
Name T_CONC: Assumptions!$B$11
Name T_BD: Assumptions!$B$12
Name T_OI: Assumptions!$B$13
Name T_TAX: Assumptions!$B$14
Name T_INS: Assumptions!$B$15
Name T_UT: Assumptions!$B$16
Name T_RM: Assumptions!$B$17
Name T_PAY: Assumptions!$B$18
Name T_ADM: Assumptions!$B$19
Name T_MGMT: Assumptions!$B$20
Name T_RES: Assumptions!$B$21
Name U_GPR: Assumptions!$B$24
Name U_LOSS: Assumptions!$B$25
Name U_OI: Assumptions!$B$26
Name U_TAX: Assumptions!$B$27
Name U_INS: Assumptions!$B$28
Name U_UT: Assumptions!$B$29
Name U_RM: Assumptions!$B$30
Name U_PAY: Assumptions!$B$31
Name U_ADM: Assumptions!$B$32
Name U_MGMT_PCT: Assumptions!$B$33
Name U_RES_PSF: Assumptions!$B$34
Name L_CAP: Assumptions!$B$37
Name L_LTV: Assumptions!$B$38
Name L_DSCR: Assumptions!$B$39
Name L_DY: Assumptions!$B$40
Name L_CR: Assumptions!$B$41
Name L_SR_FLOOR: Assumptions!$B$42
Name L_AMORT: Assumptions!$B$43
Name L_IO: Assumptions!$B$44
Name L_MAT: Assumptions!$B$45
Name L_ORIG: Assumptions!$B$46
Name L_PAYOFF: Assumptions!$B$47
Name L_CLOSE: Assumptions!$B$48
Name S_EGI: Assumptions!$B$51
Name S_RATE: Assumptions!$B$52
Name S_CAP: Assumptions!$B$53
Name UW_EGI: Underwriting!$B$5
Name UW_MGMT: Underwriting!$B$13
Name UW_OPEX: Underwriting!$B$14
Name UW_NOI: Underwriting!$B$16
Name UW_RES: Underwriting!$B$17
Name UW_NCF: Underwriting!$B$18
Name UW_VAL: Underwriting!$B$20
Name MAX_LOAN: 'Loan Sizing'!$B$9
Name SIZ_RATE: 'Loan Sizing'!$B$3
Name ADC_SIZ: 'Loan Sizing'!$B$4

Sheet README
A1: Meadow Commerce | Refinance Underwriting Workbook
A2: As of | B2: August 31, 2026
A3: Property | B3: Meadow Commerce | 6100 Meadow Bench Parkway, Richmond, VA 23234 (fictional)
A4: Sponsor | B4: Meadow Commerce Owner LLC (fictional)
A5: Loan purpose | B5: First-mortgage refinance; cash-out if proceeds permit
A6: Currency | B6: USD; rates in decimal (workbook displays percent where noted)
A8: How to use this workbook
A9: Editable inputs | B9: All yellow-shaded cells on the Assumptions sheet are reviewer-editable.
A10: Key levers | B10: Change cap rate, sizing rate, EGI drivers (GPR, revenue loss %, other income) — every downstream figure recalculates.
A11: Loan sizing | B11: Loan Sizing sheet computes LTV, DSCR and Debt Yield limits from live NOI/NCF; binding constraint auto-selects the minimum.
A12: First-year DS | B12: First-year contractual debt service uses the contract rate and honors the 12-month IO period (interest-only).
A13: Sizing DS | B13: Sizing DSCR and sizing debt yield both use the amortizing debt constant at the sizing rate, per lender convention.
A14: Sensitivity | B14: Sensitivity sheet shows the combined downside (EGI -5% AND sizing rate +100 bps, cap rate unchanged) and a separate cap-rate +50 bps case.
A15: Sources & Uses | B15: Uses = existing payoff + origination fee (1% of principal) + fixed closing costs. Cash to borrower = loan - uses. Negative = cash-in.
A16: Provisional insurance | B16: $36,000 is the underwriting placeholder only; no verified renewal quote/binder was delivered.
A17: Renewal option (Unit 101) | B17: Not exercised in delivered materials. Current expiry remains 2028-08-31.
A19: Sheet map
A20: Assumptions | B20: All editable inputs (property, rent roll, T12 annual totals, underwriting scenario, lender terms). Named ranges used throughout.
A21: Rent Roll | B21: Unit-level rent roll and occupancy KPIs (formulas).
A22: T12 | B22: Historical annual T12 EGI, opex, NOI before/after reserves, NCF.
A23: Underwriting | B23: Underwritten EGI, management fee (greater-of), opex, NOI, NCF, capitalization value.
A24: Loan Sizing | B24: LTV / DSCR / Debt Yield tests, binding constraint, sizing DS, first-year DS, sources & uses, cash to borrower.
A25: Sensitivity | B25: Combined downside and a separate cap-rate +50 bps case.
A26: Field Report | B26: Every requested field ID mapped to its computed value with a source cite.
A28: Legend
A29: Yellow | B29: Editable input
A30: Green | B30: Key computed output

Sheet Assumptions
A1: Assumptions — editable inputs (yellow)
A2: Property
A3: Total rentable SF | B3: 72000 | D3: Rent-Roll.xlsx sum of E7:E9
A4: Unit / suite count | B4: 3 | D4: Rent-Roll.xlsx C7:C9
A5: Occupied unit count | B5: 3 | D5: Rent-Roll.xlsx F7:F9 = 'Occupied'
A6: Occupied SF | B6: 72000 | D6: Sum of Area SF where Status='Occupied'
A8: Historical T12 annual totals (Sep-2025 through Aug-2026)
A9: GPR | B9: 744000 | D9: T12-Statement.pdf p.2 annual
A10: Vacancy loss | B10: 0 | D10: T12-Statement.pdf p.2 annual
A11: Concessions (negative) | B11: -18000 | D11: T12-Statement.pdf p.2 annual
A12: Bad debt (negative) | B12: -2400 | D12: T12-Statement.pdf p.2 annual
A13: Other income / recoveries | B13: 158400 | D13: T12-Statement.pdf p.2 annual
A14: Real estate taxes | B14: 102000 | D14: T12-Statement.pdf p.2 annual
A15: Property insurance | B15: 26400 | D15: T12-Statement.pdf p.2 annual
A16: Utilities | B16: 9600 | D16: T12-Statement.pdf p.2 annual
A17: Repairs & maintenance | B17: 19200 | D17: T12-Statement.pdf p.2 annual
A18: Payroll / contract labor | B18: 12000 | D18: T12-Statement.pdf p.2 annual
A19: Administrative / legal | B19: 16800 | D19: T12-Statement.pdf p.2 annual
A20: Management fee (T12 actual) | B20: 26400 | D20: T12-Statement.pdf p.2 annual
A21: Replacement reserves (T12) | B21: 14400 | D21: T12-Statement.pdf p.2 annual
A23: Underwriting scenario
A24: Underwritten GPR | B24: 756000 | D24: Property-and-Plan.pdf p.2
A25: Revenue loss % of GPR | B25: 0.03 | D25: Property-and-Plan.pdf p.2 (vac+conc+bad debt)
A26: Other income / recoveries | B26: 162000 | D26: Property-and-Plan.pdf p.2
A27: Real estate taxes | B27: 108000 | D27: Property-and-Plan.pdf p.2
A28: Insurance (provisional allowance) | B28: 36000 | D28: Property-and-Plan.pdf p.2 — verified quote NOT delivered
A29: Utilities (T12 actual) | B29: 9600 | D29: Property-and-Plan.pdf p.2
A30: Repairs & maintenance (T12 actual) | B30: 19200 | D30: Property-and-Plan.pdf p.2
A31: Payroll / contract labor (T12 actual) | B31: 12000 | D31: Property-and-Plan.pdf p.2
A32: Administrative / legal (T12 actual) | B32: 16800 | D32: Property-and-Plan.pdf p.2
A33: Management minimum % of EGI | B33: 0.03 | D33: Property-and-Plan.pdf p.2 (greater-of vs T12 actual)
A34: Replacement reserves ($/SF/yr) | B34: 0.2 | D34: Property-and-Plan.pdf p.2
A36: Lender terms
A37: Cap rate (valuation) | B37: 0.065 | D37: Lender-Terms.pdf
A38: LTV maximum | B38: 0.6 | D38: Lender-Terms.pdf
A39: DSCR minimum | B39: 1.3 | D39: Lender-Terms.pdf
A40: Debt yield minimum | B40: 0.095 | D40: Lender-Terms.pdf
A41: Contract rate (fixed) | B41: 0.061 | D41: Lender-Terms.pdf
A42: Sizing rate floor | B42: 0.065 | D42: Lender-Terms.pdf (greater of contract & floor)
A43: Amortization (years) | B43: 30 | D43: Lender-Terms.pdf
...

Sheet Rent Roll
A1: Rent Roll — as of 2026-08-31 (source: Rent-Roll.xlsx)
A3: Unit / suite | B3: Tenant | C3: Area SF | D3: Status | E3: Monthly base rent | F3: Market monthly rent | G3: Lease expiry
A4: 101 | B4: Tenant A LLC | C4: 16000 | D4: Occupied | E4: 12800 | F4: 12800 | G4: 2028-08-31
A5: 102 | B5: Tenant B LLC | C5: 24000 | D5: Occupied | E5: 20400 | F5: 20400 | G5: 2028-08-31
A6: 103 | B6: Tenant C LLC | C6: 32000 | D6: Occupied | E6: 28800 | F6: 28800 | G6: 2029-08-31
A8: KPIs
A9: space_count | E9: =UnitCount
A10: occupied_count | E10: =OccUnits
A11: total_area_sf | E11: =TotalSF
A12: occupied_area_sf | E12: =OccSF
A13: occupancy_count_pct | E13: =OccUnits/UnitCount
A14: occupancy_area_pct | E14: =OccSF/TotalSF
A15: rent_roll_monthly_base | E15: =SUMPRODUCT((D4:D6="Occupied")*E4:E6)
A16: effective_monthly_base (lease-authoritative) | E16: =SUMPRODUCT((D4:D6="Occupied")*E4:E6)
A18: Notes
A19: • Effective monthly base equals lease-authoritative rent. Unit 101 lease confirms $12,800/mo; no renewal option exercised in the packet.

Sheet T12
A1: Historical T12 (Sep-2025 through Aug-2026)
A2: GPR | B2: =T_GPR
A3: Vacancy loss | B3: =T_VAC
A4: Concessions | B4: =T_CONC
A5: Bad debt | B5: =T_BD
A6: Other income / recoveries | B6: =T_OI
A7: EGI (historical) | B7: =T_GPR+T_VAC+T_CONC+T_BD+T_OI
A9: Real estate taxes | B9: =T_TAX
A10: Property insurance | B10: =T_INS
A11: Utilities | B11: =T_UT
A12: Repairs & maintenance | B12: =T_RM
A13: Payroll / contract labor | B13: =T_PAY
A14: Administrative / legal | B14: =T_ADM
A15: Management fee (T12 actual) | B15: =T_MGMT
A16: Operating expenses (excl. reserves/capex/debt/depr.) | B16: =T_TAX+T_INS+T_UT+T_RM+T_PAY+T_ADM+T_MGMT
A18: NOI before replacement reserves | B18: =B7-B16
A19: Less: replacement reserves | B19: =T_RES
A20: NCF after reserves | B20: =B18-T_RES
A22: Below-the-line reference items (not operating expense):
A23: Capital improvements (T12) | B23: 112000 | D23: T12-Statement.pdf p.2 annual
A24: Loan principal & interest (T12) | B24: 294000 | D24: T12-Statement.pdf p.2 annual
A25: Depreciation (noncash) | B25: 180000 | D25: T12-Statement.pdf p.2 annual

Sheet Underwriting
A1: Underwriting scenario — annual
A2: Underwritten GPR | B2: =U_GPR
A3: Less: revenue loss (vac/conc/bad debt) | B3: =-U_GPR*U_LOSS
A4: Plus: other income / recoveries | B4: =U_OI
A5: Underwritten EGI | B5: =B2+B3+B4 | D5: uw_egi
A7: Real estate taxes | B7: =U_TAX
A8: Insurance (provisional) | B8: =U_INS | D8: No renewal binder delivered — placeholder only
A9: Utilities | B9: =U_UT
A10: Repairs & maintenance | B10: =U_RM
A11: Payroll / contract labor | B11: =U_PAY
A12: Administrative / legal | B12: =U_ADM
A13: Management fee (greater of T12 actual or % of EGI) | B13: =MAX(T_MGMT,B5*U_MGMT_PCT) | D13: uw_management_fee
A14: Underwritten operating expenses (before reserves) | B14: =U_TAX+U_INS+U_UT+U_RM+U_PAY+U_ADM+B13 | D14: uw_operating_expenses
A16: NOI before replacement reserves | B16: =B5-B14 | D16: uw_noi_before_reserves
A17: Less: replacement reserves ($/SF/yr × SF) | B17: =U_RES_PSF*TotalSF | D17: uw_reserves
A18: NCF after reserves | B18: =B16-B17 | D18: uw_ncf
A20: Capitalization value (NOI before reserves / cap rate) | B20: =B16/L_CAP | D20: capitalization_value

Sheet Loan Sizing
A1: Loan sizing
A2: Contract rate | B2: =L_CR | D2: contract_rate
A3: Sizing rate (greater of contract & floor) | B3: =MAX(L_CR,L_SR_FLOOR) | D3: sizing_rate
A4: Annual debt constant (30-yr amort, monthly) | B4: =-12*PMT(B3/12,L_AMORT*12,1) | D4: annual_debt_constant
A6: LTV limit = LTV × value | B6: =L_LTV*UW_VAL | D6: ltv_limit
A7: DSCR limit = NCF / (DSCR × ADC) | B7: =UW_NCF/(L_DSCR*B4) | D7: dscr_limit
A8: Debt yield limit = NCF / DY | B8: =UW_NCF/L_DY | D8: debt_yield_limit
A9: Maximum loan = MIN of three constraints | B9: =MIN(B6,B7,B8) | D9: maximum_loan
A10: Binding constraint | B10: =IF(B9=B6,"LTV",IF(B9=B7,"DSCR","Debt yield")) | D10: binding_constraint
A12: Sizing annual debt service | B12: =B9*B4 | D12: sizing_annual_debt_service
A13: Sizing DSCR (NCF / DS) | B13: =UW_NCF/B12 | D13: sizing_dscr
A14: Sizing debt yield (NCF / Loan) | B14: =UW_NCF/B9 | D14: sizing_debt_yield
A16: First-year contractual debt service (12 mo IO at contract rate) | B16: =B9*L_CR | D16: first_year_debt_service
A17: Memo: interest-only period (months) | B17: =L_IO
A18: Memo: amortizing DS if IO were 0 (12 mo) | B18: =B9*B4 | D18: For reference only; year-1 is IO per lender term sheet.
A20: Sources & Uses
A21: Sources
A22: New first mortgage | B22: =B9
A23: Uses
A24: Existing debt payoff | B24: =L_PAYOFF
A25: Origination fee (1% × loan) | B25: =L_ORIG*B9
A26: Fixed closing costs | B26: =L_CLOSE
A27: Total uses | B27: =L_PAYOFF+L_ORIG*B9+L_CLOSE
A28: Cash to (from) borrower = Loan − Uses | B28: =B9-B27 | D28: Positive = cash to borrower; negative = cash in required

Sheet Sensitivity
A1: Sensitivity
A2: Combined downside: EGI × S_EGI AND sizing rate + S_RATE; cap rate unchanged; management recalculated
A3: Stress EGI | B3: =UW_EGI*S_EGI | D3: EGI × 0.95 by default
A4: Stress management fee (greater of T12 actual or % of stress EGI) | B4: =MAX(T_MGMT,B3*U_MGMT_PCT)
A5: Stress operating expenses (before reserves) | B5: =U_TAX+U_INS+U_UT+U_RM+U_PAY+U_ADM+B4
A6: stress_uw_noi (before reserves) | B6: =B3-B5 | D6: stress_uw_noi
A7: Stress NCF (after reserves) | B7: =B6-UW_RES
A8: Stress sizing rate | B8: =SIZ_RATE+S_RATE
A9: Stress annual debt constant | B9: =-12*PMT(B8/12,L_AMORT*12,1)
A10: Stress capitalization value (cap rate unchanged) | B10: =B6/L_CAP
A11: Stress LTV limit | B11: =L_LTV*B10
A12: Stress DSCR limit | B12: =B7/(L_DSCR*B9)
A13: Stress Debt-yield limit | B13: =B7/L_DY
A14: stress_maximum_loan | B14: =MIN(B11,B12,B13) | D14: stress_maximum_loan
A15: Stress binding constraint | B15: =IF(B14=B11,"LTV",IF(B14=B12,"DSCR","Debt yield"))
A17: Separate sensitivity: cap rate +S_CAP (all other inputs at base case)
A18: Adjusted cap rate | B18: =L_CAP+S_CAP
A19: Adjusted value | B19: =UW_NOI/B18
A20: Adjusted LTV limit | B20: =L_LTV*B19
A21: DSCR limit (base NCF/rate) | B21: =UW_NCF/(L_DSCR*ADC_SIZ)
A22: Debt yield limit (base) | B22: =UW_NCF/L_DY
A23: Cap-rate +50 bps maximum loan | B23: =MIN(B20,B21,B22)

Sheet Field Report
A1: Requested field IDs — computed values with source
A2: field_id | B2: value | C2: source / note
A3: space_count | B3: =UnitCount | C3: Rent-Roll.xlsx C7:C9 (three units)
A4: occupied_count | B4: =OccUnits | C4: Rent-Roll.xlsx F7:F9 all = 'Occupied'
A5: total_area_sf | B5: =TotalSF | C5: Rent-Roll.xlsx E7:E9 sum
A6: occupied_area_sf | B6: =OccSF | C6: Rent-Roll.xlsx E7:E9 sum (all occupied)
A7: occupancy_count_pct | B7: =OccUnits/UnitCount*100 | C7: Percent 0-100
A8: occupancy_area_pct | B8: =OccSF/TotalSF*100 | C8: Percent 0-100
A9: rent_roll_monthly_base | B9: ='Rent Roll'!E15 | C9: Rent-Roll.xlsx SUMPRODUCT Occupied
A10: effective_monthly_base | B10: ='Rent Roll'!E16 | C10: Lease-authoritative; matches rent roll; no amendments/option exercise in packet
A11: t12_egi | B11: =T_GPR+T_VAC+T_CONC+T_BD+T_OI | C11: T12-Statement.pdf p.2 annual column
A12: t12_operating_expenses | B12: =T_TAX+T_INS+T_UT+T_RM+T_PAY+T_ADM+T_MGMT | C12: T12-Statement.pdf p.2 annual (excl. reserves/capex/debt/depr.)
A13: t12_noi_before_reserves | B13: =(T_GPR+T_VAC+T_CONC+T_BD+T_OI)-(T_TAX+T_INS+T_UT+T_RM+T_PAY+T_ADM+T_MGMT) | C13: EGI − Opex
A14: t12_reserves | B14: =T_RES | C14: T12-Statement.pdf p.2 (below NOI)
A15: t12_ncf | B15: =(T_GPR+T_VAC+T_CONC+T_BD+T_OI)-(T_TAX+T_INS+T_UT+T_RM+T_PAY+T_ADM+T_MGMT)-T_RES | C15: NOI − reserves
A16: uw_egi | B16: =UW_EGI | C16: Property-and-Plan.pdf p.2 — GPR − 3% loss + Other income
A17: uw_management_fee | B17: =UW_MGMT | C17: Greater of T12 actual ($26,400) or 3% × UW EGI
A18: uw_operating_expenses | B18: =UW_OPEX | C18: Property-and-Plan.pdf p.2 categories (before reserves)
A19: uw_noi_before_reserves | B19: =UW_NOI | C19: UW EGI − UW opex
A20: uw_reserves | B20: =UW_RES | C20: $0.20/SF × 72,000 SF
A21: uw_ncf | B21: =UW_NCF | C21: UW NOI − reserves
A22: capitalization_value | B22: =UW_VAL | C22: UW NOI before reserves / 6.50% cap rate
A23: contract_rate | B23: =L_CR | C23: Lender-Terms.pdf (decimal)
A24: sizing_rate | B24: =MAX(L_CR,L_SR_FLOOR) | C24: Greater of contract & 6.50% floor
A25: annual_debt_constant | B25: =ADC_SIZ | C25: 12 × PMT at sizing rate, 30-yr monthly amort
A26: ltv_limit | B26: =L_LTV*UW_VAL | C26: 60% × indicative value
A27: dscr_limit | B27: =UW_NCF/(L_DSCR*ADC_SIZ) | C27: NCF / (1.30 × ADC)
A28: debt_yield_limit | B28: =UW_NCF/L_DY | C28: NCF / 9.50%
A29: maximum_loan | B29: =MAX_LOAN | C29: MIN of three constraints
A30: binding_constraint | B30: ='Loan Sizing'!B10 | C30: LTV
A31: sizing_annual_debt_service | B31: =MAX_LOAN*ADC_SIZ | C31: Max loan × ADC (sizing rate, amortizing)
A32: sizing_dscr | B32: =UW_NCF/(MAX_LOAN*ADC_SIZ) | C32: NCF / sizing DS
A33: sizing_debt_yield | B33: =UW_NCF/MAX_LOAN | C33: NCF / max loan
A34: first_year_debt_service | B34: =MAX_LOAN*L_CR | C34: 12 months IO × contract rate
A35: cash_to_borrower | B35: =MAX_LOAN-(L_PAYOFF+L_ORIG*MAX_LOAN+L_CLOSE) | C35: Loan − payoff − origination fee − closing
A36: stress_uw_noi | B36: =Sensitivity!B6 | C36: EGI −5% with management recalculated; other opex unchanged
A37: stress_maximum_loan | B37: =Sensitivity!B14 | C37: EGI −5% AND sizing rate +100 bps; cap rate unchanged; binding = DSCR
A38: subject_lease_monthly_rent | B38: 12800 | C38: Lease-File.pdf §3 (Unit 101)
A39: subject_lease_expiry | B39: 2028-08-31 | C39: Lease-File.pdf §2 (renewal option NOT exercised)
A40: subject_lease_deposit | B40: 25600 | C40: Lease-File.pdf §4
...
