Workbook

Sheet README
A1: Magnolia Terrace — Reconciled Underwriting Model — REVISION 2
A2: Original fictional evaluation material. No real transaction. As-of date: 2026-09-01. Supersedes the 2026-08-31 revision 1 model, which is retained unchanged in the audit archive.
A4: HOW TO USE THIS WORKBOOK
A5: Blue text | B5: Hardcoded input / scenario lever. Edit these.
A6: Yellow fill | B6: The three designated input cells named in the request.
A7: Black text | B7: Formula on the same sheet. Do not overwrite.
A8: Green text | B8: Link to another sheet in this workbook. Do not overwrite.
A10: DESIGNATED INPUT CELLS | B10: Location
A11: gross_potential_rent | B11: Inputs!B5
A12: cap_rate | B12: Inputs!B14
A13: sizing_rate | B13: Inputs!B17
A15: DESIGNATED OUTPUT CELLS | B15: Location
A16: uw_egi | B16: Underwriting!B8
A17: uw_noi | B17: Underwriting!B15
A18: uw_ncf | B18: Underwriting!B17
... A21: net_cash_out | B21: Debt!B30
A23: SHEETS
A24: Revision Log | B24: What changed in revision 2, what did not, and why.
A25: Inputs | B25: All assumptions, each in its own labeled cell, with source.
A26: Rent Roll | B26: REVISED certified roll as of 2026-09-01 with the executed Suite 001 amendment.
A27: Underwriting | B27: EGI / NOI / NCF bridge and direct capitalization.
A28: Debt | B28: Three-constraint loan sizing and sources & uses.
A29: Historical | B29: T-12 cash operating statement as reported, vs underwritten.
A30: Sensitivity | B30: Value and maximum loan across cap rate and sizing rate.
A31: Fields | B31: The 38 named reporting fields with evidence locations.
A32: Sources | B32: Source register — every document, what it governs, what it does not.
A34: REVISION 2 SUMMARY | B34: Per revision-notice.pdf
A35: Roll superseded | B35: rent-roll-revised.xlsx (2026-09-01) replaces rent-roll-certified.xlsx (2026-08-31).
A36: Suite 045 | B36: Now active. Scheduled rent up $225 to $2,150. Pending count falls to zero.
... A41: DEFINITIONAL NOTE | B41: Reported T-12 NOI, underwritten NOI and NCF are three different
B42: measures and are labeled separately throughout. Reported T-12 NOI is a
B43: historical cash result; underwritten NOI is a forward prescribed
B44: assumption before reserves; NCF is underwritten NOI after reserves.

Sheet Revision Log
A1: Revision 2 Change Log
A2: Source: revision-notice.pdf p.1 and rent-roll-revised.xlsx, both effective 2026-09-01. The revision 1 model dated 2026-08-31 is retained unchanged in the audit archive and is not overwritten.
A4: Field / item | B4: Revision 1 (2026-08-31) | C4: Revision 2 (2026-09-01) | D4: Change | E4: Driver
A5: INSTRUCTED CHANGES
A6: selected_roll_date | B6: 2026-08-31 | C6: 2026-09-01 | D6: Superseded | E6: Revised roll supersedes the prior certified roll.
A7: cap_rate | B7: 0.0575 | C7: 0.0600 | D7: +25 bp | E7: Directly instructed.
A8: sizing_rate | B8: 0.0625 | C8: 0.0700 | D8: +75 bp | E8: Initial sizing rate plus 75 bp, as instructed.
A9: Suite 045 possession | B9: pending | C9: active | D9: Took possession | E9: Directly instructed.
A10: Suite 045 monthly rent | B10: $1,925 | C10: $2,150 | D10: +$225 | E10: Directly instructed.
A12: CONSEQUENTIAL CHANGES
A13: occupied_units | B13: 44 | C13: 45 | D13: +1 | E13: Suite 045 possession.
A14: pending_units | B14: 1 | C14: 0 | D14: -1 | E14: Suite 045 possession. A true zero, not unknown.
A15: occupied_area_sf | B15: 37,220 | C15: 38,250 | D15: +1,030 | E15: The 1,030 SF of Suite 045.
A16: unit_occupancy | B16: 0.9167 | C16: 0.9375 | D16: +0.0208 | E16: 45 of 48.
A17: area_occupancy | B17: 0.9123 | C17: 0.9375 | D17: +0.0252 | E17: Now equal to unit occupancy: 15 of each plan occupied.
A18: type_c_occupied | B18: 14 | C18: 15 | D18: +1 | E18: Suite 045 is a 2BR.
A19: annual_in_place_rent | B19: $894,600 | C19: $920,400 | D19: +$25,800 | E19: Suite 045 added at $2,150 x 12, plus its $225 increase.
A20: gross_potential_rent | B20: $974,400 | C20: $977,100 | D20: +$2,700 | E20: Suite 045 rent increase x 12. Possession does not affect GPR, which credits all 48 either way.
A21: uw_egi | B21: $942,480 | C21: $945,045 | D21: +$2,565 | E21: GPR uplift net of the 5% loss factor.
A22: uw_operating_expenses | B22: $301,106.40 | C22: $301,183.35 | D22: +$76.95 | E22: Only the 3% management fee moved.
A23: uw_noi | B23: $641,373.60 | C23: $643,861.65 | D23: +$2,488.05 | E23: EGI uplift less the management fee increment.
A24: uw_ncf | B24: $626,973.60 | C24: $629,461.65 | D24: +$2,488.05 | E24: Reserves unchanged at $14,400.
... A32: risk_pending_in_occupancy | B32: present | C32: absent | D32: Resolved | E32: No pending suite remains to be miscounted.
A34: EXPRESSLY UNCHANGED
A35: unit_001_monthly_rent | B35: $1,850 | C35: $1,850 | D35: None | E35: Revision notice states prior executed Suite 001 amendments continue to apply.
A36: total_units / total_area_sf | B36: 48 / 40,800 | C36: 48 / 40,800 | D36: None | E36: No suite added or removed.
A37: type_a/b/c_units | B37: 16 / 16 / 16 | C37: 16 / 16 / 16 | D37: None | E37: Mix unchanged.
A38: type_a_occupied / type_b_occupied | B38: 15 / 15 | C38: 15 / 15 | D38: None | E38: Only a 2BR changed status.
A39: uw_tax / uw_insurance | B39: $102,312 / $34,104 | C39: $102,312 / $34,104 | D39: None | E39: All other underwriting rules unchanged.
A40: Other recurring expenses | B40: $136,416 | C40: $136,416 | D40: None | E40: Unchanged.
A41: Reserves per unit | B41: $300 | C41: $300 | D41: None | E41: Unchanged.
A42: ltv_limit / dscr_limit / debt_yield_limit | B42: 0.65 / 1.25 / 0.09 | C42: 0.65 / 1.25 / 0.09 | D42: None | E42: Loan constraints unchanged.
A43: Note rate (original) / floor | B43: 6.2500% / 6.0000% | C43: 6.2500% / 6.0000% | D43: None | E43: Retained for the floor-binding test, which uses the ORIGINAL note rate.
A44: Existing payoff / closing costs | B44: $4,200,000 / $45,000 | C44: $4,200,000 / $45,000 | D44: None | E44: Revision states payoff remains unchanged.
A45: reported_t12_noi | B45: $604,128 | C45: $604,128 | D45: None | E45: No revised operating statement supplied.
A46: insurance_policy_limit | B46: $2,000,000 | C46: $2,000,000 | D46: None | E46: No revised insurance record supplied.
... A49: Missing diligence items | B49: All open | C49: All open | D49: None | E49: No photos, price, comps, sponsor history, or completed legal/environmental/PCA/title work was supplied with the revision.

Sheet Inputs
A1: Underwriting Inputs & Assumptions
A2: Every figure below is traceable to a packet document. No market comps, asking price, sponsor history or photos are supplied or assumed.
A4: Assumption | B4: Value | C4: Unit | D4: Source (file / location) | E4: Note
A5: gross_potential_rent (all-suite scheduled rent x 12) | B5: 977100 | C5: USD/yr | D5: revision-notice.pdf p.1; rent-roll-revised.xlsx E5:E52 | E5: REVISED. All 48 suites on the new roll, BEFORE the Suite 001 amendment: ($24,000 + $26,400 + $28,875 + $2,150) = $81,425 x 12. Was $974,400.
A6: Economic loss (vacancy + credit) | B6: 0.05 | C6: of GPR | D6: underwriting-instructions.pdf p.1 | E6: Prescribed 5%.
A7: Other income per unit/suite | B7: 350 | C7: USD/yr | D7: underwriting-instructions.pdf p.1 | E7: Reimbursement income already inside GPR; not added twice.
A8: Unit / suite count | B8: 48 | C8: units | D8: rent-roll-certified.xlsx A5:A52 | E8: 48 suites on the certified roll.
A9: uw_tax — real estate tax | B9: 102312 | C9: USD/yr | D9: underwriting-instructions.pdf p.1; operating-statement.pdf p.1 | E9: Prescribed; equals T-12 actual.
A10: uw_insurance — insurance expense | B10: 34104 | C10: USD/yr | D10: underwriting-instructions.pdf p.1; operating-statement.pdf p.1 | E10: Expense, NOT the $2,000,000 policy limit.
A11: Other recurring operating expenses | B11: 136416 | C11: USD/yr | D11: underwriting-instructions.pdf p.1; operating-statement.pdf p.1 | E11: Prescribed; equals T-12 actual.
A12: Management fee | B12: 0.03 | C12: of EGI | D12: underwriting-instructions.pdf p.1 | E12: 3% of underwritten EGI.
A13: Replacement reserve per unit/suite | B13: 300 | C13: USD/yr | D13: underwriting-instructions.pdf p.1 | E13: Below the NOI line; NOI is capitalized BEFORE reserves.
A14: cap_rate | B14: 0.06 | C14: decimal | D14: revision-notice.pdf p.1 | E14: REVISED. Initial 5.7500% plus 25 bp. Applied to NOI before reserves.
A15: Note rate (original, unchanged) | B15: 0.0625 | C15: decimal | D15: underwriting-instructions.pdf p.1 | E15: 6.2500%. Retained for the risk_sizing_floor_binding test, which compares the ORIGINAL note rate against the floor.
A16: Underwriting rate floor | B16: 0.06 | C16: decimal | D16: underwriting-instructions.pdf p.1 | E16: 6.0000%.
... A26: Suite 001 amendment — monthly rent increase | B26: 350 | C26: USD/mo | D26: lease-correspondence.pdf p.1 | E26: Signed 2026-07-20, effective 2026-08-01. In force at the as-of date.
A27: Near-term rollover horizon (inclusive) | B27: 2027-08-31 | C27: date | D27: underwriting-instructions.pdf p.1 | E27: Twelve months from the revised 2026-09-01 as-of date. Active suite expiry on or before this date is near-term.
A28: Suite 045 scheduled rent increase (revision 2) | B28: 225 | C28: USD/mo | D28: revision-notice.pdf p.1; rent-roll-revised.xlsx E49 | E28: $1,925 to $2,150. Suite 045 also moves from pending to active.
A30: REVISION 2 RATE DERIVATION
A31: Initial capitalization rate | B31: 0.0575 | D31: underwriting-instructions.pdf p.1
A32: Revision adjustment | B32: 0.0025 | D32: revision-notice.pdf p.1 — plus 25 basis points
A33: Revised cap_rate (ties to B14) | B33: =B31+B32 -> 0.06 | C33: =IF(B33=B14,"OK","CHECK") -> OK | D33: Check in C33
A34: Initial sizing rate (greater of note and floor) | B34: =MAX(B15,B16) -> 0.0625 | D34: 6.2500%
A35: Revision adjustment | B35: 0.0075 | D35: revision-notice.pdf p.1 — plus 75 basis points
A36: Revised sizing_rate (ties to B17) | B36: =B34+B35 -> 0.07 | C36: =IF(B36=B17,"OK","CHECK") -> OK | D36: Check in C36
A38: INTERNAL CHECKS
A39: sizing_rate still exceeds the rate floor | B39: =IF(B17>=MAX(B15,B16),"OK","CHECK") -> OK
A40: gross_potential_rent ties to revised roll x 12 (pre-amendment) | B40: =IF(B5='Rent Roll'!H55*12,"OK","CHECK") -> OK
A41: Suite count ties to revised roll | B41: =IF(B8=COUNTA('Rent Roll'!A5:A52),"OK","CHECK") -> OK
A42: Pending suites now zero (a true zero, not unknown) | B42: =IF('Rent Roll'!H61=0,"OK","CHECK") -> OK

Sheet Rent Roll
A1: Controlling Rent Roll — REVISED Certified, as of 2026-09-01
A2: Source: rent-roll-revised.xlsx (selected, 2026-09-01). It SUPERSEDES rent-roll-certified.xlsx (2026-08-31), which in turn superseded rent-roll-archive.xlsx (2026-06-30). Both prior rolls are excluded. Certified detail controls physical occupancy (manager-cover.pdf p.1).
A4: Suite | B4: Unit type | C4: Group | D4: Area SF | E4: Possession | F4: Certified monthly rent | G4: Executed amendment | H4: Controlling monthly rent | I4: Lease expiration | J4: Near-term rollover? | K4: Note
A5: 001 | B5: Studio | C5: A | D5: 700 | E5: active | F5: 1500 | G5: =Inputs!B26 -> 350 | H5: =F5+G5 -> 1850 | I5: 2029-08-31 | J5: =IF(AND(E5="active",I5<=Inputs!$B$27),"Yes","No") -> No | K5: Executed amendment +$350/mo effective 2026-08-01
A6: 002 | B6: 1BR | C6: B | D6: 820 | E6: active | F6: 1650 | G6: 0 | H6: =F6+G6 -> 1650 | I6: 2029-08-31 | J6: =IF(AND(E6="active",I6<=Inputs!$B$27),"Yes","No") -> No
A7: 003 | B7: 2BR | C7: C | D7: 1030 | E7: active | F7: 1925 | G7: 0 | H7: =F7+G7 -> 1925 | I7: 2029-08-31 | J7: =IF(AND(E7="active",I7<=Inputs!$B$27),"Yes","No") -> No
A8: 004 | B8: Studio | C8: A | D8: 700 | E8: active | F8: 1500 | G8: 0 | H8: =F8+G8 -> 1500 | I8: 2029-08-31 | J8: =IF(AND(E8="active",I8<=Inputs!$B$27),"Yes","No") -> No
A9: 005 | B9: 1BR | C9: B | D9: 820 | E9: active | F9: 1650 | G9: 0 | H9: =F9+G9 -> 1650 | I9: 2029-08-31 | J9: =IF(AND(E9="active",I9<=Inputs!$B$27),"Yes","No") -> No
A10: 006 | B10: 2BR | C10: C | D10: 1030 | E10: active | F10: 1925 | G10: 0 | H10: =F10+G10 -> 1925 | I10: 2029-08-31 | J10: =IF(AND(E10="active",I10<=Inputs!$B$27),"Yes","No") -> No
A11: 007 | B11: Studio | C11: A | D11: 700 | E11: active | F11: 1500 | G11: 0 | H11: =F11+G11 -> 1500 | I11: 2029-08-31 | J11: =IF(AND(E11="active",I11<=Inputs!$B$27),"Yes","No") -> No
A12: 008 | B12: 1BR | C12: B | D12: 820 | E12: active | F12: 1650 | G12: 0 | H12: =F12+G12 -> 1650 | I12: 2029-08-31 | J12: =IF(AND(E12="active",I12<=Inputs!$B$27),"Yes","No") -> No
A13: 009 | B13: 2BR | C13: C | D13: 1030 | E13: active | F13: 1925 | G13: 0 | H13: =F13+G13 -> 1925 | I13: 2029-08-31 | J13: =IF(AND(E13="active",I13<=Inputs!$B$27),"Yes","No") -> No
A14: 010 | B14: Studio | C14: A | D14: 700 | E14: active | F14: 1500 | G14: 0 | H14: =F14+G14 -> 1500 | I14: 2029-08-31 | J14: =IF(AND(E14="active",I14<=Inputs!$B$27),"Yes","No") -> No
A15: 011 | B15: 1BR | C15: B | D15: 820 | E15: active | F15: 1650 | G15: 0 | H15: =F15+G15 -> 1650 | I15: 2029-08-31 | J15: =IF(AND(E15="active",I15<=Inputs!$B$27),"Yes","No") -> No
A16: 012 | B16: 2BR | C16: C | D16: 1030 | E16: active | F16: 1925 | G16: 0 | H16: =F16+G16 -> 1925 | I16: 2029-08-31 | J16: =IF(AND(E16="active",I16<=Inputs!$B$27),"Yes","No") -> No
A17: 013 | B17: Studio | C17: A | D17: 700 | E17: active | F17: 1500 | G17: 0 | H17: =F17+G17 -> 1500 | I17: 2029-08-31 | J17: =IF(AND(E17="active",I17<=Inputs!$B$27),"Yes","No") -> No
... A48: 044 | B48: 1BR | C48: B | D48: 820 | E48: active | F48: 1650 | G48: 0 | H48: =F48+G48 -> 1650 | I48: 2029-08-31 | J48: =IF(AND(E48="active",I48<=Inputs!$B$27),"Yes","No") -> No
A49: 045 | B49: 2BR | C49: C | D49: 1030 | E49: active | F49: 2150 | G49: 0 | H49: =F49+G49 -> 2150 | I49: 2029-08-31 | J49: =IF(AND(E49="active",I49<=Inputs!$B$27),"Yes","No") -> No | K49: REVISION 2: now active; scheduled rent +$225 to $2,150
A50: 046 | B50: Studio | C50: A | D50: 700 | E50: vacant | F50: 1500 | G50: 0 | H50: =F50+G50 -> 1500 | I50: 2029-08-31 | J50: =IF(AND(E50="active",I50<=Inputs!$B$27),"Yes","No") -> No
A51: 047 | B51: 1BR | C51: B | D51: 820 | E51: vacant | F51: 1650 | G51: 0 | H51: =F51+G51 -> 1650 | I51: 2029-08-31 | J51: =IF(AND(E51="active",I51<=Inputs!$B$27),"Yes","No") -> No
A52: 048 | B52: 2BR | C52: C | D52: 1030 | E52: vacant | F52: 1925 | G52: 0 | H52: =F52+G52 -> 1925 | I52: 2029-08-31 | J52: =IF(AND(E52="active",I52<=Inputs!$B$27),"Yes","No") -> No
A54: TOTALS / COUNTS
A55: Scheduled rent, ALL 48 suites, certified (pre-amendment) | H55: =SUM(F5:F52) -> 81425 | K55: gross_potential_rent basis / 12
A56: Controlling monthly rent, ALL 48 suites (post-amendment) | H56: =SUM(H5:H52) -> 81775 | K56: Not the underwriting GPR basis
A57: In-place monthly rent, ACTIVE suites only (post-amendment) | H57: =SUMIF($E$5:$E$52,"active",H5:H52) -> 76700 | K57: annual_in_place_rent / 12
A58: annual_in_place_rent | H58: =H57*12 -> 920400 | K58: Active suites, executed amendment applied
A59: total_units | H59: =COUNTA(A5:A52) -> 48
A60: occupied_units (active possession) | H60: =COUNTIF($E$5:$E$52,"active") -> 45 | K60: Physical occupancy
A61: pending_units (not in possession) | H61: =COUNTIF($E$5:$E$52,"pending") -> 0 | K61: Zero after revision 2 — a true zero, not unknown
A62: vacant_units | H62: =COUNTIF($E$5:$E$52,"vacant") -> 3
A63: total_area_sf | H63: =SUM(D5:D52) -> 40800
A64: occupied_area_sf | H64: =SUMIF($E$5:$E$52,"active",D5:D52) -> 38250 | K64: Active suites only
A65: unit_occupancy | H65: =H60/H59 -> 0.9375 | K65: Decimal
A66: area_occupancy | H66: =H64/H63 -> 0.9375 | K66: Decimal
A67: Manager headline leased count (occupied + pending) | H67: =H60+H61 -> 45 | K67: Now 45 = 45 occupied + 0 pending. The manager headline and physical occupancy have converged
A68: Active suites expiring on or before 2027-08-31 | H68: =COUNTIF(J5:J52,"Yes") -> 0 | K68: Near-term rollover exposure
A70: UNIT / SUITE MIX BY MANAGER GROUP (manager-cover.pdf: groups A/B/C = Studio, 1BR, 2BR in order)
A71: Group | B71: Unit type | C71: Area SF | D71: Total units | E71: Occupied | F71: Pending | G71: Vacant | H71: Scheduled rent/mo
A72: A | B72: Studio | C72: 700 | D72: =COUNTIF($B$5:$B$52,B72) -> 16 | E72: =COUNTIFS($B$5:$B$52,B72,$E$5:$E$52,"active") -> 15 | F72: =COUNTIFS($B$5:$B$52,B72,$E$5:$E$52,"pending") -> 0 | G72: =COUNTIFS($B$5:$B$52,B72,$E$5:$E$52,"vacant") -> 1 | H72: =SUMIF($B$5:$B$52,B72,$F$5:$F$52) -> 24000
A73: B | B73: 1BR | C73: 820 | D73: =COUNTIF($B$5:$B$52,B73) -> 16 | E73: =COUNTIFS($B$5:$B$52,B73,$E$5:$E$52,"active") -> 15 | F73: =COUNTIFS($B$5:$B$52,B73,$E$5:$E$52,"pending") -> 0 | G73: =COUNTIFS($B$5:$B$52,B73,$E$5:$E$52,"vacant") -> 1 | H73: =SUMIF($B$5:$B$52,B73,$F$5:$F$52) -> 26400
...

Sheet Underwriting
A1: Underwritten Cash Flow & Direct Capitalization
A2: Prescribed stabilized underwriting per underwriting-instructions.pdf p.1 as amended by revision-notice.pdf p.1. This is NOT the historical T-12 result — see the Historical sheet.
A4: Line | B4: Amount | C4: Unit | D4: Basis / formula in words
A5: Gross potential rent (gross_potential_rent) | B5: =Inputs!B5 -> 977100 | C5: USD/yr | D5: All 48 suites on the REVISED roll, scheduled rent x 12, before the Suite 001 amendment
A6: Less: economic loss @ 5% | B6: =-B5*Inputs!B6 -> -48855 | C6: USD/yr | D6: Vacancy and credit loss
A7: Plus: other income | B7: =Inputs!B7*Inputs!B8 -> 16800 | C7: USD/yr | D7: $350 per unit/suite x 48. Reimbursements already in GPR — not double counted
A8: uw_egi — Effective gross income | B8: =B5+B6+B7 -> 945045 | C8: USD/yr | D8: GPR less economic loss plus other income
A10: Less: uw_tax — real estate tax | B10: =-Inputs!B9 -> -102312 | C10: USD/yr | D10: Prescribed $102,312
A11: Less: uw_insurance — insurance expense | B11: =-Inputs!B10 -> -34104 | C11: USD/yr | D11: Prescribed $34,104. Expense, not the policy limit
A12: Less: other recurring operating expenses | B12: =-Inputs!B11 -> -136416 | C12: USD/yr | D12: Prescribed $136,416
A13: Less: management fee @ 3% of EGI | B13: =-B8*Inputs!B12 -> -28351.35 | C13: USD/yr | D13: 3% x uw_egi
A14: uw_operating_expenses — total (before reserves) | B14: =-SUM(B10:B13) -> 301183.35 | C14: USD/yr | D14: Tax + insurance + other recurring + management. Excludes reserves by definition
A15: uw_noi — Net operating income (before reserves) | B15: =B8-B14 -> 643861.65 | C15: USD/yr | D15: uw_egi less uw_operating_expenses. This is the capitalized figure
A16: Less: replacement reserves | B16: =-Inputs!B13*Inputs!B8 -> -14400 | C16: USD/yr | D16: $300 per unit/suite x 48
A17: uw_ncf — Net cash flow (after reserves) | B17: =B15+B16 -> 629461.65 | C17: USD/yr | D17: uw_noi less reserves. DSCR and debt yield are sized on this
A19: cap_rate | B19: =Inputs!B14 -> 0.06 | C19: decimal | D19: Revised: 5.7500% initial plus 25 bp
A20: capitalization_value | B20: =B15/B19 -> 10731028 | C20: USD | D20: uw_noi (before reserves) / cap_rate
A22: Implied value per unit/suite | B22: =B20/Inputs!B8 -> 223563.07 | C22: USD/unit | D22: Derived
A23: Implied value per SF | B23: =B20/'Rent Roll'!H63 -> 263.01538 | C23: USD/SF | D23: Derived on 40,800 SF total area
A24: uw_noi margin on uw_egi | B24: =B15/B8 -> 0.68130264 | C24: decimal | D24: Derived
A25: Expense ratio (before reserves) | B25: =B14/B8 -> 0.31869736 | C25: decimal | D25: Derived
A27: RECONCILIATION TO IN-PLACE RENT
A28: annual_in_place_rent (active suites, amendment applied) | B28: ='Rent Roll'!H58 -> 920400 | D28: Contractual, occupied suites only
A29: gross_potential_rent (prescribed underwriting basis) | B29: =B5 -> 977100 | D29: All 48 suites on the revised roll, pre-amendment
A30: Difference | B30: =B29-B28 -> 56700 | D30: Upside of the 3 vacant suites, less the Suite 001 amendment excluded by the prescribed basis
A32: Note: the executed Suite 001 amendment raises in-place rent but is deliberately excluded from gross_potential_rent, because the instructions prescribe the pre-amendment certified roll as the stabilized GPR assumption. These are two separate measures, not a conflict.

Sheet Debt
A1: Debt Sizing and Sources & Uses
A2: Sized on the REVISED sizing rate of 7.0000%, fully amortizing, notwithstanding the first 24 months of interest-only. Loan constraints, payoff and fees are unchanged.
A4: Line | B4: Amount | C4: Unit | D4: Basis
A5: sizing_rate | B5: =Inputs!B17 -> 0.07 | C5: decimal | D5: Initial 6.2500% (greater of note and floor) plus 75 bp per revision notice = 7.0000%
A6: Periodic (monthly) rate | B6: =B5/Inputs!B19 -> 0.0058333333 | C6: decimal | D6: sizing_rate / 12
A7: Amortization periods | B7: =Inputs!B18*Inputs!B19 -> 360 | C7: months | D7: 30 years x 12
A8: Annuity factor | B8: =(1-(1+B6)^-B7)/B6 -> 150.30757 | C8: x | D8: Present value of $1 per month
A10: Constraint 1 — LTV @ 65.00% | B10: =Inputs!B20*Underwriting!B20 -> 6975167.9 | C10: USD | D10: ltv_limit x capitalization_value
A11: Constraint 2 — DSCR @ 1.25x on NCF | B11: =(Underwriting!B17/Inputs!B21/Inputs!B19)*B8 -> 6307523.3 | C11: USD | D11: (uw_ncf / dscr_limit / 12) x annuity factor
A12: Constraint 3 — NCF debt yield @ 9.00% | B12: =Underwriting!B17/Inputs!B22 -> 6994018.3 | C12: USD | D12: uw_ncf / debt_yield_limit
A13: maximum_loan | B13: =MIN(B10:B12) -> 6307523.3 | C13: USD | D13: Most restrictive of the three constraints
A14: Binding constraint | B14: =INDEX(A10:A12,MATCH(B13,B10:B12,0)) -> Constraint 2 — DSCR @ 1.25x on NCF | C14: text | D14: Which test governs
A16: Monthly principal & interest at sized loan | B16: =B13*B6/(1-(1+B6)^-B7) -> 41964.11 | C16: USD/mo | D16: Fully amortizing at sizing_rate
A17: Annual debt service | B17: =B16*Inputs!B19 -> 503569.32 | C17: USD/yr | D17: Monthly P&I x 12
A18: Achieved DSCR on uw_ncf | B18: =Underwriting!B17/B17 -> 1.25 | C18: ratio | D18: At the constraint minimum of 1.25 — still the binding test
A19: Achieved NCF debt yield | B19: =Underwriting!B17/B13 -> 0.099795374 | C19: decimal | D19: Cushion above the 9.00% floor
A20: Achieved LTV | B20: =B13/Underwriting!B20 -> 0.58778372 | C20: decimal | D20: Cushion below the 65.00% cap
A21: Interest-only annual payment (months 1-24, sizing rate) | B21: =B13*B5 -> 441526.63 | C21: USD/yr | D21: Actual year 1-2 cash cost at the revised rate; NOT used for sizing
A22: DSCR during interest-only period | B22: =Underwriting!B17/B21 -> 1.4256482 | C22: ratio | D22: Informational cushion in the IO window
A25: SOURCES & USES
A26: SOURCES
A27: New sized loan (maximum_loan) | B27: =B13 -> 6307523.3 | D27: Proceeds at the binding constraint
A28: Additional sponsor equity required | B28: =MAX(0,-B34) -> 0 | D28: Zero unless net cash-out is negative
A29: Total sources | B29: =B27+B28 -> 6307523.3
A30: USES
A31: Existing loan payoff | B31: =Inputs!B25 -> 4200000 | D31: Prescribed $4,200,000
A32: Origination fee @ 1.00% of sized loan | B32: =B13*Inputs!B23 -> 63075.233 | D32: 1% x maximum_loan
A33: Closing costs | B33: =Inputs!B24 -> 45000 | D33: Prescribed $45,000
A34: net_cash_out — proceeds to sponsor | B34: =B27-B31-B32-B33 -> 1999448.1 | D34: Positive = cash out. Negative = additional equity required
A35: Total uses | B35: =B31+B32+B33+MAX(0,B34) -> 6307523.3
A36: Check: sources less uses | B36: =B29-B35 -> 0 | D36: Must be zero

Sheet Historical
A1: Historical T-12 (as reported) vs Underwritten
A2: Source: operating-statement.pdf p.1, UNCHANGED by revision 2. Period 2025-09-01 through 2026-08-31. Cash basis. Amounts in USD, not thousands. Reported T-12 NOI, uw_noi and uw_ncf are three distinct measures. Only the underwritten column moves in this revision.
A4: Account | B4: T-12 actual (USD) | C4: Underwritten (USD) | D4: Variance | E4: Comment
A5: Rental and ancillary collections / EGI | B5: 876960 | C5: =Underwriting!B8 -> 945045 | D5: =C5-B5 -> 68085 | E5: Historical collections are cash received; not an annualized rent-roll total. Underwritten EGI is the prescribed forward assumption.
A6: Real estate tax expense | B6: -102312 | C6: =-Inputs!B9 -> -102312 | D6: =C6-B6 -> 0 | E6: Underwritten at actual.
A7: Insurance expense | B7: -34104 | C7: =-Inputs!B10 -> -34104 | D7: =C7-B7 -> 0 | E7: Underwritten at actual. Distinct from the $2,000,000 GL aggregate limit.
A8: Other recurring operating expenses | B8: -136416 | C8: =-Inputs!B11 -> -136416 | D8: =C8-B8 -> 0 | E8: Underwritten at actual.
A9: Management fee | B9: 0 | C9: =-Underwriting!B8*Inputs!B12 -> -28351.35 | D9: =C9-B9 -> -28351.35 | E9: Not a separate line in the T-12; underwriting adds 3% of EGI. A real economic add, not a reclassification.
A10: Roof replacement booked in repairs | B10: 0 | C10: 0 | D10: =C10-B10 -> 0 | E10: Reported as $0 in the repairs line. The roof replacement is capital and no recurring repair component is included, so no add-back or scrub is required.
A11: Total operating expenses | B11: =SUM(B6:B10) -> -272832 | C11: =-Underwriting!B14 -> -301183.35 | D11: =C11-B11 -> -28351.35
A12: reported_t12_noi / uw_noi (before reserves) | B12: =B5+B11 -> 604128 | C12: =Underwriting!B15 -> 643861.65 | D12: =C12-B12 -> 39733.65 | E12: Reported NOI of $604,128 ties to the statement. The underwritten figure is higher, driven by the prescribed GPR and other-income assumptions.
A13: Replacement reserves | B13: 0 | C13: =-Inputs!B13*Inputs!B8 -> -14400 | D13: =C13-B13 -> -14400 | E13: Not a cash line in the T-12; underwriting deducts $300/unit below NOI.
A14: uw_ncf (after reserves) | B14: n/a | C14: =Underwriting!B17 -> 629461.65 | E14: No historical equivalent is reported.
A16: Tie-out check: reported NOI stated on the operating statement | B16: 604128
A17: Recomputed from the reported accounts | B17: =B12 -> 604128
A18: Difference | B18: =B17-B16 -> 0 | C18: =IF(B18=0,"OK — ties","CHECK") -> OK — ties

Sheet Sensitivity
A1: Sensitivity — Capitalization Value and Maximum Loan
A2: Cap rate varies down the rows; sizing rate varies across the columns. Blue cells are levers. All results recalculate from Inputs.
A4: TABLE 1 — capitalization_value by cap rate (uw_noi is unaffected by sizing rate)
A5: cap_rate | B5: capitalization_value | C5: LTV constraint @ 65% | D5: Value per unit
A6: 0.055 | B6: =Underwriting!$B$15/A6 -> 11706575 | C6: =Inputs!$B$20*B6 -> 7609274 | D6: =B6/Inputs!$B$8 -> 243886.99
A7: 0.0575 | B7: =Underwriting!$B$15/A7 -> 11197594 | C7: =Inputs!$B$20*B7 -> 7278436 | D7: =B7/Inputs!$B$8 -> 233283.21
A8: 0.06 | B8: =Underwriting!$B$15/A8 -> 10731028 | C8: =Inputs!$B$20*B8 -> 6975167.9 | D8: =B8/Inputs!$B$8 -> 223563.07
A9: 0.0625 | B9: =Underwriting!$B$15/A9 -> 10301786 | C9: =Inputs!$B$20*B9 -> 6696161.2 | D9: =B9/Inputs!$B$8 -> 214620.55
A10: 0.065 | B10: =Underwriting!$B$15/A10 -> 9905563.8 | C10: =Inputs!$B$20*B10 -> 6438616.5 | D10: =B10/Inputs!$B$8 -> 206365.91
A13: TABLE 2 — maximum_loan by cap rate (rows) and sizing_rate (columns)
A14: cap_rate \ sizing_rate | B14: 0.065 | C14: 0.0675 | D14: 0.07 | E14: 0.0725 | F14: 0.075
A15: 0.055 | B15: =MIN(Inputs!$B$20*(Underwriting!$B$15/$A15),(Underwriting!$B$17/Inputs!$B$21/Inputs!$B$19)*((1-(1+B$14/Inputs!$B$19)^-(Inputs!$B$18*Inputs!$B$19))/(B$14/Inputs!$B$19)),Underwriting!$B$17/Inputs!$B$22) -> 6639176.2 | C15: =MIN(Inputs!$B$20*(Underwriting!$B$15/$A15),(Underwriting!$B$17/Inputs!$B$21/Inputs!$B$19)*((1-(1+C$14/Inputs!$B$19)^-(Inputs!$B$18*Inputs!$B$19))/(C$14/Inputs!$B$19)),Underwriting!$B$17/Inputs!$B$22) -> 6469971.2 | D15: =MIN(Inputs!$B$20*(Underwriting!$B$15/$A15),(Underwriting!$B$17/Inputs!$B$21/Inputs!$B$19)*((1-(1+D$14/Inputs!$B$19)^-(Inputs!$B$18*Inputs!$B$19))/(D$14/Inputs!$B$19)),Underwriting!$B$17/Inputs!$B$22) -> 6307523.3 | E15: =MIN(Inputs!$B$20*(Underwriting!$B$15/$A15),(Underwriting!$B$17/Inputs!$B$21/Inputs!$B$19)*((1-(1+E$14/Inputs!$B$19)^-(Inputs!$B$18*Inputs!$B$19))/(E$14/Inputs!$B$19)),Underwriting!$B$17/Inputs!$B$22) -> 6151505.3 | F15: =MIN(Inputs!$B$20*(Underwriting!$B$15/$A15),(Underwriting!$B$17/Inputs!$B$21/Inputs!$B$19)*((1-(1+F$14/Inputs!$B$19)^-(Inputs!$B$18*Inputs!$B$19))/(F$14/Inputs!$B$19)),Underwriting!$B$17/Inputs!$B$22) -> 6001607.4
A16: 0.0575 | B16: =MIN(Inputs!$B$20*(Underwriting!$B$15/$A16),(Underwriting!$B$17/Inputs!$B$21/Inputs!$B$19)*((1-(1+B$14/Inputs!$B$19)^-(Inputs!$B$18*Inputs!$B$19))/(B$14/Inputs!$B$19)),Underwriting!$B$17/Inputs!$B$22) -> 6639176.2 | C16: =MIN(Inputs!$B$20*(Underwriting!$B$15/$A16),(Underwriting!$B$17/Inputs!$B$21/Inputs!$B$19)*((1-(1+C$14/Inputs!$B$19)^-(Inputs!$B$18*Inputs!$B$19))/(C$14/Inputs!$B$19)),Underwriting!$B$17/Inputs!$B$22) -> 6469971.2 | D16: =MIN(Inputs!$B$20*(Underwriting!$B$15/$A16),(Underwriting!$B$17/Inputs!$B$21/Inputs!$B$19)*((1-(1+D$14/Inputs!$B$19)^-(Inputs!$B$18*Inputs!$B$19))/(D$14/Inputs!$B$19)),Underwriting!$B$17/Inputs!$B$22) -> 6307523.3 | E16: =MIN(Inputs!$B$20*(Underwriting!$B$15/$A16),(Underwriting!$B$17/Inputs!$B$21/Inputs!$B$19)*((1-(1+E$14/Inputs!$B$19)^-(Inputs!$B$18*Inputs!$B$19))/(E$14/Inputs!$B$19)),Underwriting!$B$17/Inputs!$B$22) -> 6151505.3 | F16: =MIN(Inputs!$B$20*(Underwriting!$B$15/$A16),(Underwriting!$B$17/Inputs!$B$21/Inputs!$B$19)*((1-(1+F$14/Inputs!$B$19)^-(Inputs!$B$18*Inputs!$B$19))/(F$14/Inputs!$B$19)),Underwriting!$B$17/Inputs!$B$22) -> 6001607.4
A17: 0.06 | B17: =MIN(Inputs!$B$20*(Underwriting!$B$15/$A17),(Underwriting!$B$17/Inputs!$B$21/Inputs!$B$19)*((1-(1+B$14/Inputs!$B$19)^-(Inputs!$B$18*Inputs!$B$19))/(B$14/Inputs!$B$19)),Underwriting!$B$17/Inputs!$B$22) -> 6639176.2 | C17: =MIN(Inputs!$B$20*(Underwriting!$B$15/$A17),(Underwriting!$B$17/Inputs!$B$21/Inputs!$B$19)*((1-(1+C$14/Inputs!$B$19)^-(Inputs!$B$18*Inputs!$B$19))/(C$14/Inputs!$B$19)),Underwriting!$B$17/Inputs!$B$22) -> 6469971.2 | D17: =MIN(Inputs!$B$20*(Underwriting!$B$15/$A17),(Underwriting!$B$17/Inputs!$B$21/Inputs!$B$19)*((1-(1+D$14/Inputs!$B$19)^-(Inputs!$B$18*Inputs!$B$19))/(D$14/Inputs!$B$19)),Underwriting!$B$17/Inputs!$B$22) -> 6307523.3 | E17: =MIN(Inputs!$B$20*(Underwriting!$B$15/$A17),(Underwriting!$B$17/Inputs!$B$21/Inputs!$B$19)*((1-(1+E$14/Inputs!$B$19)^-(Inputs!$B$18*Inputs!$B$19))/(E$14/Inputs!$B$19)),Underwriting!$B$17/Inputs!$B$22) -> 6151505.3 | F17: =MIN(Inputs!$B$20*(Underwriting!$B$15/$A17),(Underwriting!$B$17/Inputs!$B$21/Inputs!$B$19)*((1-(1+F$14/Inputs!$B$19)^-(Inputs!$B$18*Inputs!$B$19))/(F$14/Inputs!$B$19)),Underwriting!$B$17/Inputs!$B$22) -> 6001607.4
A18: 0.0625 | B18: =MIN(Inputs!$B$20*(Underwriting!$B$15/$A18),(Underwriting!$B$17/Inputs!$B$21/Inputs!$B$19)*((1-(1+B$14/Inputs!$B$19)^-(Inputs!$B$18*Inputs!$B$19))/(B$14/Inputs!$B$19)),Underwriting!$B$17/Inputs!$B$22) -> 6639176.2 | C18: =MIN(Inputs!$B$20*(Underwriting!$B$15/$A18),(Underwriting!$B$17/Inputs!$B$21/Inputs!$B$19)*((1-(1+C$14/Inputs!$B$19)^-(Inputs!$B$18*Inputs!$B$19))/(C$14/Inputs!$B$19)),Underwriting!$B$17/Inputs!$B$22) -> 6469971.2 | D18: =MIN(Inputs!$B$20*(Underwriting!$B$15/$A18),(Underwriting!$B$17/Inputs!$B$21/Inputs!$B$19)*((1-(1+D$14/Inputs!$B$19)^-(Inputs!$B$18*Inputs!$B$19))/(D$14/Inputs!$B$19)),Underwriting!$B$17/Inputs!$B$22) -> 6307523.3 | E18: =MIN(Inputs!$B$20*(Underwriting!$B$15/$A18),(Underwriting!$B$17/Inputs!$B$21/Inputs!$B$19)*((1-(1+E$14/Inputs!$B$19)^-(Inputs!$B$18*Inputs!$B$19))/(E$14/Inputs!$B$19)),Underwriting!$B$17/Inputs!$B$22) -> 6151505.3 | F18: =MIN(Inputs!$B$20*(Underwriting!$B$15/$A18),(Underwriting!$B$17/Inputs!$B$21/Inputs!$B$19)*((1-(1+F$14/Inputs!$B$19)^-(Inputs!$B$18*Inputs!$B$19))/(F$14/Inputs!$B$19)),Underwriting!$B$17/Inputs!$B$22) -> 6001607.4
A19: 0.065 | B19: =MIN(Inputs!$B$20*(Underwriting!$B$15/$A19),(Underwriting!$B$17/Inputs!$B$21/Inputs!$B$19)*((1-(1+B$14/Inputs!$B$19)^-(Inputs!$B$18*Inputs!$B$19))/(B$14/Inputs!$B$19)),Underwriting!$B$17/Inputs!$B$22) -> 6438616.5 | C19: =MIN(Inputs!$B$20*(Underwriting!$B$15/$A19),(Underwriting!$B$17/Inputs!$B$21/Inputs!$B$19)*((1-(1+C$14/Inputs!$B$19)^-(Inputs!$B$18*Inputs!$B$19))/(C$14/Inputs!$B$19)),Underwriting!$B$17/Inputs!$B$22) -> 6438616.5 | D19: =MIN(Inputs!$B$20*(Underwriting!$B$15/$A19),(Underwriting!$B$17/Inputs!$B$21/Inputs!$B$19)*((1-(1+D$14/Inputs!$B$19)^-(Inputs!$B$18*Inputs!$B$19))/(D$14/Inputs!$B$19)),Underwriting!$B$17/Inputs!$B$22) -> 6307523.3 | E19: =MIN(Inputs!$B$20*(Underwriting!$B$15/$A19),(Underwriting!$B$17/Inputs!$B$21/Inputs!$B$19)*((1-(1+E$14/Inputs!$B$19)^-(Inputs!$B$18*Inputs!$B$19))/(E$14/Inputs!$B$19)),Underwriting!$B$17/Inputs!$B$22) -> 6151505.3 | F19: =MIN(Inputs!$B$20*(Underwriting!$B$15/$A19),(Underwriting!$B$17/Inputs!$B$21/Inputs!$B$19)*((1-(1+F$14/Inputs!$B$19)^-(Inputs!$B$18*Inputs!$B$19))/(F$14/Inputs!$B$19)),Underwriting!$B$17/Inputs!$B$22) -> 6001607.4
A21: TABLE 3 — net_cash_out by cap rate (rows) and sizing_rate (columns)
A22: cap_rate \ sizing_rate | B22: =B14 -> 0.065 | C22: =C14 -> 0.0675 | D22: =D14 -> 0.07 | E22: =E14 -> 0.0725 | F22: =F14 -> 0.075
A23: =A15 -> 0.055 | B23: =B15-Inputs!$B$25-B15*Inputs!$B$23-Inputs!$B$24 -> 2327784.5 | C23: =C15-Inputs!$B$25-C15*Inputs!$B$23-Inputs!$B$24 -> 2160271.5 | D23: =D15-Inputs!$B$25-D15*Inputs!$B$23-Inputs!$B$24 -> 1999448.1 | E23: =E15-Inputs!$B$25-E15*Inputs!$B$23-Inputs!$B$24 -> 1844990.2 | F23: =F15-Inputs!$B$25-F15*Inputs!$B$23-Inputs!$B$24 -> 1696591.4
A24: =A16 -> 0.0575 | B24: =B16-Inputs!$B$25-B16*Inputs!$B$23-Inputs!$B$24 -> 2327784.5 | C24: =C16-Inputs!$B$25-C16*Inputs!$B$23-Inputs!$B$24 -> 2160271.5 | D24: =D16-Inputs!$B$25-D16*Inputs!$B$23-Inputs!$B$24 -> 1999448.1 | E24: =E16-Inputs!$B$25-E16*Inputs!$B$23-Inputs!$B$24 -> 1844990.2 | F24: =F16-Inputs!$B$25-F16*Inputs!$B$23-Inputs!$B$24 -> 1696591.4
A25: =A17 -> 0.06 | B25: =B17-Inputs!$B$25-B17*Inputs!$B$23-Inputs!$B$24 -> 2327784.5 | C25: =C17-Inputs!$B$25-C17*Inputs!$B$23-Inputs!$B$24 -> 2160271.5 | D25: =D17-Inputs!$B$25-D17*Inputs!$B$23-Inputs!$B$24 -> 1999448.1 | E25: =E17-Inputs!$B$25-E17*Inputs!$B$23-Inputs!$B$24 -> 1844990.2 | F25: =F17-Inputs!$B$25-F17*Inputs!$B$23-Inputs!$B$24 -> 1696591.4
A26: =A18 -> 0.0625 | B26: =B18-Inputs!$B$25-B18*Inputs!$B$23-Inputs!$B$24 -> 2327784.5 | C26: =C18-Inputs!$B$25-C18*Inputs!$B$23-Inputs!$B$24 -> 2160271.5 | D26: =D18-Inputs!$B$25-D18*Inputs!$B$23-Inputs!$B$24 -> 1999448.1 | E26: =E18-Inputs!$B$25-E18*Inputs!$B$23-Inputs!$B$24 -> 1844990.2 | F26: =F18-Inputs!$B$25-F18*Inputs!$B$23-Inputs!$B$24 -> 1696591.4
A27: =A19 -> 0.065 | B27: =B19-Inputs!$B$25-B19*Inputs!$B$23-Inputs!$B$24 -> 2129230.3 | C27: =C19-Inputs!$B$25-C19*Inputs!$B$23-Inputs!$B$24 -> 2129230.3 | D27: =D19-Inputs!$B$25-D19*Inputs!$B$23-Inputs!$B$24 -> 1999448.1 | E27: =E19-Inputs!$B$25-E19*Inputs!$B$23-Inputs!$B$24 -> 1844990.2 | F27: =F19-Inputs!$B$25-F19*Inputs!$B$23-Inputs!$B$24 -> 1696591.4
A29: Reading the tables: at the revised 6.0000% cap rate and 7.0000% sizing rate the DSCR test still binds, and it now binds harder. The 75 bp rate increase shortens the annuity factor from 162.4122 to 150.3076, which is what removes roughly $481,000 of proceeds. The 25 bp cap rate increase cuts value by about $423,000 but costs nothing in loan capacity, because LTV was never the binding test and now has even more headroom. Proceeds stay flat across cap rates in this range and fall only with the sizing rate.

Sheet Fields
A1: Named Field Register — 41 reported fields — REVISION 2
A2: Revision 2, as of 2026-09-01. Ratios are decimal. Missing information is stated as unknown, which is distinct from zero — pending_units is now a TRUE ZERO, not unknown. Risk fields use present / absent / unresolved.
A4: id | B4: Value | C4: Unit | D4: Evidence (file / location) | E4: Calculation / reasoning
A5: total_units | B5: ='Rent Roll'!H59 -> 48 | C5: units | D5: rent-roll-revised.xlsx, Rent Roll!A5:A52 | E5: Count of suites on the revised roll. Unchanged at 48.
A6: occupied_units | B6: ='Rent Roll'!H60 -> 45 | C6: units | D6: rent-roll-revised.xlsx, Rent Roll!D5:D52 | E6: REVISED 44 to 45. Suite 045 moved from pending to active. Excludes 3 vacant.
A7: pending_units | B7: ='Rent Roll'!H61 -> 0 | C7: units | D7: revision-notice.pdf p.1; rent-roll-revised.xlsx, Rent Roll!D49 | E7: REVISED 1 to 0. Suite 045 is now active. This is a true zero — no suite is pending — not an unknown.
A8: total_area_sf | B8: ='Rent Roll'!H63 -> 40800 | C8: SF | D8: rent-roll-revised.xlsx, Rent Roll!C5:C52 | E8: Unchanged: 16 x 700 + 16 x 820 + 16 x 1,030.
A9: occupied_area_sf | B9: ='Rent Roll'!H64 -> 38250 | C9: SF | D9: rent-roll-revised.xlsx, Rent Roll!C5:C49 | E9: REVISED 37,220 to 38,250. The 45 active suites: 15 x 700 + 15 x 820 + 15 x 1,030.
A10: unit_occupancy | B10: ='Rent Roll'!H65 -> 0.9375 | C10: decimal | D10: rent-roll-revised.xlsx, Rent Roll!D5:D52 | E10: REVISED 0.9167 to 0.9375. 45 / 48. No pending suites remain to exclude.
A11: area_occupancy | B11: ='Rent Roll'!H66 -> 0.9375 | C11: decimal | D11: rent-roll-revised.xlsx, Rent Roll!C5:C52 and D5:D52 | E11: REVISED 0.9123 to 0.9375. 38,250 / 40,800. Now equal to unit occupancy, because 15 of each plan are occupied.
A12: annual_in_place_rent | B12: ='Rent Roll'!H58 -> 920400 | C12: USD/yr | D12: rent-roll-revised.xlsx E5:E49; lease-correspondence.pdf p.1 | E12: REVISED $894,600 to $920,400. 45 active suites, amendment applied: ($76,350 + $350) x 12.
A13: unit_001_monthly_rent | B13: ='Rent Roll'!H5 -> 1850 | C13: USD/mo | D13: lease-001.pdf p.1; lease-correspondence.pdf p.1; rent-roll-revised.xlsx E5 | E13: UNCHANGED at $1,850. Base $1,500 plus the $350 amendment, which the revision notice expressly continues.
A14: gross_potential_rent | B14: =Inputs!B5 -> 977100 | C14: USD/yr | D14: revision-notice.pdf p.1; rent-roll-revised.xlsx E5:E52 | E14: REVISED $974,400 to $977,100. All 48 suites on the new roll, pre-amendment: $81,425 x 12. The $2,700 uplift is the Suite 045 increase x 12.
A15: uw_egi | B15: =Underwriting!B8 -> 945045 | C15: USD/yr | D15: underwriting-instructions.pdf p.1; revision-notice.pdf p.1 | E15: REVISED $942,480 to $945,045. $977,100 x 0.95 + $350 x 48. Loss factor and other income unchanged.
A16: uw_tax | B16: =Inputs!B9 -> 102312 | C16: USD/yr | D16: underwriting-instructions.pdf p.1; operating-statement.pdf p.1 | E16: UNCHANGED at $102,312. Prescribed at the T-12 actual.
A17: uw_insurance | B17: =Inputs!B10 -> 34104 | C17: USD/yr | D17: underwriting-instructions.pdf p.1; operating-statement.pdf p.1 | E17: UNCHANGED at $34,104. Prescribed expense; not the policy limit.
A18: uw_operating_expenses | B18: =Underwriting!B14 -> 301183.35 | C18: USD/yr | D18: underwriting-instructions.pdf p.1 | E18: REVISED $301,106.40 to $301,183.35. Only the 3% management fee moved, because EGI rose. Before reserves.
A19: uw_noi | B19: =Underwriting!B15 -> 643861.65 | C19: USD/yr | D19: underwriting-instructions.pdf p.1 | E19: REVISED $641,373.60 to $643,861.65. uw_egi less uw_operating_expenses; before reserves.
A20: uw_ncf | B20: =Underwriting!B17 -> 629461.65 | C20: USD/yr | D20: underwriting-instructions.pdf p.1 | E20: REVISED $626,973.60 to $629,461.65. uw_noi less $300 x 48 reserves, which are unchanged.
A21: sizing_rate | B21: =Inputs!B17 -> 0.07 | C21: decimal | D21: revision-notice.pdf p.1 | E21: REVISED 0.0625 to 0.0700. Initial sizing rate of 6.2500% plus 75 bp.
A22: cap_rate | B22: =Inputs!B14 -> 0.06 | C22: decimal | D22: revision-notice.pdf p.1 | E22: REVISED 0.0575 to 0.0600. Initial 5.7500% plus 25 bp.
A23: capitalization_value | B23: =Underwriting!B20 -> 10731028 | C23: USD | D23: revision-notice.pdf p.1 | E23: REVISED $11,154,323.48 to $10,731,027.50. uw_noi before reserves / 6.0000%. Higher NOI, more than offset by the wider cap rate.
A24: ltv_limit | B24: =Inputs!B20 -> 0.65 | C24: decimal | D24: underwriting-instructions.pdf p.1 | E24: UNCHANGED at 0.65.
A25: dscr_limit | B25: =Inputs!B21 -> 1.25 | C25: ratio | D25: underwriting-instructions.pdf p.1 | E25: UNCHANGED at 1.25 on NCF after reserves.
A26: debt_yield_limit | B26: =Inputs!B22 -> 0.09 | C26: decimal | D26: underwriting-instructions.pdf p.1 | E26: UNCHANGED at 0.09 on NCF after reserves.
A27: maximum_loan | B27: =Debt!B13 -> 6307523.3 | C27: USD | D27: underwriting-instructions.pdf p.1; revision-notice.pdf p.1 | E27: REVISED $6,788,545.13 to $6,307,523.32. Minimum of the three constraints; DSCR still binds, driven by the 7.0000% sizing rate.
A28: net_cash_out | B28: =Debt!B34 -> 1999448.1 | C28: USD | D28: underwriting-instructions.pdf p.1 | E28: REVISED $2,475,659.67 to $1,999,448.08. maximum_loan less the unchanged $4,200,000 payoff, 1% origination fee and $45,000 closing costs. Still positive.
A29: insurance_policy_limit | B29: 2000000 | C29: USD | D29: insurance.pdf p.1 | E29: UNCHANGED at $2,000,000. General liability aggregate limit, effective 2026-07-01 to 2027-06-30. Distinct from uw_insurance expense.
A30: selected_roll_date | B30: 2026-09-01 | C30: date | D30: rent-roll-revised.xlsx, Rent Roll!B2; revision-notice.pdf p.1 | E30: REVISED from 2026-08-31. The revised roll supersedes both the 2026-08-31 certified roll and the 2026-06-30 archive.
A31: reported_t12_noi | B31: =Historical!B12 -> 604128 | C31: USD/yr | D31: operating-statement.pdf p.1 | E31: UNCHANGED at $604,128. No revised operating statement was supplied; the T-12 period 2025-09-01 to 2026-08-31 still stands.
A32: type_a_units | B32: ='Rent Roll'!D72 -> 16 | C32: units | D32: manager-cover.pdf p.1; rent-roll-certified.xlsx B5:B52 | E32: Group A = Studio.
A33: type_a_occupied | B33: ='Rent Roll'!E72 -> 15 | C33: units | D33: rent-roll-certified.xlsx B5:B52 and D5:D52 | E33: Studios with active possession.
A34: type_b_units | B34: ='Rent Roll'!D73 -> 16 | C34: units | D34: manager-cover.pdf p.1; rent-roll-certified.xlsx B5:B52 | E34: Group B = 1BR.
A35: type_b_occupied | B35: ='Rent Roll'!E73 -> 15 | C35: units | D35: rent-roll-certified.xlsx B5:B52 and D5:D52 | E35: 1BRs with active possession.
A36: type_c_units | B36: ='Rent Roll'!D74 -> 16 | C36: units | D36: manager-cover.pdf p.1; rent-roll-certified.xlsx B5:B52 | E36: Group C = 2BR.
A37: type_c_occupied | B37: ='Rent Roll'!E74 -> 15 | C37: units | D37: rent-roll-revised.xlsx B5:B52 and D5:D52 | E37: REVISED 14 to 15. Suite 045 is a 2BR and is now active, so 15 of 16.
A38: risk_pending_in_occupancy | B38: absent | C38: flag | D38: revision-notice.pdf p.1; rent-roll-revised.xlsx D5:D52 | E38: REVISED present to absent. Suite 045 has taken possession, so no pending suite exists to be miscounted. The manager's 45-of-48 headline is now correct on its face and equals physical occupancy.
A39: risk_near_term_rollover | B39: absent | C39: flag | D39: rent-roll-revised.xlsx F5:F52 | E39: UNCHANGED. All 45 active expiries remain 2029-08-31, beyond the 2027-08-31 horizon. Zero near-term expiries.
A40: risk_missing_insurance | B40: absent | C40: flag | D40: insurance.pdf p.1 | E40: UNCHANGED. The declaration remains in force at the revised 2026-09-01 as-of date.
A41: risk_capital_in_opex | B41: absent | C41: flag | D41: operating-statement.pdf p.1 | E41: UNCHANGED. Assessed on the reported historical ledger, which the revision does not touch: roof replacement booked in repairs at $0, no recurring repair component.
...

Sheet Sources
A1: Source Register
A2: Eleven documents supplied across both rounds. No external research, outreach or market data was used.
A4: File | B4: Location | C4: Status | D4: What it governs | E4: What it does NOT establish
A5: revision-notice.pdf | B5: p.1 | C5: CONTROLLING (prescriptive) | D5: Effective 2026-09-01: the revised roll supersedes the prior roll; Suite 045 now active with rent up $225; sizing rate +75 bp; cap rate +25 bp; new roll used for all-unit scheduled gross potential. | E5: Does not change any expense input, loan constraint, payoff, fee, reserve, or the Suite 001 amendment, which it expressly continues.
A6: rent-roll-revised.xlsx | B6: Rent Roll!A1:G52 | C6: CONTROLLING | D6: As-of 2026-09-01. Unit count, type, area, possession status, scheduled rent, expirations. Controls physical occupancy. | E6: Does not reflect the Suite 001 amendment in its rent column, which still shows $1,500.
A7: rent-roll-certified.xlsx | B7: Rent Roll!A1:G52 | C7: SUPERSEDED — EXCLUDED | D7: Nothing now. Dated 2026-08-31, superseded by the revised roll. Retained in the audit archive as the revision 1 basis. | E7: Its Suite 045 pending status and $1,925 rent are no longer current.
A8: rent-roll-archive.xlsx | B8: Rent Roll!A1:G52 | C8: STALE — EXCLUDED | D8: Nothing. Dated 2026-06-30, superseded twice over. | E8: Its lower rents ($1,425 / $1,575 / $1,850) are not current and were not used anywhere.
A9: lease-001.pdf | B9: p.1 | C9: CONTROLLING (as amended) | D9: Suite 001 base terms: $1,500/mo, 700 SF, expiry 2029-08-31, $3,000 deposit. Confirms no free-rent concession applies. | E9: Its $1,500 rent is superseded by the signed amendment.
A10: lease-correspondence.pdf | B10: p.1 | C10: CONTROLLING | D10: Signed amendment, executed 2026-07-20, effective 2026-08-01: +$350/mo on Suite 001. All other terms unchanged. | E10: Does not change the prescribed pre-amendment GPR assumption.
A11: manager-cover.pdf | B11: p.1 | C11: CONTEXT + MAPPING | D11: Property identity (Magnolia Terrace, Raleigh NC multifamily). Group A/B/C = Studio/1BR/2BR. Required approved copy, preserved verbatim. | E11: Its 45-of-48 headline now coincides with physical occupancy, but only because possession changed — certified detail still controls.
A12: operating-statement.pdf | B12: p.1 | C12: CONTROLLING (historical) | D12: T-12 cash results 2025-09-01 to 2026-08-31. Reported NOI $604,128. Roof replacement booked at $0 in repairs. | E12: Historical collections are not an annualized rent-roll total and are not the underwritten EGI.
A13: insurance.pdf | B13: p.1 | C13: CONTROLLING | D13: GL aggregate limit $2,000,000; effective 2026-07-01 to 2026-06-30 term end 2027-06-30. | E13: The limit is not the insurance expense; the expense is $34,104.
A14: underwriting-instructions.pdf | B14: p.1 | C14: CONTROLLING as amended | D14: All underwriting assumptions, loan constraints, sizing conventions and risk definitions, except the cap rate, sizing rate and roll selection amended by the revision notice. | E14: Does not supply photos, asking price, market comps or sponsor history.
A15: diligence-status.pdf | B15: p.1 | C15: SCOPE LIMITATION | D15: States legal, environmental, property condition and title reviews are not complete — routine pending diligence. | E15: Supplies no evidence of contamination, litigation, fraud or structural failure; none is asserted.
A16: NOT SUPPLIED — EXPLICITLY UNKNOWN (not zero)
A17: Photographs / imagery | D17: Not supplied. Not invented.
A18: Asking price / guidance | D18: Not supplied. No price expectation is stated anywhere in this package.
A19: Market sales comparables | D19: Not supplied. The 5.7500% cap rate is a prescribed instruction, not a market-derived conclusion.
A20: Market rent comparables | D20: Not supplied. No mark-to-market or loss-to-lease conclusion can be drawn.
A21: Sponsor / borrower history | D21: Not supplied. No track record, credentials or net worth.
A22: Legal review | D22: Not complete — routine pending diligence.
A23: Environmental review | D23: Not complete — routine pending diligence.
A24: Property condition assessment | D24: Not complete — routine pending diligence. Roof replacement scope and warranty unverified.
A25: Title review | D25: Not complete — routine pending diligence.
A26: Property address | D26: Not represented; original fictional evaluation property.
A27: Historical occupancy trend | D27: Only a single point-in-time certified roll is supplied.
A28: Tax reassessment outlook | D28: Not supplied. Tax is held flat at the T-12 actual per instruction.
A29: Capital budget / roof cost | D29: The roof replacement is described as capital but no dollar amount is supplied.
