Workbook

Sheet Summary
A1: MAGNOLIA TERRACE — UNDERWRITING SUMMARY (REVISION v2)
A2: Raleigh, NC | Multifamily | 48 units | As-of 2026-09-01 (revised roll)
A3: REVISION v2 supersedes prior v1 model. Prior v1 is retained in the audit archive — this file does not replace it.
A5: INPUT CELLS (yellow) — orange highlight = changed in this revision
A6: Gross potential rent (annual, before econ loss) — CHANGED | B6: 928245 | C6: gross_potential_rent
A7: Capitalization rate — CHANGED (+25 bps) | B7: 0.06 | C7: cap_rate
A8: Sizing rate (greater of note or floor) — CHANGED (+75 bps) | B8: 0.07 | C8: sizing_rate
A9: Note rate — CHANGED (+75 bps) | B9: 0.07
A10: Rate floor (unchanged) | B10: 0.06
A11: Amortization (years) | B11: 30
A12: Economic loss % | B12: 0.05
A13: Other income $/unit/yr | B13: 350
A14: Total units | B14: 48
A15: Tax expense (annual) | B15: 102312
A16: Insurance expense (annual) | B16: 34104
A17: Other recurring operating expenses | B17: 136416
A18: Management fee % of EGI | B18: 0.03
A19: Replacement reserve $/unit/yr | B19: 300
A20: Max LTV | B20: 0.65
... A25: Existing loan payoff (unchanged) | B25: 4200000
A27: OUTPUT CELLS (green) — live formulas
A28: Effective gross income (EGI) | B28: =B6*(1-B12)+B13*B14 | C28: uw_egi
A29: Total operating expenses | B29: =B15+B16+B17+B18*B28
A30: Net operating income (NOI) | B30: =B28-B29 | C30: uw_noi
A31: Replacement reserves | B31: =B19*B14
A32: Net cash flow (NCF, after reserves) | B32: =B30-B31 | C32: uw_ncf
A33: Capitalization value (NOI / cap_rate) | B33: =B30/B7 | C33: capitalization_value
A35: DEBT SIZING
A36: Monthly sizing rate | B36: =B8/12
A37: Number of payments | B37: =B11*12
A38: Mortgage constant (annual) | B38: =12*B36*(1+B36)^B37/((1+B36)^B37-1)
A39: LTV-constrained loan | B39: =B20*B33
A40: DSCR-constrained loan (NCF / (DSCR × constant)) | B40: =B32/(B21*B38)
A41: Debt-yield-constrained loan (NCF / min DY) | B41: =B32/B22
A42: Maximum loan (min of three constraints) | B42: =MIN(B39,B40,B41) | C42: maximum_loan
A43: Binding constraint | B43: =IF(B42=B39,"LTV",IF(B42=B40,"DSCR","Debt yield"))
A45: SOURCES & USES / NET CASH-OUT
A46: Sources: loan proceeds | B46: =B42
A47: Uses: existing loan payoff | B47: =B25
A48: Uses: origination fee | B48: =B23*B42
...

Sheet Change_Log
A1: REVISION v2 CHANGE LOG
A2: Trigger: revision-notice.pdf | New controlling roll: rent-roll-revised.xlsx (as of 2026-09-01)
A3: Approved copy preserved: "Source-backed analysis. Assumptions remain subject to diligence."
A5: Item | B5: Prior (v1) | C5: Revised (v2) | D5: Delta | E5: Source / basis
A6: Controlling roll date | B6: 2026-08-31 | C6: 2026-09-01 | D6: +1 day | E6: revision-notice.pdf; rent-roll-revised.xlsx A2
A7: Suite 045 possession | B7: pending | C7: active | D7: → possessed | E7: rent-roll-revised.xlsx row 49
A8: Suite 045 monthly rent | B8: $1,925 | C8: $2,150 | D8: +$225 | E8: revision-notice.pdf; rent-roll-revised.xlsx row 49
A9: Total monthly scheduled rent | B9: $81,200 | C9: $81,425 | D9: +$225 | E9: sum of certified rents
A10: Gross potential rent (annual) | B10: $974,400 | C10: $977,100 | D10: +$2,700 | E10: GPR = monthly × 12
A11: Active (occupied) units | B11: 44 | C11: 45 | D11: +1 | E11: possession recount
A12: Pending units | B12: 1 | C12: 0 | D12: −1 | E12: Suite 045 now in possession
A13: Vacant units | B13: 3 | C13: 3 | D13: — | E13: 046–048 unchanged
A14: Unit occupancy | B14: 91.67% | C14: 93.75% | D14: +2.08 pp | E14: 45/48 vs 44/48
A15: Area occupancy | B15: 89.90% | C15: 92.43% | D15: +2.53 pp | E15: 37,710 / 40,800 vs 36,680 / 40,800
A16: Cap rate | B16: 5.75% | C16: 6.00% | D16: +25 bps | E16: revision-notice.pdf
... A31: risk_refinance_shortfall | B31: absent | C31: absent | D31: — | E31: net_cash_out still positive
A34: PRESERVED / UNAFFECTED FACTS
A35: • Property = Magnolia Terrace, Raleigh NC, multifamily (manager-cover.pdf).
A36: • Manager mapping A/B/C = Studio/1BR/2BR (manager-cover.pdf).
A37: • Suite 001 signed amendment (+$350) still applies; in-place amended rent = $1,850 (lease-correspondence.pdf).
A38: • Certified roll still shows Suite 001 at $1,500 (pre-amendment) — same known resolvable source conflict.
A39: • GPR still computed on the certified roll BEFORE Suite 001 amendment.
A40: • Tax $102,312, Insurance $34,104, Other opex $136,416, mgmt 3% of EGI, reserves $300/unit (underwriting-instructions.pdf).
A41: • LTV 65%, DSCR 1.25×, DY 9% (underwriting-instructions.pdf).
A42: • Amort 30 yr monthly; sizing on greater of note or floor (underwriting-instructions.pdf).
A43: • Origination 1%, closing $45,000, existing payoff $4,200,000 (underwriting-instructions.pdf).
A44: • Insurance policy aggregate limit $2,000,000 through 2027-06-30 (insurance.pdf).
A45: • Roof capital, not booked in repairs (operating-statement.pdf).
... A49: • Photos, asking price, market comps, sponsor history — still NOT supplied.

Sheet RentRoll_Revised
A1: MAGNOLIA TERRACE — REVISED CERTIFIED RENT ROLL
A2: Source: rent-roll-revised.xlsx | As of 2026-09-01 | SUPERSEDES 2026-08-31 certified roll
A4: Suite | B4: Unit type | C4: Area SF | D4: Possession | E4: Monthly rent | F4: Lease exp | G4: Note
A5: 001 | B5: Studio | C5: 700 | D5: active | E5: 1500 | F5: 2029-08-31
A6: 002 | B6: 1BR | C6: 820 | D6: active | E6: 1650 | F6: 2029-08-31
A7: 003 | B7: 2BR | C7: 1030 | D7: active | E7: 1925 | F7: 2029-08-31
A8: 004 | B8: Studio | C8: 700 | D8: active | E8: 1500 | F8: 2029-08-31
A9: 005 | B9: 1BR | C9: 820 | D9: active | E9: 1650 | F9: 2029-08-31
A10: 006 | B10: 2BR | C10: 1030 | D10: active | E10: 1925 | F10: 2029-08-31
A11: 007 | B11: Studio | C11: 700 | D11: active | E11: 1500 | F11: 2029-08-31
A12: 008 | B12: 1BR | C12: 820 | D12: active | E12: 1650 | F12: 2029-08-31
A13: 009 | B13: 2BR | C13: 1030 | D13: active | E13: 1925 | F13: 2029-08-31
A14: 010 | B14: Studio | C14: 700 | D14: active | E14: 1500 | F14: 2029-08-31
A15: 011 | B15: 1BR | C15: 820 | D15: active | E15: 1650 | F15: 2029-08-31
A16: 012 | B16: 2BR | C16: 1030 | D16: active | E16: 1925 | F16: 2029-08-31
... A48: 044 | B48: 1BR | C48: 820 | D48: active | E48: 1650 | F48: 2029-08-31
A49: 045 | B49: 2BR | C49: 1030 | D49: active | E49: 2150 | F49: 2029-08-31 | G49: REVISED: now active; rent +$225 per revision-notice.pdf
A50: 046 | B50: Studio | C50: 700 | D50: vacant | E50: 1500 | F50: 2029-08-31
A51: 047 | B51: 1BR | C51: 820 | D51: vacant | E51: 1650 | F51: 2029-08-31
A52: 048 | B52: 2BR | C52: 1030 | D52: vacant | E52: 1925 | F52: 2029-08-31
A53: TOTALS | C53: =SUM(C5:C52) | E53: =SUM(E5:E52)
A56: OCCUPANCY SUMMARY (physical, possession-based)
A57: Total units | B57: =COUNTA(A5:A52)
A58: Active (occupied) units | B58: =COUNTIF(D5:D52,"active")
A59: Pending units | B59: =COUNTIF(D5:D52,"pending")
A60: Vacant units | B60: =COUNTIF(D5:D52,"vacant")
A61: Unit occupancy | B61: =B58/B57
A62: Total area SF | B62: =SUM(C5:C52)
A63: Occupied area SF | B63: =SUMIF(D5:D52,"active",C5:C52)
A64: Area occupancy | B64: =B63/B62
A65: In-place monthly rent (all suites) | B65: =SUM(E5:E52)
A66: Annual in-place rent (× 12) | B66: =B65*12
A69: UNIT TYPE MIX (A=Studio, B=1BR, C=2BR)
A70: Group / Type | B70: Units | C70: Occupied | D70: Area SF/unit
A71: A — Studio | B71: =COUNTIF(B5:B52,"Studio") | C71: =COUNTIFS(B5:B52,"Studio",D5:D52,"active") | D71: 700
A72: B — 1BR | B72: =COUNTIF(B5:B52,"1BR") | C72: =COUNTIFS(B5:B52,"1BR",D5:D52,"active") | D72: 820
A73: C — 2BR | B73: =COUNTIF(B5:B52,"2BR") | C73: =COUNTIFS(B5:B52,"2BR",D5:D52,"active") | D73: 1030

Sheet UW_P&L
A1: UW P&L — HISTORICAL vs UNDERWRITTEN (REVISED)
A3: Line item | B3: Historical T12 | C3: Underwritten (v2) | D3: Basis / note
A4: Rental & ancillary collections (T12) | B4: 876960 | D4: operating-statement.pdf (T12 2025-09→2026-08); unchanged in revision
A5: Gross potential rent (all-suite scheduled × 12, revised roll) | C5: =Summary!B6 | D5: revised roll: +$225/mo on Suite 045 → +$2,700/yr vs v1
A6: Less: economic loss (5%) | C6: =-Summary!B6*Summary!B12 | D6: underwriting-instructions.pdf
A7: Plus: other income ($350/unit × 48) | C7: =Summary!B13*Summary!B14 | D7: underwriting-instructions.pdf
A8: Effective gross income (EGI) | C8: =Summary!B28
A10: Real estate taxes | B10: -102312 | C10: =-Summary!B15 | D10: unchanged
A11: Insurance | B11: -34104 | C11: =-Summary!B16 | D11: unchanged; distinct from $2M policy limit
A12: Other recurring opex | B12: -136416 | C12: =-Summary!B17 | D12: unchanged
A13: Management fee (3% of EGI) | C13: =-Summary!B18*Summary!B28 | D13: scales with EGI — small increase
A14: Roof replacement (capital) | B14: 0 | D14: unchanged
A15: Reported NOI | B15: 604128 | C15: =Summary!B30 | D15: Historical: reported. UW: NOI before reserves. Definitions differ.
A17: Replacement reserves ($300/unit) | C17: =-Summary!B31 | D17: unchanged
A18: Net cash flow (NCF) | C18: =Summary!B32
A20: Revision notes
A21: • Only Suite 045 changed: possession pending→active and rent $1,925→$2,150 (+$225).
A22: • GPR change flows through: +$2,700 GPR → +$2,565 EGI (95%) → +$2,488 NOI/NCF (net of 3% mgmt scaling).
A23: • Historical T12 unchanged — revision does not restate history.

Sheet Debt_Sizing
A1: DEBT SIZING & SOURCES / USES (REVISED)
A3: Sizing rate (greater of note or floor) | B3: =Summary!B8
A4: Note rate | B4: =Summary!B9
A5: Floor | B5: =Summary!B10
A6: Sizing floor binding? | B6: =IF(Summary!B9>=Summary!B10,"Note binds (floor not binding)","Floor binds")
A7: Amortization (yrs) | B7: =Summary!B11
A8: Annual mortgage constant | B8: =Summary!B38
A10: Cap value (NOI / cap) | B10: =Summary!B33
A11: NCF | B11: =Summary!B32
A13: LTV cap loan (65% × value) | B13: =Summary!B39
A14: DSCR cap loan | B14: =Summary!B40
A15: DY cap loan | B15: =Summary!B41
A16: MAXIMUM LOAN | B16: =Summary!B42
A17: Binding constraint | B17: =Summary!B43
A19: SOURCES & USES
A20: Sources: new loan | B20: =Summary!B46
A21: Uses: existing payoff | B21: =Summary!B47
A22: Uses: origination (1%) | B22: =Summary!B48
A23: Uses: closing costs | B23: =Summary!B49
A24: Total uses | B24: =Summary!B50
A25: Net cash-out | B25: =Summary!B51 | C25: Positive = surplus; negative = additional equity

Sheet Sensitivity
A1: SENSITIVITY — Max loan and Net cash-out (recentered around revised rates)
A2: Base case highlighted at cap 6.00% / sizing 7.00%.
A4: TABLE 1: Maximum Loan ($)
A5: Cap ↓ / Sizing rate → | B5: 0.06 | C5: 0.065 | D5: 0.07 | E5: 0.075 | F5: 0.08 | G5: 0.085
A6: 0.0525 | B6: =MIN(Summary!$B$20*Summary!$B$30/$A6,Summary!$B$32/(Summary!$B$21*12*(B$5/12)*(1+B$5/12)^(Summary!$B$11*12)/((1+B$5/12)^(Summary!$B$11*12)-1)),Summary!$B$32/Summary!$B$22) | C6: =MIN(Summary!$B$20*Summary!$B$30/$A6,Summary!$B$32/(Summary!$B$21*12*(C$5/12)*(1+C$5/12)^(Summary!$B$11*12)/((1+C$5/12)^(Summary!$B$11*12)-1)),Summary!$B$32/Summary!$B$22) | D6: =MIN(Summary!$B$20*Summary!$B$30/$A6,Summary!$B$32/(Summary!$B$21*12*(D$5/12)*(1+D$5/12)^(Summary!$B$11*12)/((1+D$5/12)^(Summary!$B$11*12)-1)),Summary!$B$32/Summary!$B$22) | E6: =MIN(Summary!$B$20*Summary!$B$30/$A6,Summary!$B$32/(Summary!$B$21*12*(E$5/12)*(1+E$5/12)^(Summary!$B$11*12)/((1+E$5/12)^(Summary!$B$11*12)-1)),Summary!$B$32/Summary!$B$22) | F6: =MIN(Summary!$B$20*Summary!$B$30/$A6,Summary!$B$32/(Summary!$B$21*12*(F$5/12)*(1+F$5/12)^(Summary!$B$11*12)/((1+F$5/12)^(Summary!$B$11*12)-1)),Summary!$B$32/Summary!$B$22) | G6: =MIN(Summary!$B$20*Summary!$B$30/$A6,Summary!$B$32/(Summary!$B$21*12*(G$5/12)*(1+G$5/12)^(Summary!$B$11*12)/((1+G$5/12)^(Summary!$B$11*12)-1)),Summary!$B$32/Summary!$B$22)
A7: 0.0575 | B7: =MIN(Summary!$B$20*Summary!$B$30/$A7,Summary!$B$32/(Summary!$B$21*12*(B$5/12)*(1+B$5/12)^(Summary!$B$11*12)/((1+B$5/12)^(Summary!$B$11*12)-1)),Summary!$B$32/Summary!$B$22) | C7: =MIN(Summary!$B$20*Summary!$B$30/$A7,Summary!$B$32/(Summary!$B$21*12*(C$5/12)*(1+C$5/12)^(Summary!$B$11*12)/((1+C$5/12)^(Summary!$B$11*12)-1)),Summary!$B$32/Summary!$B$22) | D7: =MIN(Summary!$B$20*Summary!$B$30/$A7,Summary!$B$32/(Summary!$B$21*12*(D$5/12)*(1+D$5/12)^(Summary!$B$11*12)/((1+D$5/12)^(Summary!$B$11*12)-1)),Summary!$B$32/Summary!$B$22) | E7: =MIN(Summary!$B$20*Summary!$B$30/$A7,Summary!$B$32/(Summary!$B$21*12*(E$5/12)*(1+E$5/12)^(Summary!$B$11*12)/((1+E$5/12)^(Summary!$B$11*12)-1)),Summary!$B$32/Summary!$B$22) | F7: =MIN(Summary!$B$20*Summary!$B$30/$A7,Summary!$B$32/(Summary!$B$21*12*(F$5/12)*(1+F$5/12)^(Summary!$B$11*12)/((1+F$5/12)^(Summary!$B$11*12)-1)),Summary!$B$32/Summary!$B$22) | G7: =MIN(Summary!$B$20*Summary!$B$30/$A7,Summary!$B$32/(Summary!$B$21*12*(G$5/12)*(1+G$5/12)^(Summary!$B$11*12)/((1+G$5/12)^(Summary!$B$11*12)-1)),Summary!$B$32/Summary!$B$22)
A8: 0.06 | B8: =MIN(Summary!$B$20*Summary!$B$30/$A8,Summary!$B$32/(Summary!$B$21*12*(B$5/12)*(1+B$5/12)^(Summary!$B$11*12)/((1+B$5/12)^(Summary!$B$11*12)-1)),Summary!$B$32/Summary!$B$22) | C8: =MIN(Summary!$B$20*Summary!$B$30/$A8,Summary!$B$32/(Summary!$B$21*12*(C$5/12)*(1+C$5/12)^(Summary!$B$11*12)/((1+C$5/12)^(Summary!$B$11*12)-1)),Summary!$B$32/Summary!$B$22) | D8: =MIN(Summary!$B$20*Summary!$B$30/$A8,Summary!$B$32/(Summary!$B$21*12*(D$5/12)*(1+D$5/12)^(Summary!$B$11*12)/((1+D$5/12)^(Summary!$B$11*12)-1)),Summary!$B$32/Summary!$B$22) | E8: =MIN(Summary!$B$20*Summary!$B$30/$A8,Summary!$B$32/(Summary!$B$21*12*(E$5/12)*(1+E$5/12)^(Summary!$B$11*12)/((1+E$5/12)^(Summary!$B$11*12)-1)),Summary!$B$32/Summary!$B$22) | F8: =MIN(Summary!$B$20*Summary!$B$30/$A8,Summary!$B$32/(Summary!$B$21*12*(F$5/12)*(1+F$5/12)^(Summary!$B$11*12)/((1+F$5/12)^(Summary!$B$11*12)-1)),Summary!$B$32/Summary!$B$22) | G8: =MIN(Summary!$B$20*Summary!$B$30/$A8,Summary!$B$32/(Summary!$B$21*12*(G$5/12)*(1+G$5/12)^(Summary!$B$11*12)/((1+G$5/12)^(Summary!$B$11*12)-1)),Summary!$B$32/Summary!$B$22)
A9: 0.0625 | B9: =MIN(Summary!$B$20*Summary!$B$30/$A9,Summary!$B$32/(Summary!$B$21*12*(B$5/12)*(1+B$5/12)^(Summary!$B$11*12)/((1+B$5/12)^(Summary!$B$11*12)-1)),Summary!$B$32/Summary!$B$22) | C9: =MIN(Summary!$B$20*Summary!$B$30/$A9,Summary!$B$32/(Summary!$B$21*12*(C$5/12)*(1+C$5/12)^(Summary!$B$11*12)/((1+C$5/12)^(Summary!$B$11*12)-1)),Summary!$B$32/Summary!$B$22) | D9: =MIN(Summary!$B$20*Summary!$B$30/$A9,Summary!$B$32/(Summary!$B$21*12*(D$5/12)*(1+D$5/12)^(Summary!$B$11*12)/((1+D$5/12)^(Summary!$B$11*12)-1)),Summary!$B$32/Summary!$B$22) | E9: =MIN(Summary!$B$20*Summary!$B$30/$A9,Summary!$B$32/(Summary!$B$21*12*(E$5/12)*(1+E$5/12)^(Summary!$B$11*12)/((1+E$5/12)^(Summary!$B$11*12)-1)),Summary!$B$32/Summary!$B$22) | F9: =MIN(Summary!$B$20*Summary!$B$30/$A9,Summary!$B$32/(Summary!$B$21*12*(F$5/12)*(1+F$5/12)^(Summary!$B$11*12)/((1+F$5/12)^(Summary!$B$11*12)-1)),Summary!$B$32/Summary!$B$22) | G9: =MIN(Summary!$B$20*Summary!$B$30/$A9,Summary!$B$32/(Summary!$B$21*12*(G$5/12)*(1+G$5/12)^(Summary!$B$11*12)/((1+G$5/12)^(Summary!$B$11*12)-1)),Summary!$B$32/Summary!$B$22)
A10: 0.0675 | B10: =MIN(Summary!$B$20*Summary!$B$30/$A10,Summary!$B$32/(Summary!$B$21*12*(B$5/12)*(1+B$5/12)^(Summary!$B$11*12)/((1+B$5/12)^(Summary!$B$11*12)-1)),Summary!$B$32/Summary!$B$22) | C10: =MIN(Summary!$B$20*Summary!$B$30/$A10,Summary!$B$32/(Summary!$B$21*12*(C$5/12)*(1+C$5/12)^(Summary!$B$11*12)/((1+C$5/12)^(Summary!$B$11*12)-1)),Summary!$B$32/Summary!$B$22) | D10: =MIN(Summary!$B$20*Summary!$B$30/$A10,Summary!$B$32/(Summary!$B$21*12*(D$5/12)*(1+D$5/12)^(Summary!$B$11*12)/((1+D$5/12)^(Summary!$B$11*12)-1)),Summary!$B$32/Summary!$B$22) | E10: =MIN(Summary!$B$20*Summary!$B$30/$A10,Summary!$B$32/(Summary!$B$21*12*(E$5/12)*(1+E$5/12)^(Summary!$B$11*12)/((1+E$5/12)^(Summary!$B$11*12)-1)),Summary!$B$32/Summary!$B$22) | F10: =MIN(Summary!$B$20*Summary!$B$30/$A10,Summary!$B$32/(Summary!$B$21*12*(F$5/12)*(1+F$5/12)^(Summary!$B$11*12)/((1+F$5/12)^(Summary!$B$11*12)-1)),Summary!$B$32/Summary!$B$22) | G10: =MIN(Summary!$B$20*Summary!$B$30/$A10,Summary!$B$32/(Summary!$B$21*12*(G$5/12)*(1+G$5/12)^(Summary!$B$11*12)/((1+G$5/12)^(Summary!$B$11*12)-1)),Summary!$B$32/Summary!$B$22)
A11: 0.0725 | B11: =MIN(Summary!$B$20*Summary!$B$30/$A11,Summary!$B$32/(Summary!$B$21*12*(B$5/12)*(1+B$5/12)^(Summary!$B$11*12)/((1+B$5/12)^(Summary!$B$11*12)-1)),Summary!$B$32/Summary!$B$22) | C11: =MIN(Summary!$B$20*Summary!$B$30/$A11,Summary!$B$32/(Summary!$B$21*12*(C$5/12)*(1+C$5/12)^(Summary!$B$11*12)/((1+C$5/12)^(Summary!$B$11*12)-1)),Summary!$B$32/Summary!$B$22) | D11: =MIN(Summary!$B$20*Summary!$B$30/$A11,Summary!$B$32/(Summary!$B$21*12*(D$5/12)*(1+D$5/12)^(Summary!$B$11*12)/((1+D$5/12)^(Summary!$B$11*12)-1)),Summary!$B$32/Summary!$B$22) | E11: =MIN(Summary!$B$20*Summary!$B$30/$A11,Summary!$B$32/(Summary!$B$21*12*(E$5/12)*(1+E$5/12)^(Summary!$B$11*12)/((1+E$5/12)^(Summary!$B$11*12)-1)),Summary!$B$32/Summary!$B$22) | F11: =MIN(Summary!$B$20*Summary!$B$30/$A11,Summary!$B$32/(Summary!$B$21*12*(F$5/12)*(1+F$5/12)^(Summary!$B$11*12)/((1+F$5/12)^(Summary!$B$11*12)-1)),Summary!$B$32/Summary!$B$22) | G11: =MIN(Summary!$B$20*Summary!$B$30/$A11,Summary!$B$32/(Summary!$B$21*12*(G$5/12)*(1+G$5/12)^(Summary!$B$11*12)/((1+G$5/12)^(Summary!$B$11*12)-1)),Summary!$B$32/Summary!$B$22)
A14: TABLE 2: Net Cash-Out ($) — Max Loan − ($4.2M payoff + 1% orig + $45K closing)
A15: Cap ↓ / Sizing rate → | B15: 0.06 | C15: 0.065 | D15: 0.07 | E15: 0.075 | F15: 0.08 | G15: 0.085
A16: 0.0525 | B16: =B6-Summary!$B$25-Summary!$B$23*B6-Summary!$B$24 | C16: =C6-Summary!$B$25-Summary!$B$23*C6-Summary!$B$24 | D16: =D6-Summary!$B$25-Summary!$B$23*D6-Summary!$B$24 | E16: =E6-Summary!$B$25-Summary!$B$23*E6-Summary!$B$24 | F16: =F6-Summary!$B$25-Summary!$B$23*F6-Summary!$B$24 | G16: =G6-Summary!$B$25-Summary!$B$23*G6-Summary!$B$24
A17: 0.0575 | B17: =B7-Summary!$B$25-Summary!$B$23*B7-Summary!$B$24 | C17: =C7-Summary!$B$25-Summary!$B$23*C7-Summary!$B$24 | D17: =D7-Summary!$B$25-Summary!$B$23*D7-Summary!$B$24 | E17: =E7-Summary!$B$25-Summary!$B$23*E7-Summary!$B$24 | F17: =F7-Summary!$B$25-Summary!$B$23*F7-Summary!$B$24 | G17: =G7-Summary!$B$25-Summary!$B$23*G7-Summary!$B$24
A18: 0.06 | B18: =B8-Summary!$B$25-Summary!$B$23*B8-Summary!$B$24 | C18: =C8-Summary!$B$25-Summary!$B$23*C8-Summary!$B$24 | D18: =D8-Summary!$B$25-Summary!$B$23*D8-Summary!$B$24 | E18: =E8-Summary!$B$25-Summary!$B$23*E8-Summary!$B$24 | F18: =F8-Summary!$B$25-Summary!$B$23*F8-Summary!$B$24 | G18: =G8-Summary!$B$25-Summary!$B$23*G8-Summary!$B$24
A19: 0.0625 | B19: =B9-Summary!$B$25-Summary!$B$23*B9-Summary!$B$24 | C19: =C9-Summary!$B$25-Summary!$B$23*C9-Summary!$B$24 | D19: =D9-Summary!$B$25-Summary!$B$23*D9-Summary!$B$24 | E19: =E9-Summary!$B$25-Summary!$B$23*E9-Summary!$B$24 | F19: =F9-Summary!$B$25-Summary!$B$23*F9-Summary!$B$24 | G19: =G9-Summary!$B$25-Summary!$B$23*G9-Summary!$B$24
A20: 0.0675 | B20: =B10-Summary!$B$25-Summary!$B$23*B10-Summary!$B$24 | C20: =C10-Summary!$B$25-Summary!$B$23*C10-Summary!$B$24 | D20: =D10-Summary!$B$25-Summary!$B$23*D10-Summary!$B$24 | E20: =E10-Summary!$B$25-Summary!$B$23*E10-Summary!$B$24 | F20: =F10-Summary!$B$25-Summary!$B$23*F10-Summary!$B$24 | G20: =G10-Summary!$B$25-Summary!$B$23*G10-Summary!$B$24
A21: 0.0725 | B21: =B11-Summary!$B$25-Summary!$B$23*B11-Summary!$B$24 | C21: =C11-Summary!$B$25-Summary!$B$23*C11-Summary!$B$24 | D21: =D11-Summary!$B$25-Summary!$B$23*D11-Summary!$B$24 | E21: =E11-Summary!$B$25-Summary!$B$23*E11-Summary!$B$24 | F21: =F11-Summary!$B$25-Summary!$B$23*F11-Summary!$B$24 | G21: =G11-Summary!$B$25-Summary!$B$23*G11-Summary!$B$24

Sheet Source_Register
A1: SOURCE REGISTER — evidence per fact (v2)
A3: Filename | B3: Page/Cell | C3: Fact | D3: Fields it supports
A4: revision-notice.pdf | B4: p.1 | C4: As of 2026-09-01 revised roll supersedes prior. Suite 045 now active; rent +$225. INITIAL SIZING RATE +75 bps; cap rate +25 bps. All other UW rules and payoff unchanged. Update workbook, OM, reconciled facts, risk table. Preserve approved copy exactly. | D4: selected_roll_date, gross_potential_rent, sizing_rate, cap_rate, and all downstream fields
A5: rent-roll-revised.xlsx | B5: Sheet 'Rent Roll' A2; rows 5–52 | C5: Controlling roll as of 2026-09-01. 45 active, 0 pending, 3 vacant (046–048). Suite 045: active, $2,150. | D5: total_units, occupied_units, pending_units, total_area_sf, occupied_area_sf, unit_occupancy, area_occupancy, annual_in_place_rent, gross_potential_rent, type_c_occupied
A6: rent-roll-certified.xlsx | B6: Sheet 'Rent Roll' A2 (2026-08-31) | C6: Prior certified roll — superseded by revised roll per revision-notice.pdf. | D6: (superseded)
A7: rent-roll-archive.xlsx | B7: 2026-06-30 | C7: Stale archive. | D7: (excluded)
A8: manager-cover.pdf | B8: p.1 | C8: Property = Magnolia Terrace, Raleigh NC, multifamily. Group A/B/C = Studio/1BR/2BR. | D8: asset id, type_a/b/c mapping
A9: lease-001.pdf | B9: p.1 | C9: Suite 001 base $1,500/mo. Signed later amendment controls. | D9: unit_001_monthly_rent, risk_unsigned_rent_change
A10: lease-correspondence.pdf | B10: p.1 | C10: Signed amendment (both parties 2026-07-20; effective 2026-08-01): Suite 001 monthly rent +$350 → $1,850 in place. | D10: unit_001_monthly_rent (in-place)
A11: operating-statement.pdf | B11: p.1 table | C11: T12 2025-09 → 2026-08: Collections $876,960; Taxes $102,312; Insurance $34,104; Other opex $136,416; Roof capital $0; Reported NOI $604,128. | D11: reported_t12_noi, uw_tax, uw_insurance, uw_operating_expenses, risk_capital_in_opex
A12: underwriting-instructions.pdf | B12: p.1 | C12: UW rules (unchanged in revision except cap and sizing rates): econ loss 5%; other income $350/unit; mgmt 3%; reserves $300/unit; LTV 65%; DSCR 1.25; DY 9%; amort 30 yr monthly; floor 6.00%; orig 1%; closing $45,000; payoff $4,200,000. Note rate revised to 7.00% per revision-notice.pdf. | D12: cap_rate, sizing_rate, ltv_limit, dscr_limit, debt_yield_limit, maximum_loan, net_cash_out, risk_sizing_floor_binding
A13: insurance.pdf | B13: p.1 | C13: GL policy aggregate limit $2,000,000; eff 2026-07-01 → 2027-06-30. | D13: insurance_policy_limit, risk_missing_insurance
A14: diligence-status.pdf | B14: p.1 | C14: Legal/environmental/PCA/title reviews still pending; not defects. | D14: diligence status

Sheet Named_Fields
A1: NAMED FIELD DELIVERABLES (v2) — value + unit + evidence
A3: Field id | B3: Value | C3: Unit | D3: Evidence | E3: Page/Cell | F3: Calculation / note
A4: total_units | B4: 48 | C4: units | D4: rent-roll-revised.xlsx | E4: rows 5–52 | F4: 48 suites.
A5: occupied_units | B5: 45 | C5: units | D5: rent-roll-revised.xlsx | E5: col D=active | F5: COUNTIF active. Suite 045 now active (was pending).
A6: pending_units | B6: 0 | C6: units | D6: rent-roll-revised.xlsx | E6: col D | F6: No pending on revised roll (Suite 045 now active).
A7: total_area_sf | B7: 40800 | C7: SF | D7: rent-roll-revised.xlsx | E7: col C rows 5–52 | F7: 16×700 + 16×820 + 16×1030 = 40,800.
A8: occupied_area_sf | B8: 37710 | C8: SF | D8: rent-roll-revised.xlsx | E8: col C where D=active | F8: 16 Studios + 16 1BR + 13 2BR = 11,200 + 13,120 + 13,390 = 37,710.
A9: unit_occupancy | B9: 0.9375 | C9: decimal | D9: rent-roll-revised.xlsx | E9: derived | F9: 45 / 48.
A10: area_occupancy | B10: 0.9243 | C10: decimal | D10: rent-roll-revised.xlsx | E10: derived | F10: 37,710 / 40,800.
A11: annual_in_place_rent | B11: 977100 | C11: USD | D11: rent-roll-revised.xlsx | E11: col E × 12 | F11: monthly $81,425 × 12.
A12: unit_001_monthly_rent | B12: 1850 | C12: USD/mo | D12: lease-001.pdf + lease-correspondence.pdf | E12: p.1 each | F12: Base $1,500 + signed amendment +$350 = $1,850. Certified/revised roll still shows $1,500 (pre-amendment) — known resolvable conflict; unchanged in this revision.
A13: gross_potential_rent | B13: 977100 | C13: USD | D13: underwriting-instructions.pdf + rent-roll-revised.xlsx | E13: instr p.1; roll rows | F13: All-suite scheduled × 12 on revised roll, still BEFORE Suite 001 amendment.
A14: uw_egi | B14: 945045 | C14: USD | D14: computed | E14: Summary!B28 | F14: 977,100 × 0.95 + 350 × 48 = 928,245 + 16,800.
A15: uw_tax | B15: 102312 | C15: USD | D15: operating-statement.pdf | E15: p.1 | F15: Unchanged.
... A25: debt_yield_limit | B25: 0.09 | C25: decimal | D25: underwriting-instructions.pdf | E25: p.1 | F25: Unchanged.
A26: maximum_loan | B26: =Summary!B42 | C26: USD | D26: computed | E26: Summary!B42 | F26: MIN(LTV, DSCR, DY) — DSCR still binds.
A27: net_cash_out | B27: =Summary!B51 | C27: USD | D27: computed | E27: Summary!B51 | F27: Max loan − ($4.2M payoff + 1% orig + $45K closing). Positive.
A28: insurance_policy_limit | B28: 2000000 | C28: USD | D28: insurance.pdf | E28: p.1 | F28: GL aggregate limit; unchanged.
A29: selected_roll_date | B29: 2026-09-01 | C29: date | D29: rent-roll-revised.xlsx | E29: A2 | F29: Revised roll now controls per revision-notice.pdf.
A30: reported_t12_noi | B30: 604128 | C30: USD | D30: operating-statement.pdf | E30: p.1 | F30: Unchanged historical figure.
A31: type_a_units | B31: 16 | C31: units | D31: rent-roll-revised.xlsx + manager-cover.pdf | E31: col B; mapping | F31: A=Studio; 16 units.
A32: type_a_occupied | B32: 16 | C32: units | D32: rent-roll-revised.xlsx | E32: B=Studio,D=active | F32: All Studios active.
A33: type_b_units | B33: 16 | C33: units | D33: rent-roll-revised.xlsx + manager-cover.pdf | E33: col B; mapping | F33: B=1BR; 16 units.
A34: type_b_occupied | B34: 16 | C34: units | D34: rent-roll-revised.xlsx | E34: B=1BR,D=active | F34: All 1BR active.
A35: type_c_units | B35: 16 | C35: units | D35: rent-roll-revised.xlsx + manager-cover.pdf | E35: col B; mapping | F35: C=2BR; 16 units.
A36: type_c_occupied | B36: 13 | C36: units | D36: rent-roll-revised.xlsx | E36: B=2BR,D=active | F36: 13 of 16 2BRs active (045 now active; 048 vacant; also 042,045,048 series check → only 048 vacant among 2BRs).
A37: risk_pending_in_occupancy | B37: absent | C37: flag | D37: rent-roll-revised.xlsx + manager-cover.pdf | E37: revised roll | F37: Revised roll has 0 pending units; possession-based count equals leased count. Cleared.
A38: risk_near_term_rollover | B38: absent | C38: flag | D38: rent-roll-revised.xlsx | E38: col F | F38: All active leases expire 2029-08-31; none within 12 months of 2026-09-01.
A39: risk_missing_insurance | B39: absent | C39: flag | D39: insurance.pdf | E39: p.1 | F39: GL policy in force through 2027-06-30.
A40: risk_capital_in_opex | B40: absent | C40: flag | D40: operating-statement.pdf | E40: p.1 | F40: Roof shown at $0 in repairs; correctly capital.
A41: risk_unsigned_rent_change | B41: absent | C41: flag | D41: lease-001.pdf + lease-correspondence.pdf | E41: packet | F41: Only rent change in packet is a signed amendment.
A42: risk_temporary_free_rent | B42: absent | C42: flag | D42: lease-001.pdf | E42: p.1 | F42: No free-rent concession.
A43: risk_sizing_floor_binding | B43: absent | C43: flag | D43: underwriting-instructions.pdf + revision-notice.pdf | E43: revision p.1 | F43: Note 7.00% > floor 6.00%. Note binds; floor not binding.
A44: risk_refinance_shortfall | B44: =IF(Summary!B51<0,"present","absent") | C44: flag | D44: computed | E44: Summary!B51 | F44: Formula: IF(net_cash_out<0,'present','absent'). Still absent.

Sheet IO_Map
A1: INPUT & OUTPUT CELL MAP (unchanged from v1)
A3: INPUTS
A4: Field | B4: Sheet!Cell | C4: Notes
A5: gross_potential_rent | B5: Summary!B6 | C5: Revised: $977,100
A6: cap_rate | B6: Summary!B7 | C6: Revised: 6.00% (+25 bps)
A7: sizing_rate | B7: Summary!B8 | C7: Revised: 7.00% (+75 bps)
A9: OUTPUTS
A10: Field | B10: Sheet!Cell | C10: Notes
A11: uw_egi | B11: Summary!B28 | C11: Live formula
A12: uw_noi | B12: Summary!B30 | C12: Live formula
A13: uw_ncf | B13: Summary!B32 | C13: Live formula
A14: capitalization_value | B14: Summary!B33 | C14: NOI / cap_rate
A15: maximum_loan | B15: Summary!B42 | C15: MIN(LTV, DSCR, DY)
A16: net_cash_out | B16: Summary!B51 | C16: Sources − Uses
