Workbook

Sheet Assumptions
A1: Juniper Flats | Editable underwriting assumptions
A2: As of 2026-08-31. [INPUT] cells may be changed; all downstream sheets recalculate.
A4: Revenue inputs (underwriting scenario, Sep-2026 forward)
A5: Gross potential base rent (annual) [INPUT] | B5: 864000 | C5: Property-and-Plan.pdf p.2, scenario amount
A6: Combined revenue loss % of GPR [INPUT] | B6: 0.06 | C6: Vacancy, concessions, bad debt
A7: Other income / recoveries (annual) [INPUT] | B7: 42000 | C7: Added after revenue loss
A8: Underwritten EGI (calculated) | B8: =B5*(1-B6)+B7 -> 854160
A10: Underwritten operating expense inputs (before reserves)
A11: Real estate taxes [INPUT] | B11: 112000
A12: Property insurance (renewal quote in plan) [INPUT] | B12: 33600
A13: Utilities (T12 actual) [INPUT] | B13: 28800
A14: Repairs and maintenance (T12 46,200 less 6,000 casualty) [INPUT] | B14: 40200
A15: Payroll / contract labor (T12 actual) [INPUT] | B15: 42000
A16: Administrative / legal (T12 actual) [INPUT] | B16: 21600
A17: Management fee - T12 actual floor [INPUT] | B17: 30000
A18: Management fee - % of underwritten EGI [INPUT] | B18: 0.03
A19: Normalized management fee (greater of) | B19: =MAX(B17,B18*B8) -> 30000
A21: Reserves
A22: Units (rent roll count) [INPUT] | B22: 36
A23: Replacement reserves per unit per year [INPUT] | B23: 300
A24: Underwritten replacement reserves | B24: =B22*B23 -> 10800
A26: Valuation and loan terms
A27: Capitalization rate [INPUT] | B27: 0.0575
A28: Cap rate sensitivity increment (separate test) [INPUT] | B28: 0.005
A29: Contract rate (fixed, actual debt service) [INPUT] | B29: 0.059
A30: Underwriting rate floor [INPUT] | B30: 0.0625
A31: Sizing rate base = greater of contract and floor | B31: =MAX(B29,B30) -> 0.0625
A32: Sizing rate increment [INPUT] | B32: 0
A33: Sizing rate used | B33: =B31+B32 -> 0.0625
A34: Amortization (years) [INPUT] | B34: 30
A35: Payments per year [INPUT] | B35: 12
A36: Interest-only period (months) [INPUT] | B36: 24
A37: Maximum LTV [INPUT] | B37: 0.65
A38: Minimum DSCR (NCF after reserves) [INPUT] | B38: 1.25
A39: Minimum debt yield (NCF after reserves) [INPUT] | B39: 0.085
A40: Origination fee % of initial principal [INPUT] | B40: 0.0075
A41: Existing debt payoff [INPUT] | B41: 3300000
A42: Fixed closing costs [INPUT] | B42: 45000
A44: Downside test parameters
A45: EGI stress factor [INPUT] | B45: 0.95
...

Sheet T12
A1: Historical T12 | September 2025 - August 2026 (actual)
A2: Source: T12-Statement.pdf pp.1-2, Annual column. Historical only - not underwriting.
A4: Gross potential base rent | B4: 840000
A5: Vacancy loss | B5: -42000
A6: Concessions | B6: -12000
A7: Bad debt | B7: -4500
A8: Net rental income | B8: =SUM(B4:B7) -> 781500
A9: Other income / recoveries | B9: 39600
A10: T12 effective gross income (EGI) | B10: =B8+B9 -> 821100
A12: Real estate taxes | B12: 108000
A13: Property insurance | B13: 31200
A14: Utilities | B14: 28800
A15: Repairs and maintenance (incl. 6,000 one-time casualty) | B15: 46200
A16: Payroll / contract labor | B16: 42000
A17: Administrative / legal | B17: 21600
A18: Management fee | B18: 30000
A19: T12 operating expenses (excl. reserves/capex/debt/depreciation) | B19: =SUM(B12:B18) -> 307800
A20: T12 NOI before replacement reserves | B20: =B10-B19 -> 513300
A21: Replacement reserves (below NOI) | B21: 10800
A22: T12 NCF after replacement reserves | B22: =B20-B21 -> 502500
A24: Below-the-line items shown for reconciliation only
A25: Capital improvements | B25: 62000
A26: Loan principal and interest (existing debt) | B26: 294000
A27: Depreciation (noncash) | B27: 180000
A29: Note: the accounting package may label cash flow after reserves as 'property NOI'; both measures are shown separately above.

Sheet RentRoll
A1: Rent roll summary | as of 2026-08-31
A2: Source: Rent-Roll.xlsx 'Rent Roll' rows 7-42. Vacant units 109, 125, 136 carry market rent only.
A4: Unit type | B4: Units | C4: Occupied | D4: Area SF/unit | E4: Monthly rent/unit | F4: Total SF | G4: Occupied SF
A5: One-bedroom (units 101-120) | B5: 20 | C5: 19 | D5: 750 | E5: 1675 | F5: =B5*D5 -> 15000 | G5: =C5*D5 -> 14250
A6: Two-bedroom (units 121-136) | B6: 16 | C6: 14 | D6: 1050 | E6: 2175 | F6: =B6*D6 -> 16800 | G6: =C6*D6 -> 14700
A7: Total / weighted | B7: =SUM(B5:B6) -> 36 | C7: =SUM(C5:C6) -> 33 | F7: =SUM(F5:F6) -> 31800 | G7: =SUM(G5:G6) -> 28950
A9: space_count (units) | B9: =B7 -> 36
A10: occupied_count | B10: =C7 -> 33
A11: total_area_sf | B11: =F7 -> 31800
A12: occupied_area_sf | B12: =G7 -> 28950
A13: occupancy_count_pct | B13: =100*B10/B9 -> 91.666667
A14: occupancy_area_pct | B14: =100*B12/B11 -> 91.037736
A15: rent_roll_monthly_base (as printed) | B15: =C5*E5+C6*E6 -> 62275
A16: effective_monthly_base (after authoritative lease review) | B16: =B15 -> 62275
A17: Annualized contractual base rent (context only) | B17: =B16*12 -> 747300
A19: No executed amendment changes unit 101 rent (Lease-File.pdf p.1 s.3); rent roll and lease agree at $1,675/month. Annualized contractual rent is not used as underwritten EGI.

Sheet Underwriting
A1: Underwritten cash flow | scenario, September 2026 forward
A2: Driven by editable inputs on Assumptions. Separate from historical T12.
A4: Gross potential base rent | B4: =Assumptions!B5 -> 864000
A5: Combined revenue loss (vacancy/concessions/bad debt) | B5: =-Assumptions!B5*Assumptions!B6 -> -51840
A6: Other income / recoveries | B6: =Assumptions!B7 -> 42000
A7: Underwritten EGI (uw_egi) | B7: =B4+B5+B6 -> 854160
A9: Real estate taxes | B9: =Assumptions!B11 -> 112000
A10: Property insurance | B10: =Assumptions!B12 -> 33600
A11: Utilities | B11: =Assumptions!B13 -> 28800
A12: Repairs and maintenance (normalized) | B12: =Assumptions!B14 -> 40200
A13: Payroll / contract labor | B13: =Assumptions!B15 -> 42000
A14: Administrative / legal | B14: =Assumptions!B16 -> 21600
A15: Management fee (lender-normalized, greater-of test) | B15: =MAX(Assumptions!B17,Assumptions!B18*B7) -> 30000
A16: Total underwritten operating expenses before reserves | B16: =SUM(B9:B15) -> 308200
A17: Underwritten NOI before reserves | B17: =B7-B16 -> 545960
A18: Replacement reserves ($/unit/yr x units) | B18: =Assumptions!B24 -> 10800
A19: Underwritten NCF after reserves | B19: =B17-B18 -> 535160
A21: Capitalization rate | B21: =Assumptions!B27 -> 0.0575
A22: Indicative capitalization value (NOI before reserves / cap rate) | B22: =B17/B21 -> 9494956.5
A24: Expense ratio (opex before reserves / EGI) | B24: =B16/B7 -> 0.36082233

Sheet Sizing
A1: Loan sizing | three constraints
A2: Lender definitions per Lender-Terms.pdf p.1. Sizing uses unrounded values.
A4: Underwritten NOI before reserves | B4: =Underwriting!B17 -> 545960
A5: Underwritten NCF after reserves | B5: =Underwriting!B19 -> 535160
A6: Sizing rate (greater of contract and floor, plus increment) | B6: =Assumptions!B33 -> 0.0625
A7: Annual debt constant per $1 (12 monthly payments, 30-yr amort) | B7: =-Assumptions!B35*PMT(B6/Assumptions!B35,Assumptions!B34*Assumptions!B35,1) -> 0.073886064
A9: Indicative value (NOI before reserves / cap rate) | B9: =Underwriting!B22 -> 9494956.5
A10: LTV constraint (65% of value) | B10: =Assumptions!B37*B9 -> 6171721.7
A11: DSCR constraint ((NCF / 1.25x) / annual constant) | B11: =(B5/Assumptions!B38)/B7 -> 5794435.1
A12: Debt-yield constraint (NCF after reserves / 8.50%) | B12: =B5/Assumptions!B39 -> 6296000
A14: Maximum loan (lowest constraint) | B14: =MIN(B10,B11,B12) -> 5794435.1
A15: Binding constraint | B15: =IF(B14=B10,"LTV",IF(B14=B11,"DSCR","Debt yield")) -> DSCR
A17: Sizing annual debt service (max loan x annual constant) | B17: =B14*B7 -> 428128
A18: Sizing DSCR (NCF / sizing debt service) | B18: =B5/B17 -> 1.25
A19: Sizing debt yield (NCF / max loan) | B19: =B5/B14 -> 0.09235758
A20: Sizing LTV (max loan / value) | B20: =B14/B9 -> 0.61026452
A21: First-year contractual debt service (24-mo IO at contract rate) | B21: =IF(Assumptions!B36>=12,B14*Assumptions!B29,B14*-Assumptions!B35*PMT(Assumptions!B29/Assumptions!B35,Assumptions!B34*Assumptions!B35,1)) -> 341871.67
A22: Post-IO amortizing debt service at contract rate (context) | B22: =B14*-Assumptions!B35*PMT(Assumptions!B29/Assumptions!B35,Assumptions!B34*Assumptions!B35,1) -> 412426.92
A23: Actual first-year DSCR on NCF (IO basis) | B23: =B5/B21 -> 1.5653827
A24: Sizing debt service less first-year actual debt service | B24: =B17-B21 -> 86256.331

Sheet SourcesUses
A1: Sources and uses at maximum loan
A2: No fee capitalization, interest reserve or holdback assumed (Lender-Terms.pdf p.1).
A4: Sources
A5: New first-mortgage loan | B5: =Sizing!B14 -> 5794435.1
A6: Total sources | B6: =B5 -> 5794435.1
A8: Uses
A9: Existing debt payoff | B9: =Assumptions!B41 -> 3300000
A10: Origination fee (0.75% of initial principal) | B10: =Assumptions!B40*B5 -> 43458.263
A11: Fixed closing costs | B11: =Assumptions!B42 -> 45000
A12: Net cash to borrower (negative = cash in) | B12: =B5-B9-B10-B11 -> 2405976.8
A13: Total uses | B13: =B9+B10+B11+B12 -> 5794435.1

Sheet Sensitivity
A1: Sensitivity | EGI, sizing rate and cap rate tests
A2: Management fee re-tested in each case; other operating expenses and reserves held constant.
A4: Scenario | B4: EGI -5% only | C4: Combined EGI -5% & rate +100bps | D4: Cap rate +50bps only | E4: Base case
A5: EGI factor | B5: =Assumptions!B45 -> 0.95 | C5: =Assumptions!B45 -> 0.95 | D5: 1 | E5: 1
A6: Sizing rate delta | B6: 0 | C6: =Assumptions!B46 -> 0.01 | D6: 0 | E6: 0
A7: Cap rate delta | B7: 0 | C7: 0 | D7: =Assumptions!B28 -> 0.005 | E7: 0
A9: Stressed EGI | B9: =Underwriting!$B$7*B5 -> 811452 | C9: =Underwriting!$B$7*C5 -> 811452 | D9: =Underwriting!$B$7*D5 -> 854160 | E9: =Underwriting!$B$7*E5 -> 854160
A10: Operating expenses (mgmt re-tested) | B10: =Underwriting!$B$16-Underwriting!$B$15+MAX(Assumptions!$B$17,Assumptions!$B$18*B9) -> 308200 | C10: =Underwriting!$B$16-Underwriting!$B$15+MAX(Assumptions!$B$17,Assumptions!$B$18*C9) -> 308200 | D10: =Underwriting!$B$16-Underwriting!$B$15+MAX(Assumptions!$B$17,Assumptions!$B$18*D9) -> 308200 | E10: =Underwriting!$B$16-Underwriting!$B$15+MAX(Assumptions!$B$17,Assumptions!$B$18*E9) -> 308200
A11: NOI before reserves | B11: =B9-B10 -> 503252 | C11: =C9-C10 -> 503252 | D11: =D9-D10 -> 545960 | E11: =E9-E10 -> 545960
A12: NCF after reserves | B12: =B11-Assumptions!$B$24 -> 492452 | C12: =C11-Assumptions!$B$24 -> 492452 | D12: =D11-Assumptions!$B$24 -> 535160 | E12: =E11-Assumptions!$B$24 -> 535160
A13: Indicative value | B13: =B11/(Assumptions!$B$27+B7) -> 8752208.7 | C13: =C11/(Assumptions!$B$27+C7) -> 8752208.7 | D13: =D11/(Assumptions!$B$27+D7) -> 8735360 | E13: =E11/(Assumptions!$B$27+E7) -> 9494956.5
A14: Annual debt constant at scenario sizing rate | B14: =-Assumptions!$B$35*PMT((Assumptions!$B$33+B6)/Assumptions!$B$35,Assumptions!$B$34*Assumptions!$B$35,1) -> 0.073886064 | C14: =-Assumptions!$B$35*PMT((Assumptions!$B$33+C6)/Assumptions!$B$35,Assumptions!$B$34*Assumptions!$B$35,1) -> 0.081861154 | D14: =-Assumptions!$B$35*PMT((Assumptions!$B$33+D6)/Assumptions!$B$35,Assumptions!$B$34*Assumptions!$B$35,1) -> 0.073886064 | E14: =-Assumptions!$B$35*PMT((Assumptions!$B$33+E6)/Assumptions!$B$35,Assumptions!$B$34*Assumptions!$B$35,1) -> 0.073886064
A15: LTV constraint | B15: =Assumptions!$B$37*B13 -> 5688935.7 | C15: =Assumptions!$B$37*C13 -> 5688935.7 | D15: =Assumptions!$B$37*D13 -> 5677984 | E15: =Assumptions!$B$37*E13 -> 6171721.7
A16: DSCR constraint | B16: =(B12/Assumptions!$B$38)/B14 -> 5332015 | C16: =(C12/Assumptions!$B$38)/C14 -> 4812558.6 | D16: =(D12/Assumptions!$B$38)/D14 -> 5794435.1 | E16: =(E12/Assumptions!$B$38)/E14 -> 5794435.1
A17: Debt-yield constraint | B17: =B12/Assumptions!$B$39 -> 5793552.9 | C17: =C12/Assumptions!$B$39 -> 5793552.9 | D17: =D12/Assumptions!$B$39 -> 6296000 | E17: =E12/Assumptions!$B$39 -> 6296000
A18: Maximum loan | B18: =MIN(B15,B16,B17) -> 5332015 | C18: =MIN(C15,C16,C17) -> 4812558.6 | D18: =MIN(D15,D16,D17) -> 5677984 | E18: =MIN(E15,E16,E17) -> 5794435.1
A19: Binding constraint | B19: =IF(B18=B15,"LTV",IF(B18=B16,"DSCR","Debt yield")) -> DSCR | C19: =IF(C18=C15,"LTV",IF(C18=C16,"DSCR","Debt yield")) -> DSCR | D19: =IF(D18=D15,"LTV",IF(D18=D16,"DSCR","Debt yield")) -> LTV | E19: =IF(E18=E15,"LTV",IF(E18=E16,"DSCR","Debt yield")) -> DSCR
A20: Change in maximum loan vs base | B20: =B18-$E$18 -> -462420.08 | C20: =C18-$E$18 -> -981876.45 | D20: =D18-$E$18 -> -116451.06

Sheet Map
A1: Reviewer map | where to change inputs and read outputs
A2: Change only the [INPUT] cells on Assumptions; every output below is a live formula.
A4: Item | B4: Location | C4: Current value / note
A5: Cap rate (input) | B5: Assumptions!B27 | C5: =TEXT(Assumptions!B27,"0.00%") -> 5.75%
A6: Cap rate sensitivity increment (input) | B6: Assumptions!B28 | C6: =TEXT(Assumptions!B28,"0.00%") -> 0.50%
A7: Sizing rate increment (input) | B7: Assumptions!B32 | C7: =TEXT(Assumptions!B33,"0.000%")&" sizing rate used" -> 6.250% sizing rate used
A8: Contract rate (input) | B8: Assumptions!B29 | C8: =TEXT(Assumptions!B29,"0.000%") -> 5.900%
A9: EGI drivers (inputs) | B9: Assumptions!B5, B6, B7 | C9: Gross potential rent, loss %, other income
A10: Underwritten EGI (output) | B10: Underwriting!B7 | C10: =Underwriting!B7 -> 854160
A11: UW NOI before reserves (output) | B11: Underwriting!B17 | C11: =Underwriting!B17 -> 545960
A12: UW NCF after reserves (output) | B12: Underwriting!B19 | C12: =Underwriting!B19 -> 535160
A13: Capitalization value (output) | B13: Underwriting!B22 | C13: =Underwriting!B22 -> 9494956.5
A14: LTV / DSCR / DY limits (outputs) | B14: Sizing!B10, B11, B12 | C14: =TEXT(Sizing!B10,"#,##0")&" / "&TEXT(Sizing!B11,"#,##0")&" / "&TEXT(Sizing!B12,"#,##0") -> 6,171,722 / 5,794,435 / 6,296,000
A15: Maximum loan (output) | B15: Sizing!B14 | C15: =Sizing!B14 -> 5794435.1
A16: Binding constraint (output) | B16: Sizing!B15 | C16: =Sizing!B15 -> DSCR
A17: Sizing DS / DSCR / debt yield (outputs) | B17: Sizing!B17, B18, B19 | C17: =TEXT(Sizing!B17,"#,##0")&" / "&TEXT(Sizing!B18,"0.000")&" / "&TEXT(Sizing!B19,"0.00%") -> 428,128 / 1.250 / 9.24%
A18: First-year contractual debt service (output) | B18: Sizing!B21 | C18: =Sizing!B21 -> 341871.67
A19: Net cash to borrower (output) | B19: SourcesUses!B12 | C19: =SourcesUses!B12 -> 2405976.8
A20: Downside NOI / downside max loan (outputs) | B20: Sensitivity!B11, Sensitivity!C18 | C20: =TEXT(Sensitivity!B11,"#,##0")&" / "&TEXT(Sensitivity!C18,"#,##0") -> 503,252 / 4,812,559
A21: T12 EGI / NOI / NCF (outputs) | B21: T12!B10, B20, B22 | C21: =TEXT('T12'!B10,"#,##0")&" / "&TEXT('T12'!B20,"#,##0")&" / "&TEXT('T12'!B22,"#,##0") -> 821,100 / 513,300 / 502,500
A22: Rent roll metrics (outputs) | B22: RentRoll!B9:B16 | C22: =TEXT(RentRoll!B15,"#,##0")&" monthly base; "&TEXT(RentRoll!B14,"0.00")&"% occupancy by area" -> 62,275 monthly base; 91.04% occupancy by area
