Workbook

Sheet README
B2: Stonebridge Logistics — Refinance Underwriting Workbook
B3: As of August 31, 2026 · USD · Fictional evaluation material · No real transaction
B5: Legend
B6: Yellow cells | C6: Editable input assumptions — reviewer can change these
B7: Green cells | C7: Calculated with live formulas
B8: Orange cells | C8: Key results (maximum loan, binding constraint, etc.)
B10: Sheet Map
B11: Assumptions | C11: All editable inputs (cap rate, sizing rate, EGI drivers, expenses, loan terms)
B12: Rent Roll | C12: Unit-level rent roll, occupancy calculations
B13: T12 | C13: Trailing-twelve historical statement, monthly detail + annual
B14: Underwriting | C14: Underwritten EGI, expenses, NOI, NCF — driven by Assumptions
B15: Loan Sizing | C15: LTV / DSCR / Debt Yield tests, binding constraint, sources & uses
B16: Sensitivity | C16: Stress: EGI -5%, Rate +100 bps combined downside; cap +50 bps separately
B17: Fields | C17: All requested analysis field IDs with values / sources
B19: Key Inputs Quick-Access
B20: Cap rate | C20: =Assumptions!C24 -> 0.0725
B21: Sizing rate | C21: =Assumptions!C33 -> 0.0725
B22: Contract rate | C22: =Assumptions!C32 -> 0.0675
B23: Underwritten EGI | C23: =Underwriting!C10 -> 1023000
B24: Underwritten NOI (before reserves) | C24: =Underwriting!C22 -> 760710
B25: Indicative value | C25: ='Loan Sizing'!C6 -> 10492552
B26: Maximum loan | C26: ='Loan Sizing'!C18 -> 6295531
B27: Binding constraint | C27: ='Loan Sizing'!C19 -> LTV

Sheet Assumptions
B2: Editable Assumptions
B4: Property
B5: Total rentable SF | C5: 85000 | D5: From rent roll (sum of unit SF)
B6: As-of date | C6: 2026-08-31 | D6: Rent roll and T12 as-of
B8: Underwriting — Revenue
B9: Gross potential base rent (annual) | C9: 900000 | D9: Supplied scenario per Property-and-Plan p.2
B10: Combined revenue loss % | C10: 0.08 | D10: Vacancy + concessions + bad debt per plan
B11: Other income / recoveries (annual) | C11: 195000 | D11: Added after revenue loss
B13: Underwriting — Operating Expenses (annual)
B14: Real estate taxes | C14: 132000 | D14: Plan override; T12 was $126,000
B15: Property insurance | C15: 33600 | D15: Renewal quote in plan (verified renewal confirmation Aug 25, 2026)
B16: Utilities | C16: 12000 | D16: Use T12 actual
B17: Repairs & maintenance | C17: 18000 | D17: T12 $24,000 less $6,000 one-time casualty cleanup
B18: Payroll / contract labor | C18: 18000 | D18: Use T12 actual
B19: Administrative / legal | C19: 18000 | D19: Use T12 actual
B20: Management — T12 actual | C20: 25200 | D20: Historical T12 mgmt fee
B21: Management — % of underwritten EGI | C21: 0.03 | D21: Plan: greater of T12 actual OR 3% of underwritten EGI
B22: Replacement reserves ($/SF/yr) | C22: 0.2 | D22: Deducted BELOW NOI
B24: Cap rate (valuation) | C24: 0.0725 | D24: NOI BEFORE reserves ÷ cap rate; no appraisal implied
B26: Loan Terms
B27: Index rate | C27: 0.0325 | D27: Lender Terms
B28: Index floor | C28: 0.04 | D28: Apply floor BEFORE spread
B29: Spread | C29: 0.0275 | D29: Added AFTER floor
B30: Sizing rate floor | C30: 0.0725 | D30: Underwriting floor
B31: Effective index (after floor) | C31: =MAX(C27,C28) -> 0.04 | D31: MAX(index, floor)
B32: Contract rate | C32: =C31+C29 -> 0.0675 | D32: Effective index + spread
B33: Sizing rate | C33: =MAX(C32,C30) -> 0.0725 | D33: Greater of contract rate and 7.25%
B34: Amortization (years) | C34: 25 | D34: Monthly payments
B35: Interest-only period (months) | C35: 12 | D35: First 12 months IO
B36: Maturity (months) | C36: 36
B38: Loan Sizing Constraints
B39: Max LTV | C39: 0.6 | D39: Applied to indicative value
B40: Min DSCR | C40: 1.3 | D40: NCF after reserves ÷ amortizing DS at sizing rate
B41: Min debt yield | C41: 0.1 | D41: NCF after reserves ÷ loan
B43: Fees & Uses
B44: Existing debt payoff | C44: 4200000 | D44: Property plan
B45: Fixed closing costs | C45: 70000 | D45: Property plan
B46: Origination fee % of loan | C46: 0.0125 | D46: 1.25% of actual initial principal
B48: Sensitivity Levers
B49: EGI stress % | C49: -0.05 | D49: Downside EGI adjustment
...

Sheet Rent Roll
B2: Rent Roll — As of 2026-08-31
B4: Unit | C4: Tenant | D4: Area SF | E4: Status | F4: Monthly Base Rent | G4: Market Monthly Rent | H4: Lease Expiry
B5: 101 | C5: Tenant A LLC | D5: 18000 | E5: Occupied | F5: 15000 | G5: 15000 | H5: 2030-08-31
B6: 102 | C6: Tenant B LLC | D6: 22000 | E6: Occupied | F6: 18700 | G6: 18700 | H6: 2028-08-31
B7: 103 | C7: Tenant C LLC | D7: 30000 | E7: Occupied | F7: 27000 | G7: 27000 | H7: 2029-08-31
B8: 104 | C8: Vacant | D8: 15000 | E8: Vacant | G8: 12500
B10: Totals | D10: =SUM(D5:D8) -> 85000 | F10: =SUM(F5:F8) -> 60700 | G10: =SUM(G5:G8) -> 73200
B12: Occupancy Summary
B13: Total space count | C13: =COUNTA(B5:B8) -> 4
B14: Occupied count | C14: =COUNTIF(E5:E8,"Occupied") -> 3
B15: Total area SF | C15: =SUM(D5:D8) -> 85000
B16: Occupied area SF | C16: =SUMIF(E5:E8,"Occupied",D5:D8) -> 70000
B17: Occupancy by count % | C17: =C14/C13 -> 0.75
B18: Occupancy by area % | C18: =C16/C15 -> 0.82352941
B19: Rent roll monthly base | C19: =SUM(F5:F8) -> 60700
B20: Effective monthly base (after amendments) | C20: =C19 -> 60700 | D20: Lease file confirms Unit 101 $15,000/mo as of 2026-08-31; no amendments

Sheet T12
B2: Trailing 12 Months (Sep-2025 to Aug-2026) — Annual
B4: Gross potential base rent | C4: 852000 | D4: T12 p.2 Annual
B5: Vacancy loss | C5: -150000 | D5: T12
B6: Concessions | C6: -36000 | D6: T12
B7: Bad debt | C7: -6000 | D7: T12
B8: Other income / recoveries | C8: 186000 | D8: T12
B9: Effective Gross Income (EGI) | C9: =SUM(C4:C8) -> 846000
B11: Operating expenses
B12: Real estate taxes | C12: 126000
B13: Property insurance | C13: 30000
B14: Utilities | C14: 12000
B15: Repairs and maintenance | C15: 24000
B16: Payroll / contract labor | C16: 18000
B17: Administrative / legal | C17: 18000
B18: Management fee | C18: 25200
B19: Total operating expenses | C19: =SUM(C12:C18) -> 253200
B21: NOI before replacement reserves | C21: =C9-C19 -> 592800
B22: Replacement reserves (below NOI) | C22: 17000
B23: Net cash flow after reserves | C23: =C21-C22 -> 575800
B25: Memo — below cash flow / non-operating
B26: Capital improvements | C26: 220000 | D26: Not an operating expense
B27: Loan principal & interest | C27: 294000 | D27: Existing debt service
B28: Depreciation (noncash) | C28: 180000 | D28: Excluded from NOI

Sheet Underwriting
B2: Underwritten Cash Flow — driven by Assumptions
B4: Gross potential base rent | C4: =Assumptions!C9 -> 900000 | D4: Assumptions!C9
B5: Combined revenue loss (vac + conc + bad debt) | C5: =-C4*Assumptions!C10 -> -72000 | D5: -GPR × loss %
B6: Other income / recoveries | C6: =Assumptions!C11 -> 195000
B10: Effective Gross Income (EGI) | C10: =C4+C5+C6 -> 1023000
B12: Operating expenses
B13: Real estate taxes | C13: =Assumptions!C14 -> 132000
B14: Property insurance | C14: =Assumptions!C15 -> 33600
B15: Utilities | C15: =Assumptions!C16 -> 12000
B16: Repairs & maintenance | C16: =Assumptions!C17 -> 18000
B17: Payroll / contract labor | C17: =Assumptions!C18 -> 18000
B18: Administrative / legal | C18: =Assumptions!C19 -> 18000
B19: Management fee (max of T12 or % of EGI) | C19: =MAX(Assumptions!C20,Assumptions!C21*C10) -> 30690 | D19: =MAX(T12 actual, % × EGI)) -> #N/A
B20: Total operating expenses | C20: =SUM(C13:C19) -> 262290
B22: NOI before replacement reserves | C22: =C10-C20 -> 760710 | D22: EGI − total operating expenses
B23: Replacement reserves | C23: =Assumptions!C22*Assumptions!C5 -> 17000 | D23: $/SF × total SF
B24: Net cash flow after reserves | C24: =C22-C23 -> 743710

Sheet Loan Sizing
B2: Loan Sizing — LTV / DSCR / Debt Yield
B4: Valuation basis
B5: Underwritten NOI before reserves | C5: =Underwriting!C22 -> 760710 | D5: Underwriting sheet
B6: Indicative value | C6: =C5/Assumptions!C24 -> 10492552 | D6: NOI before reserves ÷ cap rate
B8: Underwritten NCF after reserves | C8: =Underwriting!C24 -> 743710
B10: Sizing rate | C10: =Assumptions!C33 -> 0.0725
B11: Annual debt constant | C11: =-12*PMT(C10/12,Assumptions!C34*12,1) -> 0.086736824 | D11: Amortizing DS per $1 principal, 25-yr monthly
B13: Constraint | C13: Maximum Loan | D13: Formula
B14: LTV (60% of value) | C14: =Assumptions!C39*C6 -> 6295531 | D14: =ltv × value -> #N/A
B15: DSCR (min 1.30x) | C15: =C8/(Assumptions!C40*C11) -> 6595637.1 | D15: NCF ÷ (min DSCR × debt constant)
B16: Debt yield (min 10%) | C16: =C8/Assumptions!C41 -> 7437100 | D16: NCF ÷ min DY
B18: Maximum loan (binding minimum) | C18: =MIN(C14:C16) -> 6295531
B19: Binding constraint | C19: =IF(C18=C14,"LTV",IF(C18=C15,"DSCR","Debt yield")) -> LTV
B21: Sizing annual debt service | C21: =C18*C11 -> 546054.37
B22: Sizing DSCR | C22: =C8/C21 -> 1.3619706
B23: Sizing debt yield | C23: =C8/C18 -> 0.11813301
B25: Contract rate | C25: =Assumptions!C32 -> 0.0675
B26: First-year debt service (12-mo IO at contract rate) | C26: =C18*C25 -> 424948.34 | D26: IO year: principal × contract rate
B29: Sources & Uses
B30: SOURCES
B31: New first mortgage | C31: =C18 -> 6295531
B32: Borrower cash-in (if negative below) | C32: =MAX(0,-C39) -> 0
B33: Total sources | C33: =C31+C32 -> 6295531
B35: USES
B36: Existing debt payoff | C36: =Assumptions!C44 -> 4200000
B37: Origination fee (1.25% of loan) | C37: =Assumptions!C46*C18 -> 78694.138
B38: Fixed closing costs | C38: =Assumptions!C45 -> 70000
B39: Cash to borrower (positive) / cash-in (negative) | C39: =C18-C36-C37-C38 -> 1946836.9
B40: Total uses | C40: =C36+C37+C38+MAX(0,C39)+MAX(0,-C39) -> 6295531

Sheet Sensitivity
B2: Sensitivity Analysis
C4: Base case | D4: Downside
B5: EGI adjustment | C5: =0 -> 0 | D5: =Assumptions!C49 -> -0.05
B6: Sizing-rate adjustment | C6: =0 -> 0 | D6: =Assumptions!C50/10000 -> 0.01
B8: EGI | C8: =Underwriting!C10*(1+C5) -> 1023000 | D8: =Underwriting!C10*(1+D5) -> 971850
B9: Management fee (recalculated) | C9: =MAX(Assumptions!C20,Assumptions!C21*C8) -> 30690 | D9: =MAX(Assumptions!C20,Assumptions!C21*D8) -> 29155.5
B10: Other operating expenses (unchanged) | C10: =Assumptions!C14+Assumptions!C15+Assumptions!C16+Assumptions!C17+Assumptions!C18+Assumptions!C19 -> 231600 | D10: =C10 -> 231600
B11: Total operating expenses | C11: =C9+C10 -> 262290 | D11: =D9+D10 -> 260755.5
B12: NOI before reserves | C12: =C8-C11 -> 760710 | D12: =D8-D11 -> 711094.5
B13: Reserves | C13: =Assumptions!C22*Assumptions!C5 -> 17000 | D13: =C13 -> 17000
B14: NCF after reserves | C14: =C12-C13 -> 743710 | D14: =D12-D13 -> 694094.5
B16: Cap rate | C16: =Assumptions!C24 -> 0.0725 | D16: =Assumptions!C24 -> 0.0725
B17: Sizing rate | C17: =Assumptions!C33+C6 -> 0.0725 | D17: =Assumptions!C33+D6 -> 0.0825
B18: Annual debt constant | C18: =-12*PMT(C17/12,Assumptions!C34*12,1) -> 0.086736824 | D18: =-12*PMT(D17/12,Assumptions!C34*12,1) -> 0.094614016
B20: Indicative value (NOI ÷ cap rate) | C20: =C12/C16 -> 10492552 | D20: =D12/D16 -> 9808200
B21: LTV limit | C21: =Assumptions!C39*C20 -> 6295531 | D21: =Assumptions!C39*D20 -> 5884920
B22: DSCR limit | C22: =C14/(Assumptions!C40*C18) -> 6595637.1 | D22: =D14/(Assumptions!C40*D18) -> 5643126.3
B23: Debt yield limit | C23: =C14/Assumptions!C41 -> 7437100 | D23: =D14/Assumptions!C41 -> 6940945
B24: Maximum loan | C24: =MIN(C21:C23) -> 6295531 | D24: =MIN(D21:D23) -> 5643126.3
B25: Binding constraint | C25: =IF(C24=C21,"LTV",IF(C24=C22,"DSCR","Debt yield")) -> LTV | D25: =IF(D24=D21,"LTV",IF(D24=D22,"DSCR","Debt yield")) -> DSCR
B28: Separate cap-rate sensitivity (+50 bps default)
B29: Cap rate + adjustment | C29: =Assumptions!C24+Assumptions!C51/10000 -> 0.0775
B30: Stressed value | C30: =Underwriting!C22/C29 -> 9815612.9
B31: LTV limit under stressed cap | C31: =Assumptions!C39*C30 -> 5889367.7
B32: Maximum loan (LTV vs DSCR vs DY base) | C32: =MIN(C31, 'Loan Sizing'!C15, 'Loan Sizing'!C16) -> 5889367.7

Sheet Fields
B2: Analysis Fields
B4: Field ID | C4: Value | D4: Source / Calculation
B5: space_count | C5: ='Rent Roll'!C13 -> 4 | D5: Rent-Roll.xlsx — count of unit rows
B6: occupied_count | C6: ='Rent Roll'!C14 -> 3 | D6: Rent-Roll.xlsx — Status='Occupied'
B7: total_area_sf | C7: ='Rent Roll'!C15 -> 85000 | D7: Rent-Roll.xlsx — SUM Area SF
B8: occupied_area_sf | C8: ='Rent Roll'!C16 -> 70000 | D8: Rent-Roll.xlsx — SUMIF occupied
B9: occupancy_count_pct | C9: ='Rent Roll'!C17*100 -> 75 | D9: Occupied count / total × 100
B10: occupancy_area_pct | C10: ='Rent Roll'!C18*100 -> 82.352941 | D10: Occupied SF / total SF × 100
B11: rent_roll_monthly_base | C11: ='Rent Roll'!C19 -> 60700 | D11: Rent-Roll.xlsx — SUM Monthly Base Rent
B12: effective_monthly_base | C12: ='Rent Roll'!C20 -> 60700 | D12: Lease-File.pdf confirms Unit 101 $15,000/mo; no amendments — equals rent roll
B13: t12_egi | C13: ='T12'!C9 -> 846000 | D13: T12-Statement.pdf p.2 Annual column
B14: t12_operating_expenses | C14: ='T12'!C19 -> 253200 | D14: T12 opex: taxes+ins+util+R&M+payroll+admin+mgmt
B15: t12_noi_before_reserves | C15: ='T12'!C21 -> 592800 | D15: T12 EGI − opex (before reserves)
B16: t12_reserves | C16: ='T12'!C22 -> 17000 | D16: T12 replacement reserves
B17: t12_ncf | C17: ='T12'!C23 -> 575800 | D17: T12 NOI before reserves − reserves
B18: uw_egi | C18: =Underwriting!C10 -> 1023000 | D18: Property-and-Plan p.2 UW scenario
B19: uw_management_fee | C19: =Underwriting!C19 -> 30690 | D19: MAX(T12 $25,200; 3% × UW EGI)
B20: uw_operating_expenses | C20: =Underwriting!C20 -> 262290 | D20: UW opex before reserves
B21: uw_noi_before_reserves | C21: =Underwriting!C22 -> 760710 | D21: UW EGI − UW opex
B22: uw_reserves | C22: =Underwriting!C23 -> 17000 | D22: $0.20/SF × 85,000 SF
B23: uw_ncf | C23: =Underwriting!C24 -> 743710 | D23: UW NOI − reserves
B24: capitalization_value | C24: ='Loan Sizing'!C6 -> 10492552 | D24: UW NOI before reserves ÷ 6.75% cap rate
B25: contract_rate | C25: =Assumptions!C32 -> 0.0675 | D25: MAX(3.25%,4.00% floor)+2.75% spread = 6.75%
B26: sizing_rate | C26: =Assumptions!C33 -> 0.0725 | D26: MAX(contract 6.75%, 7.25% floor) = 7.25%
B27: annual_debt_constant | C27: ='Loan Sizing'!C11 -> 0.086736824 | D27: 25-yr monthly amort, sizing rate
B28: ltv_limit | C28: ='Loan Sizing'!C14 -> 6295531 | D28: 60% × indicative value
B29: dscr_limit | C29: ='Loan Sizing'!C15 -> 6595637.1 | D29: NCF ÷ (1.30 × debt constant)
B30: debt_yield_limit | C30: ='Loan Sizing'!C16 -> 7437100 | D30: NCF ÷ 10%
B31: maximum_loan | C31: ='Loan Sizing'!C18 -> 6295531 | D31: MIN of three constraints
B32: binding_constraint | C32: ='Loan Sizing'!C19 -> LTV | D32: Binding of LTV/DSCR/DY
B33: sizing_annual_debt_service | C33: ='Loan Sizing'!C21 -> 546054.37 | D33: Max loan × debt constant
B34: sizing_dscr | C34: ='Loan Sizing'!C22 -> 1.3619706 | D34: NCF ÷ sizing DS
B35: sizing_debt_yield | C35: ='Loan Sizing'!C23 -> 0.11813301 | D35: NCF ÷ max loan
B36: first_year_debt_service | C36: ='Loan Sizing'!C26 -> 424948.34 | D36: IO year: principal × contract rate
B37: cash_to_borrower | C37: ='Loan Sizing'!C39 -> 1946836.9 | D37: Loan − payoff − orig fee − closing
B38: stress_uw_noi | C38: =Sensitivity!D12 -> 711094.5 | D38: EGI -5%, mgmt recalc, other opex unchanged
B39: stress_maximum_loan | C39: =Sensitivity!D24 -> 5643126.3 | D39: Combined downside: EGI -5%, sizing rate +100 bps, cap unchanged
B40: subject_lease_monthly_rent | C40: 15000 | D40: Lease-File.pdf §3 — $15,000/mo as of 2026-08-31
B41: subject_lease_expiry | C41: 2030-08-31 | D41: Lease-File.pdf §2 — Initial term expiry; option not exercised in packet
B42: subject_lease_deposit | C42: 30000 | D42: Lease-File.pdf §4 — $30,000, not prepaid rent
...
