Workbook

Sheet Instructions
A1: Hawthorn Center | Refinance Underwriting Model
A2: Prepared: | B2: 2026-09-01
A3: As-of date: | B3: 2026-08-31
A4: Purpose: | B4: First-mortgage cash-out refinance sizing (internal review)
A5: Source packet: | B5: Property-and-Plan.pdf, Rent-Roll.xlsx, T12-Statement.pdf, Lease-File.pdf, Lender-Terms.pdf
A7: How to use this workbook
A8: Editable inputs | B8: Yellow-filled cells with blue text on the Assumptions tab. Change any and every dependent calculation recalculates.
A9: Recalculate | B9: The model uses formulas, not baked values. Open in Excel/LibreOffice and press F9 if needed.
A10: Never edit | B10: Black-text formulas and green-text cross-sheet links. Historical T12 numbers on the T12 tab are hardcoded from the source PDF and marked as such.
A11: Sensitivities | B11: The Sensitivity tab uses the same formula engine driven by scenario inputs on Assumptions.
A13: Location map — key inputs and outputs
A14: Item | B14: Sheet | C14: Cell
A15: Cap rate (input) | B15: Assumptions | C15: B26
A16: Sizing rate (calc) | B16: Assumptions | C16: B25
A17: Contract rate (input) | B17: Assumptions | C17: B24
A18: Amortization years (input) | B18: Assumptions | C18: B27
A19: LTV cap (input) | B19: Assumptions | C19: B29
A20: DSCR floor (input) | B20: Assumptions | C20: B30
A21: Debt yield floor (input) | B21: Assumptions | C21: B31
A22: Origination fee % (input) | B22: Assumptions | C22: B32
A23: UW GPR (input) | B23: Assumptions | C23: B7
A24: UW combined revenue loss % (input) | B24: Assumptions | C24: B8
A25: UW Other income (input) | B25: Assumptions | C25: B9
... A39: Cap rate +50bps — Max loan | B39: Sensitivity | C39: C14
A41: Legend
A42: Blue text + yellow fill | B42: Editable input
A43: Black text | B43: Formula (do not overwrite)
A44: Green text | B44: Link to another sheet

Sheet Rent Roll
A1: Hawthorn Center | Rent Roll — as of 2026-08-31 (source: Rent-Roll.xlsx)
A3: Unit | B3: Tenant | C3: Area SF | D3: Status | E3: Monthly base rent | F3: Market monthly rent | G3: Lease expiry | H3: Notes
A4: 101 | B4: Tenant A LLC | C4: 1400 | D4: Occupied | E4: 3000 | F4: 3000 | G4: 2029-08-31 | H4: See Lease tab — no exercised renewal notice supplied
A5: 102 | B5: Tenant B LLC | C5: 1800 | D5: Occupied | E5: 4000 | F5: 4000 | G5: 2028-08-31
A6: 103 | B6: Tenant C LLC | C6: 2200 | D6: Occupied | E6: 4900 | F6: 4900 | G6: 2029-08-31
A7: 104 | B7: Tenant D LLC | C7: 2500 | D7: Occupied | E7: 5600 | F7: 5600 | G7: 2030-08-31
A8: 105 | B8: Tenant E LLC | C8: 3000 | D8: Occupied | E8: 6500 | F8: 6500 | G8: 2031-08-31
A9: 106 | B9: Tenant F LLC | C9: 3300 | D9: Occupied | E9: 7400 | F9: 7400 | G9: 2027-08-31
A10: 107 | B10: Tenant G LLC | C10: 3800 | D10: Occupied | E10: 8600 | F10: 8600 | G10: 2028-08-31
A11: 108 | B11: Tenant H LLC | C11: 4200 | D11: Occupied | E11: 9200 | F11: 9200 | G11: 2029-08-31
A12: 109 | B12: Tenant I LLC | C12: 5000 | D12: Occupied | E12: 10800 | F12: 10800 | G12: 2030-08-31
A13: 110 | B13: Vacant | C13: 1600 | D13: Vacant | F13: 3400 | H13: Vacant — no contractual base rent
A14: Totals | C14: =SUM(C4:C13) -> 28800 | E14: =SUM(E4:E13) -> 60000 | F14: =SUM(F4:F13) -> 63400
A16: Summary
A17: space_count | B17: =COUNTA(A4:A13) -> 10
A18: occupied_count | B18: =COUNTIF(D4:D13,"Occupied") -> 9
A19: total_area_sf | B19: =SUM(C4:C13) -> 28800
A20: occupied_area_sf | B20: =SUMIF(D4:D13,"Occupied",C4:C13) -> 27200
A21: occupancy_count_pct (0-100) | B21: =COUNTIF(D4:D13,"Occupied")/COUNTA(A4:A13)*100 -> 90
A22: occupancy_area_pct (0-100) | B22: =SUMIF(D4:D13,"Occupied",C4:C13)/SUM(C4:C13)*100 -> 94.444444
A23: rent_roll_monthly_base | B23: =SUM(E4:E13) -> 60000
A24: annualized rent-roll base | B24: =SUM(E4:E13)*12 -> 720000
A25: effective_monthly_base (post-amendment) | B25: =SUM(E4:E13) -> 60000 | C25: Equals rent-roll total; Lease amendment for Unit 101 confirms $3,000/mo — no adjustment

Sheet T12
A1: Hawthorn Center | T12 Sep-2025 through Aug-2026 (source: T12-Statement.pdf)
A3: Account | B3: Sep-25 | C3: Oct-25 | D3: Nov-25 | E3: Dec-25 | F3: Jan-26 | G3: Feb-26 | H3: Mar-26 | I3: Apr-26 | J3: May-26 | K3: Jun-26 | L3: Jul-26 | M3: Aug-26 | N3: Annual (formula) | O3: Annual (source)
A4: Gross potential base rent | B4: 59502 | C4: 60768 | D4: 62034 | E4: 62667 | F4: 63933 | G4: 65199 | H4: 65832 | I4: 67098 | J4: 65199 | K4: 63933 | L4: 62034 | M4: 61401 | N4: =SUM(B4:M4) -> 759600 | O4: 759600
A5: Vacancy loss | B5: -3264 | C5: -3332 | D5: -3366 | E5: -3434 | F5: -3502 | G5: -3536 | H5: -3604 | I5: -3502 | J5: -3434 | K5: -3332 | L5: -3298 | M5: -3196 | N5: =SUM(B5:M5) -> -40800 | O5: -40800
A6: Concessions | B6: -1862 | C6: -1881 | D6: -1919 | E6: -1957 | F6: -1976 | G6: -2014 | H6: -1957 | I6: -1919 | J6: -1862 | K6: -1843 | L6: -1786 | M6: -1824 | N6: =SUM(B6:M6) -> -22800 | O6: -22800
A7: Bad debt | B7: -495 | C7: -505 | D7: -515 | E7: -520 | F7: -530 | G7: -515 | H7: -505 | I7: -490 | J7: -485 | K7: -470 | L7: -480 | M7: -490 | N7: =SUM(B7:M7) -> -6000 | O7: -6000
A8: Other income / recoveries | B8: 14847 | C8: 15141 | D8: 15288 | E8: 15582 | F8: 15141 | G8: 14847 | H8: 14406 | I8: 14259 | J8: 13818 | K8: 14112 | L8: 14406 | M8: 14553 | N8: =SUM(B8:M8) -> 176400 | O8: 176400
A9: Real estate taxes | B9: 9785 | C9: 9880 | D9: 10070 | E9: 9785 | F9: 9595 | G9: 9310 | H9: 9215 | I9: 8930 | J9: 9120 | K9: 9310 | L9: 9405 | M9: 9595 | N9: =SUM(B9:M9) -> 114000 | O9: 114000
A10: Property insurance | B10: 2808 | C10: 2862 | D10: 2781 | E10: 2727 | F10: 2646 | G10: 2619 | H10: 2538 | I10: 2592 | J10: 2646 | K10: 2673 | L10: 2727 | M10: 2781 | N10: =SUM(B10:M10) -> 32400 | O10: 32400
A11: Utilities | B11: 1908 | C11: 1854 | D11: 1818 | E11: 1764 | F11: 1746 | G11: 1692 | H11: 1728 | I11: 1764 | J11: 1782 | K11: 1818 | L11: 1854 | M11: 1872 | N11: =SUM(B11:M11) -> 21600 | O11: 21600
A12: Repairs and maintenance | B12: 3090 | C12: 3030 | D12: 2940 | E12: 2910 | F12: 2820 | G12: 2880 | H12: 2940 | I12: 2970 | J12: 3030 | K12: 3090 | L12: 3120 | M12: 3180 | N12: =SUM(B12:M12) -> 36000 | O12: 36000
A13: Payroll / contract labor | B13: 2020 | C13: 1960 | D13: 1940 | E13: 1880 | F13: 1920 | G13: 1960 | H13: 1980 | I13: 2020 | J13: 2060 | K13: 2080 | L13: 2120 | M13: 2060 | N13: =SUM(B13:M13) -> 24000 | O13: 24000
A14: Administrative / legal | B14: 1470 | C14: 1455 | D14: 1410 | E14: 1440 | F14: 1470 | G14: 1485 | H14: 1515 | I14: 1545 | J14: 1560 | K14: 1590 | L14: 1545 | M14: 1515 | N14: =SUM(B14:M14) -> 18000 | O14: 18000
A15: Management fee | B15: 1455 | C15: 1410 | D15: 1440 | E15: 1470 | F15: 1485 | G15: 1515 | H15: 1545 | I15: 1560 | J15: 1590 | K15: 1545 | L15: 1515 | M15: 1470 | N15: =SUM(B15:M15) -> 18000 | O15: 18000
... A19: Depreciation (noncash) | B19: 14850 | C19: 15150 | D19: 15450 | E19: 15600 | F19: 15900 | G19: 15450 | H19: 15150 | I19: 14700 | J19: 14550 | K19: 14100 | L19: 14400 | M19: 14700 | N19: =SUM(B19:M19) -> 180000 | O19: 180000
A21: Reconciled T12 (calculated, based on 'Annual (source)')
A22: t12_gpr | B22: =O4 -> 759600
A23: t12_revenue_loss (vac+conc+bad) | B23: =O5+O6+O7 -> -69600
A24: t12_other_income | B24: =O8 -> 176400
A25: t12_egi | B25: =O4+O5+O6+O7+O8 -> 866400 | C25: EGI = GPR + vac + conc + bad + other (vac/conc/bad are negative)
A26: t12_operating_expenses | B26: =O9+O10+O11+O12+O13+O14+O15 -> 264000 | C26: Excludes reserves, capex, debt, depreciation
A27: t12_noi_before_reserves | B27: =O4+O5+O6+O7+O8-(O9+O10+O11+O12+O13+O14+O15) -> 602400
A28: t12_reserves | B28: =O16 -> 11520
A29: t12_ncf | B29: =O4+O5+O6+O7+O8-(O9+O10+O11+O12+O13+O14+O15)-O16 -> 590880

Sheet Assumptions
A1: Underwriting Assumptions — inputs are yellow-fill / blue-text
A3: Property basics
A4: Total rentable SF (from Rent Roll) | B4: ='Rent Roll'!C14 -> 28800 | C4: Green = link. Source: Rent Roll tab row-total
A5: As-of date | B5: 2026-08-31
A6: Underwriting revenue (from Property-and-Plan.pdf, page 2)
A7: UW GPR (annual, supplied scenario) | B7: 741000 | C7: Plan: $780,000 annual; not inferred from T12
A8: Combined revenue loss % (vac+conc+bad) | B8: 0.05 | C8: Plan: 5.00% of UW GPR
A9: Other income / recoveries (annual) | B9: 171000 | C9: Plan: $180,000; add after revenue loss
A10: UW EGI (calc) | B10: =B7-B7*B8+B9 -> 874950 | C10: GPR − loss + other
A11: Underwriting operating expenses (annual)
A12: Real estate taxes | B12: 120000 | C12: Plan: $120,000
A13: Property insurance | B13: 34800 | C13: Plan: fictional insurer renewal 2026-08-25, $34,800
A14: Utilities (T12 actual) | B14: ='T12'!O11 -> 21600
A15: Repairs & maintenance (T12 actual; no removal) | B15: ='T12'!O12 -> 36000
A16: Payroll / contract labor (T12) | B16: ='T12'!O13 -> 24000
A17: Administrative / legal (T12) | B17: ='T12'!O14 -> 18000
A18: T12 management fee (for max()) | B18: ='T12'!O15 -> 18000
A19: UW management fee = MAX(T12, 4% × EGI) | B19: =MAX(B18,0.04*B10) -> 34998 | C19: Lender rule: greater of T12 or 4.00% of UW EGI
A20: UW NOI before reserves (calc) | B20: =B10-(B12+B13+B14+B15+B16+B17+B19) -> 585552
A21: UW replacement reserves ($0.15/SF/yr) | B21: =0.15*B4 -> 4320 | C21: Plan: deduct after NOI
A22: UW NCF after reserves (calc) | B22: =B20-B21 -> 581232
A23: Lender terms (Lender-Terms.pdf)
A24: Contract rate (annual) | B24: 0.0635 | C24: Term sheet: 6.35% fixed
A25: Sizing rate = MAX(contract, 6.35% floor) | B25: =MAX(B24,0.0635) -> 0.0635
A26: Cap rate (valuation) | B26: 0.0625 | C26: Term sheet: 6.25%
A27: Amortization (years) | B27: 25 | C27: Term sheet: 25 years, monthly
A28: IO months | B28: 0 | C28: Term sheet: 0
A29: LTV cap | B29: 0.625 | C29: Term sheet: 62.50%
A30: DSCR minimum | B30: 1.25 | C30: NCF after reserves / annual amortizing DS at sizing rate
A31: Debt yield minimum | B31: 0.09 | C31: Numerator: NOI before reserves
A32: Origination fee % | B32: 0.008 | C32: 0.80% of actual initial principal
A33: Transaction context (Property-and-Plan.pdf, page 1)
A34: Existing debt payoff | B34: 4200000
A35: Fixed closing costs | B35: 52000
A36: Sensitivity levers (used on Sensitivity tab)
A37: Downside — EGI haircut | B37: -0.05 | C37: Plan: reduce total UW EGI by 5%
A38: Downside — sizing rate delta (bps) | B38: 100 | C38: Plan: +100 bps in combined downside
A39: Cap rate sensitivity — delta (bps) | B39: 50 | C39: Plan: separate +50bps cap-rate sensitivity

Sheet Loan Sizing
A1: Loan sizing at MAX(contract, floor) sizing rate
A3: Cash flows and valuation
A4: UW NOI before reserves | B4: =Assumptions!B20 -> 585552
A5: UW NCF after reserves | B5: =Assumptions!B22 -> 581232
A6: Cap rate | B6: =Assumptions!B26 -> 0.0625
A7: Indicative value (NOI-before-reserves / cap) | B7: =B4/B6 -> 9368832
A8: Debt constant
A9: Annual debt constant at sizing rate (25-yr amort, monthly) | B9: =(-PMT(Assumptions!B25/12,Assumptions!B27*12,1))*12 -> 0.079903715 | C9: PMT-based; per $1 of principal, ×12 = annual constant
A10: Three constraints
A11: LTV = Value × LTV cap | B11: =B7*Assumptions!B29 -> 5855520
A12: LTV maximum principal | B12: =B11 -> 5855520
A13: DSCR maximum principal = NCF / DSCR / debt constant | B13: =B5/Assumptions!B30/B9 -> 5819323.9
A14: Debt yield max principal = NOI / DY min | B14: =B4/Assumptions!B31 -> 6506133.3
A15: Binding result
A16: MAXIMUM LOAN (min of three) | B16: =MIN(B12,B13,B14) -> 5819323.9
A17: Binding constraint | B17: =IF(B16=B12,"LTV",IF(B16=B13,"DSCR","Debt yield")) -> DSCR
A18: Debt service and coverage at max loan
A19: Sizing annual debt service (at sizing rate) | B19: =B16*B9 -> 464985.6
A20: First-year debt service (contract rate, IO respected) | B20: =IF(Assumptions!B28>0,B16*Assumptions!B24,B16*((-PMT(Assumptions!B24/12,Assumptions!B27*12,1))*12)) -> 464985.6 | C20: IO months > 0 → interest-only; otherwise contract-rate amortizing
A21: Sizing DSCR (NCF / sizing DS) | B21: =B5/B19 -> 1.25
A22: Sizing debt yield (NOI / max loan) | B22: =B4/B16 -> 0.100622

Sheet Sources & Uses
A1: Sources & Uses — closing
A3: Sources
A4: First-mortgage proceeds | B4: ='Loan Sizing'!B16 -> 5819323.9
A5: Borrower cash (if cash-in) | B5: =IF(B14<0,-B14,0) -> 0 | C5: Zero if cash-out
A6: Total sources | B6: =B4+B5 -> 5819323.9
A7: Uses
A8: Existing debt payoff | B8: =Assumptions!B34 -> 4200000
A9: Origination fee (0.80% of loan) | B9: =Assumptions!B32*B4 -> 46554.591
A10: Fixed closing costs | B10: =Assumptions!B35 -> 52000
A11: Cash to borrower (if cash-out) | B11: =IF(B14>0,B14,0) -> 1520769.3
A12: Total uses | B12: =B8+B9+B10+B11 -> 5819323.9
A13: Net cash to (from) borrower
A14: Cash to borrower = Loan − Payoff − Origination − Fixed closing | B14: =B4-B8-B9-B10 -> 1520769.3 | C14: Positive = cash out; negative = cash in required

Sheet Sensitivity
A1: Sensitivity — Combined downside and Cap-rate stress
A3: Scenario | B3: Combined downside: EGI × (1+haircut), sizing rate + delta | C3: Cap rate + delta (bps) | D3: Notes
A4: Stressed EGI | B4: =(Assumptions!B7-Assumptions!B7*Assumptions!B8+Assumptions!B9)*(1+Assumptions!B37) -> 831202.5 | C4: =Assumptions!B10 -> 874950 | D4: Downside: apply EGI haircut on Assumptions!B37; cap-rate scenario keeps EGI unchanged
A5: Recalculated management fee | B5: =MAX(Assumptions!B18,0.04*B4) -> 33248.1 | C5: =MAX(Assumptions!B18,0.04*C4) -> 34998
A6: Total operating expenses (other + recalculated mgmt) | B6: =(Assumptions!B12+Assumptions!B13+Assumptions!B14+Assumptions!B15+Assumptions!B16+Assumptions!B17)+B5 -> 287648.1 | C6: =(Assumptions!B12+Assumptions!B13+Assumptions!B14+Assumptions!B15+Assumptions!B16+Assumptions!B17)+C5 -> 289398
A7: NOI (before reserves) | B7: =B4-B6 -> 543554.4 | C7: =C4-C6 -> 585552
A8: Replacement reserves | B8: =Assumptions!B21 -> 4320 | C8: =Assumptions!B21 -> 4320
A9: NCF (after reserves) | B9: =B7-B8 -> 539234.4 | C9: =C7-C8 -> 581232
A10: Sizing rate | B10: =Assumptions!B25+Assumptions!B38/10000 -> 0.0735 | C10: =Assumptions!B25 -> 0.0635
A11: Annual debt constant | B11: =(-PMT(B10/12,Assumptions!B27*12,1))*12 -> 0.087511438 | C11: =(-PMT(C10/12,Assumptions!B27*12,1))*12 -> 0.079903715
A12: Indicative value (NOI / cap) | B12: =B7/Assumptions!B26 -> 8696870.4 | C12: =C7/(Assumptions!B26+Assumptions!B39/10000) -> 8674844.4
A13: LTV constraint | B13: =B12*Assumptions!B29 -> 5435544 | C13: =C12*Assumptions!B29 -> 5421777.8
A14: MAXIMUM LOAN (stress) | B14: =MIN(B13,B9/Assumptions!B30/B11,B7/Assumptions!B31) -> 4929498.7 | C14: =MIN(C13,C9/Assumptions!B30/C11,C7/Assumptions!B31) -> 5421777.8 | D14: Combined downside binds where DSCR is tightest given lower NCF and higher rate; cap-rate scenario compresses LTV
A15: Binding constraint (stress) | B15: =IF(B14=B13,"LTV",IF(B14=B9/Assumptions!B30/B11,"DSCR","Debt yield")) -> DSCR | C15: =IF(C14=C13,"LTV",IF(C14=C9/Assumptions!B30/C11,"DSCR","Debt yield")) -> LTV
A16: Delta vs base max loan | B16: =B14-'Loan Sizing'!B16 -> -889825.18 | C16: =C14-'Loan Sizing'!B16 -> -397546.12

Sheet Analysis Fields
A1: Requested analysis fields — with sources
A3: Field ID | B3: Value | C3: Source / calculation | D3: Notes
A4: space_count | B4: ='Rent Roll'!B17 -> 10 | C4: Rent Roll tab; source: Rent-Roll.xlsx
A5: occupied_count | B5: ='Rent Roll'!B18 -> 9 | C5: Rent Roll tab
A6: total_area_sf | B6: ='Rent Roll'!B19 -> 28800 | C6: Rent Roll tab
A7: occupied_area_sf | B7: ='Rent Roll'!B20 -> 27200 | C7: Rent Roll tab
A8: occupancy_count_pct | B8: ='Rent Roll'!B21 -> 90 | C8: 9 of 10 units occupied | D8: Percent 0-100
A9: occupancy_area_pct | B9: ='Rent Roll'!B22 -> 94.444444 | C9: 27,200 of 28,800 SF occupied | D9: Percent 0-100
A10: rent_roll_monthly_base | B10: ='Rent Roll'!B23 -> 60000 | C10: Sum of column E on Rent Roll | D10: USD monthly
A11: effective_monthly_base | B11: ='Rent Roll'!B25 -> 60000 | C11: Rent Roll total; Lease-File.pdf confirms Unit 101 $3,000/mo | D11: No exercised amendment changing contractual rent supplied
A12: t12_egi | B12: ='T12'!B25 -> 866400 | C12: T12 source annuals: GPR+other+(vac+conc+bad)
A13: t12_operating_expenses | B13: ='T12'!B26 -> 264000 | C13: T12; excludes reserves, capex, debt, depreciation
A14: t12_noi_before_reserves | B14: ='T12'!B27 -> 602400 | C14: T12 EGI − OpEx
A15: t12_reserves | B15: ='T12'!B28 -> 11520 | C15: T12 replacement reserves (below NOI)
A16: t12_ncf | B16: ='T12'!B29 -> 590880 | C16: T12 NOI − reserves | D16: Debt principal/interest and capex NOT included per lender rule
A17: uw_egi | B17: =Assumptions!B10 -> 874950 | C17: Assumptions: GPR − 5% loss + Other
A18: uw_management_fee | B18: =Assumptions!B19 -> 34998 | C18: MAX(T12 mgmt, 4% × UW EGI) | D18: 4% × EGI binds ($36,840 > $18,000)
A19: uw_operating_expenses | B19: =Assumptions!B12+Assumptions!B13+Assumptions!B14+Assumptions!B15+Assumptions!B16+Assumptions!B17+Assumptions!B19 -> 289398 | C19: Sum of UW OpEx line items (incl. lender-normalized mgmt) | D19: Excludes reserves
A20: uw_noi_before_reserves | B20: =Assumptions!B20 -> 585552 | C20: UW EGI − UW OpEx
A21: uw_reserves | B21: =Assumptions!B21 -> 4320 | C21: $0.15 × total SF
A22: uw_ncf | B22: =Assumptions!B22 -> 581232 | C22: UW NOI − reserves
A23: capitalization_value | B23: ='Loan Sizing'!B7 -> 9368832 | C23: UW NOI-before-reserves / 6.25% | D23: Indicative; not an appraisal
A24: contract_rate | B24: =Assumptions!B24 -> 0.0635 | C24: Lender-Terms.pdf: 6.35% contract | D24: Decimal
A25: sizing_rate | B25: =Assumptions!B25 -> 0.0635 | C25: MAX(contract, 6.35% floor) | D25: Decimal
A26: annual_debt_constant | B26: ='Loan Sizing'!B9 -> 0.079903715 | C26: PMT(sizing/12, 25×12, 1) × 12 | D26: Per $1 of principal
A27: ltv_limit | B27: ='Loan Sizing'!B12 -> 5855520 | C27: Value × 62.5%
A28: dscr_limit | B28: ='Loan Sizing'!B13 -> 5819323.9 | C28: NCF / 1.25 / debt constant
A29: debt_yield_limit | B29: ='Loan Sizing'!B14 -> 6506133.3 | C29: NOI / 9.00%
A30: maximum_loan | B30: ='Loan Sizing'!B16 -> 5819323.9 | C30: MIN of the three constraints
A31: binding_constraint | B31: ='Loan Sizing'!B17 -> DSCR | C31: Auto-labeled
A32: sizing_annual_debt_service | B32: ='Loan Sizing'!B19 -> 464985.6 | C32: Max loan × annual debt constant
A33: sizing_dscr | B33: ='Loan Sizing'!B21 -> 1.25 | C33: NCF / sizing DS | D33: ≈ 1.25x by construction (DSCR-bound)
A34: sizing_debt_yield | B34: ='Loan Sizing'!B22 -> 0.100622 | C34: NOI / max loan
A35: first_year_debt_service | B35: ='Loan Sizing'!B20 -> 464985.6 | C35: IO=0 → contract-rate amortizing DS | D35: Equals sizing DS because contract = sizing rate
A36: cash_to_borrower | B36: ='Sources & Uses'!B14 -> 1520769.3 | C36: Loan − payoff − origination − fixed closing | D36: Positive = cash out
A37: stress_uw_noi | B37: =Sensitivity!B7 -> 543554.4 | C37: EGI −5%; mgmt recalc; other opex unchanged
A38: stress_maximum_loan | B38: =Sensitivity!B14 -> 4929498.7 | C38: Combined downside: EGI −5% AND sizing +100 bps; cap unchanged
A39: subject_lease_monthly_rent | B39: =3000 -> 3000 | C39: Lease-File.pdf §3: base rent $3,000/mo as of 2026-08-31
A40: subject_lease_expiry | B40: "2029-08-31" | C40: Lease-File.pdf §2: initial term expires 2029-08-31 | D40: Renewal option not evidenced as exercised
A41: subject_lease_deposit | B41: =6000 -> 6000 | C41: Lease-File.pdf §4 | D41: Not prepaid rent or recurring income
...

Sheet Reconciliation
A1: Reconciliation and evidence flags
A3: Item | B3: Source A | C3: Source B / Rule | D3: Resolution
A4: Unit 101 rent | B4: Rent Roll: $3,000/mo | C4: Lease-File.pdf §3: $3,000/mo, no increase before 2027-09-01 | D4: Consistent — no amendment overrides
A5: Unit 101 expiry | B5: Rent Roll: 2029-08-31 | C5: Lease §2 initial term expires 2029-08-31; §5 renewal option not exercised | D5: Use 2029-08-31; option existence does not extend expiry
A6: Insurance premium (UW) | B6: Property-Plan: $34,800 renewal quote (2026-08-25) | C6: T12 actual insurance $32,400 | D6: Per plan: use $34,800 for UW
A7: Real estate taxes (UW) | B7: Property-Plan: $120,000 | C7: T12 actual $114,000 | D7: Per plan: use $120,000 for UW
A8: Management fee (UW) | B8: T12 $18,000 | C8: Lender rule: MAX(T12, 4% × UW EGI) = MAX($18,000, $36,840) = $36,840 | D8: 4% × EGI binds
A9: Replacement reserves (UW) | B9: Plan: $0.15/SF/yr | C9: T12 actual $11,520 (~$0.40/SF) | D9: Per plan: $0.15 × 28,800 = $4,320
A10: R&M one-time removal | B10: T12 $36,000 | C10: Plan: 'remove $0 of one-time casualty cleanup' | D10: No removal; use T12 as-is
A11: Utilities / Payroll / Admin | B11: T12 actuals | C11: Plan: use T12 actual | D11: Use T12 values
A12: Historical 'property NOI' label | B12: T12 accounting shows cash flow after reserves | C12: Plan: preserve reported line; separately identify NOI before reserves and NCF after reserves | D12: We show both explicitly on T12 and Assumptions tabs
A13: Debt / capex / depreciation | B13: T12 lists below cash flow | C13: Plan: not operating expenses | D13: Excluded from OpEx totals
A14: Cap rate 6.25% vs 6.75% | B14: Term sheet cap 6.25% | C14: Downside instruction: separate +50 bps cap sensitivity | D14: Base uses 6.25%; sensitivity tab computes +50 bps case
... A16: Appraisal / comps / sponsor track | B16: Not supplied | C16: Plan explicitly states none supplied | D16: Left unknown; not inferred
