Workbook

Sheet Summary
A1: MAGNOLIA TERRACE — UNDERWRITING SUMMARY
A2: Raleigh, NC | Multifamily | 48 units | As-of date 2026-08-31
A3: Original fictional CRE Bench evaluation material — no real transaction represented
A5: INPUT CELLS (yellow) — edit to flex model
A6: Gross potential rent (annual, before economic loss) | B6: 974400 | C6: gross_potential_rent
A7: Capitalization rate | B7: 0.0625 | C7: cap_rate
A8: Sizing rate (greater of note 6.25% or floor 6.00%) | B8: 0.0625 | C8: sizing_rate
A9: Note rate | B9: 0.0625
A10: Rate floor | B10: 0.06
A11: Amortization (years) | B11: 30
A12: Economic loss % | B12: 0.05
A13: Other income $/unit/yr | B13: 350
A14: Total units | B14: 48
A15: Tax expense (annual) | B15: 102312
A16: Insurance expense (annual) | B16: 34104
A17: Other recurring operating expenses | B17: 136416
A18: Management fee % of EGI | B18: 0.03
A19: Replacement reserve $/unit/yr | B19: 300
A20: Max LTV | B20: 0.65
... A25: Existing loan payoff | B25: 4200000
A27: OUTPUT CELLS (green) — derived from inputs
A28: Effective gross income (EGI) | B28: =B6*(1-B12)+B13*B14 -> 942480 | C28: uw_egi
A29: Total operating expenses | B29: =B15+B16+B17+B18*B28 -> 301106.4
A30: Net operating income (NOI) | B30: =B28-B29 -> 641373.6 | C30: uw_noi
A31: Replacement reserves | B31: =B19*B14 -> 14400
A32: Net cash flow (NCF, after reserves) | B32: =B30-B31 -> 626973.6 | C32: uw_ncf
A33: Capitalization value (NOI / cap_rate) | B33: =B30/B7 -> 10261978 | C33: capitalization_value
A35: DEBT SIZING
A36: Monthly sizing rate | B36: =B8/12 -> 0.0052083333
A37: Number of payments | B37: =B11*12 -> 360
A38: Mortgage constant (annual) | B38: =12*B36*(1+B36)^B37/((1+B36)^B37-1) -> 0.073886064
A39: LTV-constrained loan | B39: =B20*B33 -> 6670285.4
A40: DSCR-constrained loan (NCF / (DSCR × constant)) | B40: =B32/(B21*B38) -> 6788545.1
A41: Debt-yield-constrained loan (NCF / min DY) | B41: =B32/B22 -> 6966373.3
A42: Maximum loan (min of three constraints) | B42: =MIN(B39,B40,B41) -> 6670285.4 | C42: maximum_loan
A43: Binding constraint | B43: =IF(B42=B39,"LTV",IF(B42=B40,"DSCR","Debt yield")) -> LTV
A45: SOURCES & USES / NET CASH-OUT
A46: Sources: loan proceeds | B46: =B42 -> 6670285.4
A47: Uses: existing loan payoff | B47: =B25 -> 4200000
A48: Uses: origination fee | B48: =B23*B42 -> 66702.854
...

Sheet RentRoll_Certified
A1: MAGNOLIA TERRACE — CERTIFIED RENT ROLL
A2: Source: rent-roll-certified.xlsx | As of 2026-08-31 | Controls over 2026-06-30 archive
A4: Suite | B4: Unit type | C4: Area SF | D4: Possession | E4: Monthly rent | F4: Lease exp | G4: Note
A5: 001 | B5: Studio | C5: 700 | D5: active | E5: 1500 | F5: 2029-08-31
A6: 002 | B6: 1BR | C6: 820 | D6: active | E6: 1650 | F6: 2029-08-31
A7: 003 | B7: 2BR | C7: 1030 | D7: active | E7: 1925 | F7: 2029-08-31
A8: 004 | B8: Studio | C8: 700 | D8: active | E8: 1500 | F8: 2029-08-31
A9: 005 | B9: 1BR | C9: 820 | D9: active | E9: 1650 | F9: 2029-08-31
A10: 006 | B10: 2BR | C10: 1030 | D10: active | E10: 1925 | F10: 2029-08-31
A11: 007 | B11: Studio | C11: 700 | D11: active | E11: 1500 | F11: 2029-08-31
A12: 008 | B12: 1BR | C12: 820 | D12: active | E12: 1650 | F12: 2029-08-31
A13: 009 | B13: 2BR | C13: 1030 | D13: active | E13: 1925 | F13: 2029-08-31
A14: 010 | B14: Studio | C14: 700 | D14: active | E14: 1500 | F14: 2029-08-31
A15: 011 | B15: 1BR | C15: 820 | D15: active | E15: 1650 | F15: 2029-08-31
A16: 012 | B16: 2BR | C16: 1030 | D16: active | E16: 1925 | F16: 2029-08-31
... A48: 044 | B48: 1BR | C48: 820 | D48: active | E48: 1650 | F48: 2029-08-31
A49: 045 | B49: 2BR | C49: 1030 | D49: pending | E49: 1925 | F49: 2029-08-31 | G49: Pending means not yet in possession
A50: 046 | B50: Studio | C50: 700 | D50: vacant | E50: 1500 | F50: 2029-08-31
A51: 047 | B51: 1BR | C51: 820 | D51: vacant | E51: 1650 | F51: 2029-08-31
A52: 048 | B52: 2BR | C52: 1030 | D52: vacant | E52: 1925 | F52: 2029-08-31
A53: TOTALS | C53: =SUM(C5:C52) -> 40800 | E53: =SUM(E5:E52) -> 81200
A56: OCCUPANCY SUMMARY (physical, possession-based)
A57: Total units | B57: =COUNTA(A5:A52) -> 48
A58: Active (occupied) units | B58: =COUNTIF(D5:D52,"active") -> 44
A59: Pending units (not in possession) | B59: =COUNTIF(D5:D52,"pending") -> 1
A60: Vacant units | B60: =COUNTIF(D5:D52,"vacant") -> 3
A61: Unit occupancy (active / total) | B61: =B58/B57 -> 0.91666667
A62: Total area SF | B62: =SUM(C5:C52) -> 40800
A63: Occupied area SF | B63: =SUMIF(D5:D52,"active",C5:C52) -> 37220
A64: Area occupancy (occupied SF / total SF) | B64: =B63/B62 -> 0.9122549
A65: In-place monthly rent (all suites, certified) | B65: =SUM(E5:E52) -> 81200
A66: Annual in-place rent (× 12) | B66: =B65*12 -> 974400
A69: UNIT TYPE MIX (A=Studio, B=1BR, C=2BR per manager mapping)
A70: Group / Type | B70: Units | C70: Occupied | D70: Area SF/unit
A71: A — Studio | B71: =COUNTIF(B5:B52,"Studio") -> 16 | C71: =COUNTIFS(B5:B52,"Studio",D5:D52,"active") -> 15 | D71: 700
A72: B — 1BR | B72: =COUNTIF(B5:B52,"1BR") -> 16 | C72: =COUNTIFS(B5:B52,"1BR",D5:D52,"active") -> 15 | D72: 820
A73: C — 2BR | B73: =COUNTIF(B5:B52,"2BR") -> 16 | C73: =COUNTIFS(B5:B52,"2BR",D5:D52,"active") -> 14 | D73: 1030

Sheet UW_P&L
A1: UNDERWRITING P&L — HISTORICAL vs UNDERWRITTEN
A3: Line item | B3: Historical T12 | C3: Underwritten | D3: Basis / note
A4: Rental & ancillary collections (T12) | B4: 876960 | D4: operating-statement.pdf — 2025-09 through 2026-08
A5: Gross potential rent (all suites × 12, pre-amendment) | C5: =Summary!B6 -> 974400 | D5: underwriting-instructions.pdf: certified roll × 12, before Suite 001 amendment
A6: Less: economic loss (5%) | C6: =-Summary!B6*Summary!B12 -> -48720 | D6: underwriting-instructions.pdf
A7: Plus: other income ($350/unit × 48) | C7: =Summary!B13*Summary!B14 -> 16800 | D7: underwriting-instructions.pdf; reimbursement already inside T12/roll — do not double-count
A8: Effective gross income (EGI) | C8: =Summary!B28 -> 942480
A10: Real estate taxes | B10: -102312 | C10: =-Summary!B15 -> -102312 | D10: operating-statement.pdf; underwriting-instructions.pdf
A11: Insurance | B11: -34104 | C11: =-Summary!B16 -> -34104 | D11: operating-statement.pdf (expense, distinct from policy limit $2M in insurance.pdf)
A12: Other recurring operating expenses | B12: -136416 | C12: =-Summary!B17 -> -136416 | D12: operating-statement.pdf; underwriting-instructions.pdf
A13: Management fee (3% of EGI) | C13: =-Summary!B18*Summary!B28 -> -28274.4 | D13: underwriting-instructions.pdf
A14: Roof replacement (capital; NOT in opex) | B14: 0 | D14: operating-statement.pdf: roof is capital, no recurring repair booked
A15: Reported NOI (as stated) | B15: 604128 | C15: =Summary!B30 -> 641373.6 | D15: Historical: reported. Underwritten: derived (NOI before reserves)
A17: Replacement reserves ($300/unit) | C17: =-Summary!B31 -> -14400 | D17: underwriting-instructions.pdf
A18: Net cash flow (NCF, after reserves) | C18: =Summary!B32 -> 626973.6
A20: Reconciliation notes
A21: • Historical T12 collections ($876,960) are actual cash — NOT an annualized rent-roll total (per operating-statement.pdf).
A22: • UW GPR uses certified all-suite scheduled rent × 12 = $974,400 (per underwriting-instructions.pdf), BEFORE Suite 001 amendment.
A23: • Historical NOI ($604,128) is calculated before reserves; UW NCF is after $14,400 reserves. Definitions differ — labeled explicitly.
A24: • Roof replacement is capital; operating statement confirms it was NOT booked to opex.

Sheet Debt_Sizing
A1: DEBT SIZING & SOURCES / USES
A3: Sizing rate (greater of note or floor) | B3: =Summary!B8 -> 0.0625
A4: Note rate | B4: =Summary!B9 -> 0.0625
A5: Floor | B5: =Summary!B10 -> 0.06
A6: Sizing rate binding vs floor? | B6: =IF(Summary!B9>=Summary!B10,"Note binds (floor not binding)","Floor binds") -> Note binds (floor not binding)
A7: Amortization (yrs) | B7: =Summary!B11 -> 30
A8: Annual mortgage constant | B8: =Summary!B38 -> 0.073886064
A10: Cap value (NOI / cap) | B10: =Summary!B33 -> 10261978
A11: NCF | B11: =Summary!B32 -> 626973.6
A13: LTV cap loan (65% × value) | B13: =Summary!B39 -> 6670285.4
A14: DSCR cap loan (NCF / 1.25 / constant) | B14: =Summary!B40 -> 6788545.1
A15: DY cap loan (NCF / 9%) | B15: =Summary!B41 -> 6966373.3
A16: MAXIMUM LOAN | B16: =Summary!B42 -> 6670285.4
A17: Binding constraint | B17: =Summary!B43 -> LTV
A19: SOURCES & USES
A20: Sources: new loan | B20: =Summary!B46 -> 6670285.4
A21: Uses: existing payoff | B21: =Summary!B47 -> 4200000
A22: Uses: origination (1%) | B22: =Summary!B48 -> 66702.854
A23: Uses: closing costs | B23: =Summary!B49 -> 45000
A24: Total uses | B24: =Summary!B50 -> 4311702.9
A25: Net cash-out (Sources − Uses) | B25: =Summary!B51 -> 2358582.6 | C25: Negative = additional equity required

Sheet Sensitivity
A1: SENSITIVITY — Maximum loan and net cash-out
A2: Rows: cap rate | Columns: sizing rate. Live formulas — will recompute if you change assumptions.
A4: TABLE 1: Maximum Loan ($)
A5: Cap ↓ / Sizing rate → | B5: 0.055 | C5: 0.06 | D5: 0.0625 | E5: 0.065 | F5: 0.07 | G5: 0.075
A6: 0.05 | B6: =MIN(Summary!$B$20*Summary!$B$30/$A6,Summary!$B$32/(Summary!$B$21*12*(B$5/12)*(1+B$5/12)^(Summary!$B$11*12)/((1+B$5/12)^(Summary!$B$11*12)-1)),Summary!$B$32/Summary!$B$22) -> 6966373.3 | C6: =MIN(Summary!$B$20*Summary!$B$30/$A6,Summary!$B$32/(Summary!$B$21*12*(C$5/12)*(1+C$5/12)^(Summary!$B$11*12)/((1+C$5/12)^(Summary!$B$11*12)-1)),Summary!$B$32/Summary!$B$22) -> 6966373.3 | D6: =MIN(Summary!$B$20*Summary!$B$30/$A6,Summary!$B$32/(Summary!$B$21*12*(D$5/12)*(1+D$5/12)^(Summary!$B$11*12)/((1+D$5/12)^(Summary!$B$11*12)-1)),Summary!$B$32/Summary!$B$22) -> 6788545.1 | E6: =MIN(Summary!$B$20*Summary!$B$30/$A6,Summary!$B$32/(Summary!$B$21*12*(E$5/12)*(1+E$5/12)^(Summary!$B$11*12)/((1+E$5/12)^(Summary!$B$11*12)-1)),Summary!$B$32/Summary!$B$22) -> 6612933.8 | F6: =MIN(Summary!$B$20*Summary!$B$30/$A6,Summary!$B$32/(Summary!$B$21*12*(F$5/12)*(1+F$5/12)^(Summary!$B$11*12)/((1+F$5/12)^(Summary!$B$11*12)-1)),Summary!$B$32/Summary!$B$22) -> 6282591.8 | G6: =MIN(Summary!$B$20*Summary!$B$30/$A6,Summary!$B$32/(Summary!$B$21*12*(G$5/12)*(1+G$5/12)^(Summary!$B$11*12)/((1+G$5/12)^(Summary!$B$11*12)-1)),Summary!$B$32/Summary!$B$22) -> 5977885.1
A7: 0.055 | B7: =MIN(Summary!$B$20*Summary!$B$30/$A7,Summary!$B$32/(Summary!$B$21*12*(B$5/12)*(1+B$5/12)^(Summary!$B$11*12)/((1+B$5/12)^(Summary!$B$11*12)-1)),Summary!$B$32/Summary!$B$22) -> 6966373.3 | C7: =MIN(Summary!$B$20*Summary!$B$30/$A7,Summary!$B$32/(Summary!$B$21*12*(C$5/12)*(1+C$5/12)^(Summary!$B$11*12)/((1+C$5/12)^(Summary!$B$11*12)-1)),Summary!$B$32/Summary!$B$22) -> 6966373.3 | D7: =MIN(Summary!$B$20*Summary!$B$30/$A7,Summary!$B$32/(Summary!$B$21*12*(D$5/12)*(1+D$5/12)^(Summary!$B$11*12)/((1+D$5/12)^(Summary!$B$11*12)-1)),Summary!$B$32/Summary!$B$22) -> 6788545.1 | E7: =MIN(Summary!$B$20*Summary!$B$30/$A7,Summary!$B$32/(Summary!$B$21*12*(E$5/12)*(1+E$5/12)^(Summary!$B$11*12)/((1+E$5/12)^(Summary!$B$11*12)-1)),Summary!$B$32/Summary!$B$22) -> 6612933.8 | F7: =MIN(Summary!$B$20*Summary!$B$30/$A7,Summary!$B$32/(Summary!$B$21*12*(F$5/12)*(1+F$5/12)^(Summary!$B$11*12)/((1+F$5/12)^(Summary!$B$11*12)-1)),Summary!$B$32/Summary!$B$22) -> 6282591.8 | G7: =MIN(Summary!$B$20*Summary!$B$30/$A7,Summary!$B$32/(Summary!$B$21*12*(G$5/12)*(1+G$5/12)^(Summary!$B$11*12)/((1+G$5/12)^(Summary!$B$11*12)-1)),Summary!$B$32/Summary!$B$22) -> 5977885.1
A8: 0.0575 | B8: =MIN(Summary!$B$20*Summary!$B$30/$A8,Summary!$B$32/(Summary!$B$21*12*(B$5/12)*(1+B$5/12)^(Summary!$B$11*12)/((1+B$5/12)^(Summary!$B$11*12)-1)),Summary!$B$32/Summary!$B$22) -> 6966373.3 | C8: =MIN(Summary!$B$20*Summary!$B$30/$A8,Summary!$B$32/(Summary!$B$21*12*(C$5/12)*(1+C$5/12)^(Summary!$B$11*12)/((1+C$5/12)^(Summary!$B$11*12)-1)),Summary!$B$32/Summary!$B$22) -> 6966373.3 | D8: =MIN(Summary!$B$20*Summary!$B$30/$A8,Summary!$B$32/(Summary!$B$21*12*(D$5/12)*(1+D$5/12)^(Summary!$B$11*12)/((1+D$5/12)^(Summary!$B$11*12)-1)),Summary!$B$32/Summary!$B$22) -> 6788545.1 | E8: =MIN(Summary!$B$20*Summary!$B$30/$A8,Summary!$B$32/(Summary!$B$21*12*(E$5/12)*(1+E$5/12)^(Summary!$B$11*12)/((1+E$5/12)^(Summary!$B$11*12)-1)),Summary!$B$32/Summary!$B$22) -> 6612933.8 | F8: =MIN(Summary!$B$20*Summary!$B$30/$A8,Summary!$B$32/(Summary!$B$21*12*(F$5/12)*(1+F$5/12)^(Summary!$B$11*12)/((1+F$5/12)^(Summary!$B$11*12)-1)),Summary!$B$32/Summary!$B$22) -> 6282591.8 | G8: =MIN(Summary!$B$20*Summary!$B$30/$A8,Summary!$B$32/(Summary!$B$21*12*(G$5/12)*(1+G$5/12)^(Summary!$B$11*12)/((1+G$5/12)^(Summary!$B$11*12)-1)),Summary!$B$32/Summary!$B$22) -> 5977885.1
A9: 0.06 | B9: =MIN(Summary!$B$20*Summary!$B$30/$A9,Summary!$B$32/(Summary!$B$21*12*(B$5/12)*(1+B$5/12)^(Summary!$B$11*12)/((1+B$5/12)^(Summary!$B$11*12)-1)),Summary!$B$32/Summary!$B$22) -> 6948214 | C9: =MIN(Summary!$B$20*Summary!$B$30/$A9,Summary!$B$32/(Summary!$B$21*12*(C$5/12)*(1+C$5/12)^(Summary!$B$11*12)/((1+C$5/12)^(Summary!$B$11*12)-1)),Summary!$B$32/Summary!$B$22) -> 6948214 | D9: =MIN(Summary!$B$20*Summary!$B$30/$A9,Summary!$B$32/(Summary!$B$21*12*(D$5/12)*(1+D$5/12)^(Summary!$B$11*12)/((1+D$5/12)^(Summary!$B$11*12)-1)),Summary!$B$32/Summary!$B$22) -> 6788545.1 | E9: =MIN(Summary!$B$20*Summary!$B$30/$A9,Summary!$B$32/(Summary!$B$21*12*(E$5/12)*(1+E$5/12)^(Summary!$B$11*12)/((1+E$5/12)^(Summary!$B$11*12)-1)),Summary!$B$32/Summary!$B$22) -> 6612933.8 | F9: =MIN(Summary!$B$20*Summary!$B$30/$A9,Summary!$B$32/(Summary!$B$21*12*(F$5/12)*(1+F$5/12)^(Summary!$B$11*12)/((1+F$5/12)^(Summary!$B$11*12)-1)),Summary!$B$32/Summary!$B$22) -> 6282591.8 | G9: =MIN(Summary!$B$20*Summary!$B$30/$A9,Summary!$B$32/(Summary!$B$21*12*(G$5/12)*(1+G$5/12)^(Summary!$B$11*12)/((1+G$5/12)^(Summary!$B$11*12)-1)),Summary!$B$32/Summary!$B$22) -> 5977885.1
A10: 0.065 | B10: =MIN(Summary!$B$20*Summary!$B$30/$A10,Summary!$B$32/(Summary!$B$21*12*(B$5/12)*(1+B$5/12)^(Summary!$B$11*12)/((1+B$5/12)^(Summary!$B$11*12)-1)),Summary!$B$32/Summary!$B$22) -> 6413736 | C10: =MIN(Summary!$B$20*Summary!$B$30/$A10,Summary!$B$32/(Summary!$B$21*12*(C$5/12)*(1+C$5/12)^(Summary!$B$11*12)/((1+C$5/12)^(Summary!$B$11*12)-1)),Summary!$B$32/Summary!$B$22) -> 6413736 | D10: =MIN(Summary!$B$20*Summary!$B$30/$A10,Summary!$B$32/(Summary!$B$21*12*(D$5/12)*(1+D$5/12)^(Summary!$B$11*12)/((1+D$5/12)^(Summary!$B$11*12)-1)),Summary!$B$32/Summary!$B$22) -> 6413736 | E10: =MIN(Summary!$B$20*Summary!$B$30/$A10,Summary!$B$32/(Summary!$B$21*12*(E$5/12)*(1+E$5/12)^(Summary!$B$11*12)/((1+E$5/12)^(Summary!$B$11*12)-1)),Summary!$B$32/Summary!$B$22) -> 6413736 | F10: =MIN(Summary!$B$20*Summary!$B$30/$A10,Summary!$B$32/(Summary!$B$21*12*(F$5/12)*(1+F$5/12)^(Summary!$B$11*12)/((1+F$5/12)^(Summary!$B$11*12)-1)),Summary!$B$32/Summary!$B$22) -> 6282591.8 | G10: =MIN(Summary!$B$20*Summary!$B$30/$A10,Summary!$B$32/(Summary!$B$21*12*(G$5/12)*(1+G$5/12)^(Summary!$B$11*12)/((1+G$5/12)^(Summary!$B$11*12)-1)),Summary!$B$32/Summary!$B$22) -> 5977885.1
A11: 0.07 | B11: =MIN(Summary!$B$20*Summary!$B$30/$A11,Summary!$B$32/(Summary!$B$21*12*(B$5/12)*(1+B$5/12)^(Summary!$B$11*12)/((1+B$5/12)^(Summary!$B$11*12)-1)),Summary!$B$32/Summary!$B$22) -> 5955612 | C11: =MIN(Summary!$B$20*Summary!$B$30/$A11,Summary!$B$32/(Summary!$B$21*12*(C$5/12)*(1+C$5/12)^(Summary!$B$11*12)/((1+C$5/12)^(Summary!$B$11*12)-1)),Summary!$B$32/Summary!$B$22) -> 5955612 | D11: =MIN(Summary!$B$20*Summary!$B$30/$A11,Summary!$B$32/(Summary!$B$21*12*(D$5/12)*(1+D$5/12)^(Summary!$B$11*12)/((1+D$5/12)^(Summary!$B$11*12)-1)),Summary!$B$32/Summary!$B$22) -> 5955612 | E11: =MIN(Summary!$B$20*Summary!$B$30/$A11,Summary!$B$32/(Summary!$B$21*12*(E$5/12)*(1+E$5/12)^(Summary!$B$11*12)/((1+E$5/12)^(Summary!$B$11*12)-1)),Summary!$B$32/Summary!$B$22) -> 5955612 | F11: =MIN(Summary!$B$20*Summary!$B$30/$A11,Summary!$B$32/(Summary!$B$21*12*(F$5/12)*(1+F$5/12)^(Summary!$B$11*12)/((1+F$5/12)^(Summary!$B$11*12)-1)),Summary!$B$32/Summary!$B$22) -> 5955612 | G11: =MIN(Summary!$B$20*Summary!$B$30/$A11,Summary!$B$32/(Summary!$B$21*12*(G$5/12)*(1+G$5/12)^(Summary!$B$11*12)/((1+G$5/12)^(Summary!$B$11*12)-1)),Summary!$B$32/Summary!$B$22) -> 5955612
A14: TABLE 2: Net Cash-Out ($) — (Max Loan) − (Existing Payoff + Orig 1% + Closing $45K)
A15: Cap ↓ / Sizing rate → | B15: 0.055 | C15: 0.06 | D15: 0.0625 | E15: 0.065 | F15: 0.07 | G15: 0.075
A16: 0.05 | B16: =B6-Summary!$B$25-Summary!$B$23*B6-Summary!$B$24 -> 2651709.6 | C16: =C6-Summary!$B$25-Summary!$B$23*C6-Summary!$B$24 -> 2651709.6 | D16: =D6-Summary!$B$25-Summary!$B$23*D6-Summary!$B$24 -> 2475659.7 | E16: =E6-Summary!$B$25-Summary!$B$23*E6-Summary!$B$24 -> 2301804.5 | F16: =F6-Summary!$B$25-Summary!$B$23*F6-Summary!$B$24 -> 1974765.9 | G16: =G6-Summary!$B$25-Summary!$B$23*G6-Summary!$B$24 -> 1673106.3
A17: 0.055 | B17: =B7-Summary!$B$25-Summary!$B$23*B7-Summary!$B$24 -> 2651709.6 | C17: =C7-Summary!$B$25-Summary!$B$23*C7-Summary!$B$24 -> 2651709.6 | D17: =D7-Summary!$B$25-Summary!$B$23*D7-Summary!$B$24 -> 2475659.7 | E17: =E7-Summary!$B$25-Summary!$B$23*E7-Summary!$B$24 -> 2301804.5 | F17: =F7-Summary!$B$25-Summary!$B$23*F7-Summary!$B$24 -> 1974765.9 | G17: =G7-Summary!$B$25-Summary!$B$23*G7-Summary!$B$24 -> 1673106.3
A18: 0.0575 | B18: =B8-Summary!$B$25-Summary!$B$23*B8-Summary!$B$24 -> 2651709.6 | C18: =C8-Summary!$B$25-Summary!$B$23*C8-Summary!$B$24 -> 2651709.6 | D18: =D8-Summary!$B$25-Summary!$B$23*D8-Summary!$B$24 -> 2475659.7 | E18: =E8-Summary!$B$25-Summary!$B$23*E8-Summary!$B$24 -> 2301804.5 | F18: =F8-Summary!$B$25-Summary!$B$23*F8-Summary!$B$24 -> 1974765.9 | G18: =G8-Summary!$B$25-Summary!$B$23*G8-Summary!$B$24 -> 1673106.3
A19: 0.06 | B19: =B9-Summary!$B$25-Summary!$B$23*B9-Summary!$B$24 -> 2633731.9 | C19: =C9-Summary!$B$25-Summary!$B$23*C9-Summary!$B$24 -> 2633731.9 | D19: =D9-Summary!$B$25-Summary!$B$23*D9-Summary!$B$24 -> 2475659.7 | E19: =E9-Summary!$B$25-Summary!$B$23*E9-Summary!$B$24 -> 2301804.5 | F19: =F9-Summary!$B$25-Summary!$B$23*F9-Summary!$B$24 -> 1974765.9 | G19: =G9-Summary!$B$25-Summary!$B$23*G9-Summary!$B$24 -> 1673106.3
A20: 0.065 | B20: =B10-Summary!$B$25-Summary!$B$23*B10-Summary!$B$24 -> 2104598.6 | C20: =C10-Summary!$B$25-Summary!$B$23*C10-Summary!$B$24 -> 2104598.6 | D20: =D10-Summary!$B$25-Summary!$B$23*D10-Summary!$B$24 -> 2104598.6 | E20: =E10-Summary!$B$25-Summary!$B$23*E10-Summary!$B$24 -> 2104598.6 | F20: =F10-Summary!$B$25-Summary!$B$23*F10-Summary!$B$24 -> 1974765.9 | G20: =G10-Summary!$B$25-Summary!$B$23*G10-Summary!$B$24 -> 1673106.3
A21: 0.07 | B21: =B11-Summary!$B$25-Summary!$B$23*B11-Summary!$B$24 -> 1651055.9 | C21: =C11-Summary!$B$25-Summary!$B$23*C11-Summary!$B$24 -> 1651055.9 | D21: =D11-Summary!$B$25-Summary!$B$23*D11-Summary!$B$24 -> 1651055.9 | E21: =E11-Summary!$B$25-Summary!$B$23*E11-Summary!$B$24 -> 1651055.9 | F21: =F11-Summary!$B$25-Summary!$B$23*F11-Summary!$B$24 -> 1651055.9 | G21: =G11-Summary!$B$25-Summary!$B$23*G11-Summary!$B$24 -> 1651055.9

Sheet Source_Register
A1: SOURCE REGISTER — evidence per fact
A3: Filename | B3: Page/Cell | C3: Fact / data captured | D3: Fields it supports
A4: manager-cover.pdf | B4: p.1 | C4: Property = Magnolia Terrace, Raleigh NC, multifamily. Manager mapping: A/B/C = Studio/1BR/2BR. Headline occupancy 45 of 48 counts pending as leased. | D4: asset id, type_a/b/c mapping, risk_pending_in_occupancy
A5: rent-roll-certified.xlsx | B5: Sheet 'Rent Roll' A2 (date); rows 5–52 | C5: 48 units as of 2026-08-31. 44 active, 1 pending (045), 3 vacant (046–048). Unit-type areas & rents controlling. | D5: total_units, occupied_units, pending_units, total_area_sf, occupied_area_sf, unit_occupancy, area_occupancy, annual_in_place_rent, unit_001_monthly_rent, gross_potential_rent, selected_roll_date, type_a/b/c_units + _occupied
A6: rent-roll-archive.xlsx | B6: Sheet 'Rent Roll' A2 | C6: As-of 2026-06-30. Stale — superseded by certified roll per diligence-status.pdf. | D6: selected_roll_date (excluded — stale archive)
A7: lease-001.pdf | B7: p.1 | C7: Suite 001 executed base $1,500/mo. Notes: signed later amendment controls conflicting terms; unsigned proposal does not change agreement. | D7: unit_001_monthly_rent, risk_unsigned_rent_change
A8: lease-correspondence.pdf | B8: p.1 | C8: Signed amendment effective 2026-08-01; both parties signed 2026-07-20. Monthly rent +$350; all other terms unchanged. | D8: unit_001_monthly_rent (in-place amended), source-conflict note
A9: operating-statement.pdf | B9: p.1 table | C9: T12 2025-09-01 → 2026-08-31: Collections $876,960; Taxes $102,312; Insurance $34,104; Other opex $136,416; Roof capital $0; Reported NOI $604,128. | D9: reported_t12_noi, uw_tax, uw_insurance, uw_operating_expenses, risk_capital_in_opex
A10: underwriting-instructions.pdf | B10: p.1 | C10: UW rules: GPR = all-suite scheduled rent × 12 pre-amendment; econ loss 5%; other income $350/unit; mgmt 3% of EGI; reserve $300/unit; cap 5.75%; LTV 65%; DSCR 1.25; DY 9%; amort 30 yr monthly; note 6.25%; floor 6.00%; size on greater rate; orig 1%; closing $45,000; payoff $4,200,000. | D10: cap_rate, sizing_rate, ltv_limit, dscr_limit, debt_yield_limit, uw_egi (rules), maximum_loan, net_cash_out, risk_sizing_floor_binding
A11: insurance.pdf | B11: p.1 | C11: GL policy aggregate limit $2,000,000. Effective 2026-07-01 → 2026-06-30-2027. Distinct from operating insurance expense. | D11: insurance_policy_limit, risk_missing_insurance
A12: diligence-status.pdf | B12: p.1 | C12: Legal / environmental / PCA / title reviews NOT completed — routine pending, no defect asserted. Match documents to this property; historical NOI, UW NOI, NCF have different definitions. | D12: diligence status, definitional labeling

Sheet Named_Fields
A1: NAMED FIELD DELIVERABLES — value + unit + evidence
A3: Field id | B3: Value | C3: Unit | D3: Evidence (filename) | E3: Page/Cell | F3: Calculation / note
A4: total_units | B4: 48 | C4: units | D4: rent-roll-certified.xlsx | E4: Sheet 'Rent Roll' rows 5–52 | F4: Count of suites 001–048.
A5: occupied_units | B5: 44 | C5: units | D5: rent-roll-certified.xlsx | E5: col D (Possession) rows 5–48 | F5: COUNTIF possession="active". Pending (045) and vacant (046–048) excluded.
A6: pending_units | B6: 1 | C6: units | D6: rent-roll-certified.xlsx | E6: row 49 (suite 045) | F6: Suite 045 — pending, not in possession.
A7: total_area_sf | B7: 40800 | C7: SF | D7: rent-roll-certified.xlsx | E7: col C rows 5–52 | F7: 16×700 + 16×820 + 16×1030 = 11,200 + 13,120 + 16,480 = 40,800.
A8: occupied_area_sf | B8: 36680 | C8: SF | D8: rent-roll-certified.xlsx | E8: col C where D='active' | F8: 16 Studios + 16 1BR + 12 2BR = 11,200 + 13,120 + 12,360 = 36,680.
A9: unit_occupancy | B9: 0.9167 | C9: decimal | D9: rent-roll-certified.xlsx | E9: derived | F9: 44 / 48 = 0.9167. Physical, possession-based — excludes pending.
A10: area_occupancy | B10: 0.899 | C10: decimal | D10: rent-roll-certified.xlsx | E10: derived | F10: 36,680 / 40,800 = 0.8990.
A11: annual_in_place_rent | B11: 974400 | C11: USD | D11: rent-roll-certified.xlsx | E11: col E × 12 | F11: SUM(all suite monthly rents) × 12 = 81,200 × 12.
A12: unit_001_monthly_rent | B12: 1850 | C12: USD/mo | D12: lease-001.pdf + lease-correspondence.pdf | E12: lease-001 p.1; correspondence p.1 | F12: Base $1,500 + signed amendment +$350 (effective 2026-08-01) = $1,850 in-place. Certified roll ($1,500) is pre-amendment — known resolvable source conflict.
A13: gross_potential_rent | B13: 974400 | C13: USD | D13: underwriting-instructions.pdf + rent-roll-certified.xlsx | E13: instructions p.1; roll rows 5–52 | F13: Per instructions: all-suite scheduled rent × 12 BEFORE Suite 001 amendment.
A14: uw_egi | B14: 942480 | C14: USD | D14: underwriting-instructions.pdf | E14: computed Summary!B28 | F14: GPR × (1 − 5% econ loss) + $350 × 48 = 925,680 + 16,800 = 942,480.
A15: uw_tax | B15: 102312 | C15: USD | D15: operating-statement.pdf + underwriting-instructions.pdf | E15: op stmt table row 'Real estate tax' | F15: Prescribed.
... A25: debt_yield_limit | B25: 0.09 | C25: decimal | D25: underwriting-instructions.pdf | E25: p.1 | F25: Prescribed min 9% on NCF.
A26: maximum_loan | B26: =Summary!B42 -> 6670285.4 | C26: USD | D26: computed | E26: Summary!B42 | F26: MIN(LTV, DSCR, DY) — see workbook for live value.
A27: net_cash_out | B27: =Summary!B51 -> 2358582.6 | C27: USD | D27: computed | E27: Summary!B51 | F27: Max loan − ($4.2M payoff + 1% orig + $45K closing). Negative = equity required.
A28: insurance_policy_limit | B28: 2000000 | C28: USD | D28: insurance.pdf | E28: p.1 | F28: GL aggregate limit; NOT the annual insurance expense.
A29: selected_roll_date | B29: 2026-08-31 | C29: date | D29: rent-roll-certified.xlsx | E29: A2 | F29: Controlling roll. Archive dated 2026-06-30 is stale.
A30: reported_t12_noi | B30: 604128 | C30: USD | D30: operating-statement.pdf | E30: p.1 table row 'Reported NOI' | F30: Historical, cash basis, before reserves. Definition differs from UW NCF.
A31: type_a_units | B31: 16 | C31: units | D31: rent-roll-certified.xlsx + manager-cover.pdf | E31: col B (Studio); manager mapping | F31: A=Studio per manager. 16 Studios in roll.
A32: type_a_occupied | B32: 16 | C32: units | D32: rent-roll-certified.xlsx | E32: col B=Studio, D=active | F32: All 16 Studios active.
A33: type_b_units | B33: 16 | C33: units | D33: rent-roll-certified.xlsx + manager-cover.pdf | E33: col B (1BR); manager mapping | F33: B=1BR. 16 units.
A34: type_b_occupied | B34: 16 | C34: units | D34: rent-roll-certified.xlsx | E34: col B=1BR, D=active | F34: All 16 1BRs active.
A35: type_c_units | B35: 16 | C35: units | D35: rent-roll-certified.xlsx + manager-cover.pdf | E35: col B (2BR); manager mapping | F35: C=2BR. 16 units.
A36: type_c_occupied | B36: 12 | C36: units | D36: rent-roll-certified.xlsx | E36: col B=2BR, D=active | F36: 12 of 16 2BRs active (045 pending, 048 vacant).
A37: risk_pending_in_occupancy | B37: present | C37: flag | D37: manager-cover.pdf | E37: p.1 | F37: Manager headline 'leased 45 of 48' counts 1 pending as leased. Cover note explicitly states pending occupants have not taken possession.
A38: risk_near_term_rollover | B38: absent | C38: flag | D38: rent-roll-certified.xlsx | E38: col F rows 5–52 | F38: All lease expirations 2029-08-31 — none within 12 months of 2026-08-31.
A39: risk_missing_insurance | B39: absent | C39: flag | D39: insurance.pdf | E39: p.1 | F39: GL policy in force through 2027-06-30; expense captured in T12.
A40: risk_capital_in_opex | B40: absent | C40: flag | D40: operating-statement.pdf | E40: p.1 row 'Roof replacement booked in repairs' | F40: Roof shown as $0 in repairs; explicitly labeled capital. Historical ledger classification is correct.
A41: risk_unsigned_rent_change | B41: absent | C41: flag | D41: lease-001.pdf + lease-correspondence.pdf | E41: packet review | F41: The only rent change in the packet is a SIGNED amendment (both parties executed 2026-07-20). No unsigned proposal is present.
A42: risk_temporary_free_rent | B42: absent | C42: flag | D42: lease-001.pdf | E42: p.1 | F42: 'No free-rent concession applies as of the evaluation date.'
A43: risk_sizing_floor_binding | B43: absent | C43: flag | D43: underwriting-instructions.pdf | E43: p.1 | F43: Note 6.25% > floor 6.00%. Note rate binds; floor is not the binding constraint.
A44: risk_refinance_shortfall | B44: =IF(Summary!B51<0,"present","absent") -> absent | C44: flag | D44: computed | E44: Summary!B51 | F44: Present if net_cash_out < 0 (loan proceeds < payoff + costs); see workbook.

Sheet IO_Map
A1: INPUT & OUTPUT CELL MAP (interoperability)
A3: INPUTS
A4: Field | B4: Sheet!Cell | C4: Notes
A5: gross_potential_rent | B5: Summary!B6 | C5: Annual, before econ loss
A6: cap_rate | B6: Summary!B7 | C6: Decimal
A7: sizing_rate | B7: Summary!B8 | C7: Greater of note or floor
A9: OUTPUTS
A10: Field | B10: Sheet!Cell | C10: Notes
A11: uw_egi | B11: Summary!B28 | C11: Live formula
A12: uw_noi | B12: Summary!B30 | C12: Live formula (before reserves)
A13: uw_ncf | B13: Summary!B32 | C13: Live formula (after reserves)
A14: capitalization_value | B14: Summary!B33 | C14: NOI / cap_rate
A15: maximum_loan | B15: Summary!B42 | C15: MIN(LTV, DSCR, DY)
A16: net_cash_out | B16: Summary!B51 | C16: Sources − Uses; negative = equity required
