Workbook

Sheet UW
A1: Magnolia Terrace - Underwriting
A3: As of date | B3: 2026-08-31
A4: Gross potential rent (annual) | B4: 974400
A5: Economic loss % | B5: 0.05
A6: Cap rate | B6: 0.0625
A7: Total units/suites | B7: 48
A8: Other income per unit (annual) | B8: 350
A9: Other income (annual) | B9: =B7*B8 -> 16800
A10: Real estate tax expense | B10: 102312
A11: Insurance expense | B11: 34104
A12: Other recurring opex | B12: 136416
A13: Management fee % of EGI | B13: 0.03
A14: Replacement reserve per unit (annual) | B14: 300
A15: Existing payoff | B15: 4200000
A16: Closing costs | B16: 45000
A17: Origination fee % | B17: 0.01
A18: Max LTV | B18: 0.65
A19: Min DSCR | B19: 1.25
A20: Min debt yield | B20: 0.09
A21: Amortization (years) | B21: 30
... A23: UW rate floor | B23: 0.06
A24: Sizing rate (used) | B24: =MAX(B22,B23) -> 0.0625
A26: Gross potential rent (annual) | B26: =B4 -> 974400
A27: Economic loss | B27: =B26*B5 -> 48720
A28: Other income (annual) | B28: =B9 -> 16800
A29: Underwritten EGI | B29: =B26-B27+B28 -> 942480
A31: Management fee | B31: =B29*B13 -> 28274.4
A32: Real estate tax expense | B32: =B10 -> 102312
A33: Insurance expense | B33: =B11 -> 34104
A34: Other recurring opex | B34: =B12 -> 136416
A35: Total opex before reserves | B35: =SUM(B31:B34) -> 301106.4
A36: UW NOI (before reserves) | B36: =B29-B35 -> 641373.6
A37: Replacement reserves | B37: =B7*B14 -> 14400
A38: UW NCF (after reserves) | B38: =B36-B37 -> 626973.6
A39: Capitalization value | B39: =B36/B6 -> 10261978
A41: LTV limit | B41: =B39*B18 -> 6670285.4
A42: Monthly sizing rate | B42: =B24/12 -> 0.0052083333
A43: Term (months) | B43: =B21*12 -> 360
A44: Payment per $1 (PMT monthly) | B44: =-PMT(B42,B43,1) -> 0.006157172
A45: ADS at DSCR (annual) | B45: =B38/B19 -> 501578.88
...

Sheet Sensitivity
A1: Maximum Loan Sensitivity
A3: Cap rate ↓ | Sizing rate → | B3: 0.0575 | C3: 0.0625 | D3: 0.0675
A4: 0.0525 | B4: =MIN((UW!B36/A4)*UW!B18, (UW!B38/UW!B19)/12/(-PMT(B3/12,UW!B43,1)), UW!B38/UW!B20) -> 6966373.3 | C4: =MIN((UW!B36/A4)*UW!B18, (UW!B38/UW!B19)/12/(-PMT(C3/12,UW!B43,1)), UW!B38/UW!B20) -> 6788545.1 | D4: =MIN((UW!B36/A4)*UW!B18, (UW!B38/UW!B19)/12/(-PMT(D3/12,UW!B43,1)), UW!B38/UW!B20) -> 6444397.6
A5: 0.0575 | B5: =MIN((UW!B36/A5)*UW!B18, (UW!B38/UW!B19)/12/(-PMT(B3/12,UW!B43,1)), UW!B38/UW!B20) -> 6966373.3 | C5: =MIN((UW!B36/A5)*UW!B18, (UW!B38/UW!B19)/12/(-PMT(C3/12,UW!B43,1)), UW!B38/UW!B20) -> 6788545.1 | D5: =MIN((UW!B36/A5)*UW!B18, (UW!B38/UW!B19)/12/(-PMT(D3/12,UW!B43,1)), UW!B38/UW!B20) -> 6444397.6
A6: 0.0625 | B6: =MIN((UW!B36/A6)*UW!B18, (UW!B38/UW!B19)/12/(-PMT(B3/12,UW!B43,1)), UW!B38/UW!B20) -> 6670285.4 | C6: =MIN((UW!B36/A6)*UW!B18, (UW!B38/UW!B19)/12/(-PMT(C3/12,UW!B43,1)), UW!B38/UW!B20) -> 6670285.4 | D6: =MIN((UW!B36/A6)*UW!B18, (UW!B38/UW!B19)/12/(-PMT(D3/12,UW!B43,1)), UW!B38/UW!B20) -> 6444397.6
A8: Max Loan ($)

Sheet Sources
A1: Source register
A3: Document | B3: Location (page / cell) | C3: Key data used
A4: rent-roll-certified.xlsx | B4: B2; A5:G52 | C4: Certified roll as of 2026-08-31; unit types, areas, statuses, monthly rents
A5: lease-001.pdf | B5: p.1 | C5: Suite 001 lease; $1,500/mo; 700 SF; 2029-08-31 expiry; no free rent; amendment may control
A6: lease-correspondence.pdf | B6: p.1 | C6: Signed amendment effective 2026-08-01; +$350/mo (impacts in-place rent only)
A7: operating-statement.pdf | B7: p.1 | C7: T12 collections $876,960; taxes $102,312; insurance $34,104; other opex $136,416; reported NOI $604,128
A8: insurance.pdf | B8: p.1 | C8: GL aggregate limit $2,000,000; 2026-07-01 to 2027-06-30
A9: manager-cover.pdf | B9: p.1 | C9: Manager counts occupied + pending as leased (45/48). A/B/C = Studio/1BR/2BR. Approved copy.
A10: diligence-status.pdf | B10: p.1 | C10: Pending third-party diligence; reconcile documents; different NOI/NCF definitions
A11: rent-roll-archive.xlsx | B11: B2; A5:G52 | C11: June 30, 2026 stale roll for comparison
