Workbook

Sheet README
B2: Juniper Flats — Underwriting Workbook
B3: Fictional refinance scenario | As of 2026-08-31 | USD | Prepared 2026-09-06
B5: Cell Color Legend
B6: Yellow = Editable Input
B7: Green = Key Output
B8: White = Formula / calculated
B10: Sheet Map
B11: Sheet | C11: Purpose
B12: Inputs | C12: Central editable assumptions — Cap Rate (B21), Sizing Rate (B22), UW EGI drivers (B10:B12), Op-Ex line items, loan terms
B13: Rent_Roll | C13: Unit-level rent roll and derived occupancy / contractual rent
B14: T12_Historical | C14: T12 monthly income statement and annual totals; NOI before reserves; NCF
B15: Underwriting | C15: Underwritten EGI, OpEx (incl. lender mgmt normalization), NOI, NCF — linked to Inputs
B16: Loan_Sizing | C16: LTV, DSCR and Debt-Yield constraints; binding maximum; first-year DS; sources & uses; cash to borrower
B17: Sensitivity | C17: Combined downside (EGI -5%, sizing rate +100 bps) and cap-rate +50 bps sensitivity
B18: Reported_Fields | C18: All requested field IDs with values, formulas and source citations
B21: Key Editable Inputs (jump to Inputs sheet)
B22: Cap Rate | C22: =Inputs!B21 -> 0.0575
B23: Sizing Rate (floor) | C23: =Inputs!B22 -> 0.0625
B24: Contract Rate | C24: =Inputs!B23 -> 0.059
B25: UW GPR (annual) | C25: =Inputs!B10 -> 864000
B26: UW Revenue Loss % | C26: =Inputs!B11 -> 0.06
B27: UW Other Income | C27: =Inputs!B12 -> 42000
B32: Key Outputs (live)
B33: UW NOI (before reserves) | C33: =Underwriting!B22 -> 545960
B34: UW NCF (after reserves) | C34: =Underwriting!B24 -> 535160
B35: Capitalized Value | C35: =Loan_Sizing!B7 -> 9494956.5
B36: Maximum Loan | C36: =Loan_Sizing!B22 -> 5794435.1
B37: Binding Constraint | C37: =Loan_Sizing!B23 -> DSCR
B38: Cash to Borrower | C38: =Loan_Sizing!B36 -> 2405976.8

Sheet Inputs
A1: Inputs — Editable Assumptions
A3: Underwriting Revenue
A4: Field | B4: Value | C4: Note
A5: Unit count (space_count) | B5: 36 | C5: Rent roll count
A6: Occupied count | B6: 33 | C6: Rent roll status
A7: Total rentable SF | B7: 31800 | C7: 20 x 750 + 16 x 1050
A8: Occupied SF | B8: 28950 | C8: Rent roll
A10: UW Gross Potential Base Rent (annual) | B10: 864000 | C10: Property-and-Plan p.2 (supplied scenario)
A11: UW Combined Revenue Loss % | B11: 0.06 | C11: 6.00% of UW GPR — vacancy/concessions/bad debt
A12: UW Other Income / Recoveries (annual) | B12: 42000 | C12: Property-and-Plan p.2 (added AFTER revenue loss)
A14: Management Fee — T12 actual (floor) | B14: 30000 | C14: T12-Statement annual col
A15: Management Fee — % of UW EGI (rate) | B15: 0.03 | C15: 3.00% per lender convention
A17: Loan Assumptions
A18: Field | B18: Value | C18: Note
A19: LTV maximum | B19: 0.65 | C19: Lender-Terms
A20: Loan-sizing DSCR minimum | B20: 1.25 | C20: Lender-Terms
A21: Cap Rate (valuation) | B21: 0.0575 | C21: Lender-Terms — applied to UW NOI BEFORE reserves
A22: Sizing Rate (floor) | B22: 0.0625 | C22: Lender-Terms — greater of contract rate and 6.25%
A23: Contract Rate (annual, fixed) | B23: 0.059 | C23: Lender-Terms
A24: Debt-Yield minimum (on NCF) | B24: 0.085 | C24: Lender-Terms
A25: Amortization (years) | B25: 30 | C25: Lender-Terms
A26: Interest-Only period (months) | B26: 24 | C26: Lender-Terms
A27: Maturity (months) | B27: 84 | C27: Lender-Terms
A28: Origination fee (% of initial principal) | B28: 0.0075 | C28: Lender-Terms
A29: Existing debt payoff | B29: 3300000 | C29: Property-and-Plan
A30: Fixed closing costs | B30: 45000 | C30: Property-and-Plan
A31: Replacement Reserves ($/unit/yr) | B31: 300 | C31: Property-and-Plan
A34: UW Operating Expenses (per Property-and-Plan)
A35: Line item | B35: UW annual $ | C35: Basis
A36: Real estate taxes | B36: 112000 | C36: Property-and-Plan table
A37: Property insurance | B37: 33600 | C37: Renewal quote in packet ($33,600)
A38: Utilities | B38: 28800 | C38: T12 actual
A39: Repairs & maintenance | B39: 40200 | C39: T12 46,200 less 6,000 one-time casualty
A40: Payroll / contract labor | B40: 42000 | C40: T12 actual
A41: Administrative / legal | B41: 21600 | C41: T12 actual

Sheet Rent_Roll
A1: Rent Roll — as of 2026-08-31
A2: Source: Rent-Roll.xlsx
A4: Unit | B4: Tenant | C4: Area SF | D4: Status | E4: Monthly Base Rent | F4: Market Monthly Rent | G4: Lease Expiry
A5: 101 | B5: Household 101 | C5: 750 | D5: Occupied | E5: 1675 | F5: 1675 | G5: 2027-07-31
A6: 102 | B6: Household 102 | C6: 750 | D6: Occupied | E6: 1675 | F6: 1675 | G6: 2026-10-31
A7: 103 | B7: Household 103 | C7: 750 | D7: Occupied | E7: 1675 | F7: 1675 | G7: 2026-11-30
A8: 104 | B8: Household 104 | C8: 750 | D8: Occupied | E8: 1675 | F8: 1675 | G8: 2026-12-31
A9: 105 | B9: Household 105 | C9: 750 | D9: Occupied | E9: 1675 | F9: 1675 | G9: 2027-01-31
A10: 106 | B10: Household 106 | C10: 750 | D10: Occupied | E10: 1675 | F10: 1675 | G10: 2027-02-28
A11: 107 | B11: Household 107 | C11: 750 | D11: Occupied | E11: 1675 | F11: 1675 | G11: 2027-03-31
A12: 108 | B12: Household 108 | C12: 750 | D12: Occupied | E12: 1675 | F12: 1675 | G12: 2027-04-30
A13: 109 | B13: Vacant | C13: 750 | D13: Vacant | F13: 1675
A14: 110 | B14: Household 110 | C14: 750 | D14: Occupied | E14: 1675 | F14: 1675 | G14: 2027-06-30
A15: 111 | B15: Household 111 | C15: 750 | D15: Occupied | E15: 1675 | F15: 1675 | G15: 2027-07-31
A16: 112 | B16: Household 112 | C16: 750 | D16: Occupied | E16: 1675 | F16: 1675 | G16: 2027-08-31
A17: 113 | B17: Household 113 | C17: 750 | D17: Occupied | E17: 1675 | F17: 1675 | G17: 2026-09-30
A18: 114 | B18: Household 114 | C18: 750 | D18: Occupied | E18: 1675 | F18: 1675 | G18: 2026-10-31
A19: 115 | B19: Household 115 | C19: 750 | D19: Occupied | E19: 1675 | F19: 1675 | G19: 2026-11-30
A20: 116 | B20: Household 116 | C20: 750 | D20: Occupied | E20: 1675 | F20: 1675 | G20: 2026-12-31
A21: 117 | B21: Household 117 | C21: 750 | D21: Occupied | E21: 1675 | F21: 1675 | G21: 2027-01-31
A22: 118 | B22: Household 118 | C22: 750 | D22: Occupied | E22: 1675 | F22: 1675 | G22: 2027-02-28
A23: 119 | B23: Household 119 | C23: 750 | D23: Occupied | E23: 1675 | F23: 1675 | G23: 2027-03-31
A24: 120 | B24: Household 120 | C24: 750 | D24: Occupied | E24: 1675 | F24: 1675 | G24: 2027-04-30
A25: 121 | B25: Household 121 | C25: 1050 | D25: Occupied | E25: 2175 | F25: 2175 | G25: 2027-05-31
... A28: 124 | B28: Household 124 | C28: 1050 | D28: Occupied | E28: 2175 | F28: 2175 | G28: 2027-08-31
A29: 125 | B29: Vacant | C29: 1050 | D29: Vacant | F29: 2175
A30: 126 | B30: Household 126 | C30: 1050 | D30: Occupied | E30: 2175 | F30: 2175 | G30: 2026-10-31
A31: 127 | B31: Household 127 | C31: 1050 | D31: Occupied | E31: 2175 | F31: 2175 | G31: 2026-11-30
A32: 128 | B32: Household 128 | C32: 1050 | D32: Occupied | E32: 2175 | F32: 2175 | G32: 2026-12-31
A33: 129 | B33: Household 129 | C33: 1050 | D33: Occupied | E33: 2175 | F33: 2175 | G33: 2027-01-31
A34: 130 | B34: Household 130 | C34: 1050 | D34: Occupied | E34: 2175 | F34: 2175 | G34: 2027-02-28
A35: 131 | B35: Household 131 | C35: 1050 | D35: Occupied | E35: 2175 | F35: 2175 | G35: 2027-03-31
A36: 132 | B36: Household 132 | C36: 1050 | D36: Occupied | E36: 2175 | F36: 2175 | G36: 2027-04-30
A37: 133 | B37: Household 133 | C37: 1050 | D37: Occupied | E37: 2175 | F37: 2175 | G37: 2027-05-31
A38: 134 | B38: Household 134 | C38: 1050 | D38: Occupied | E38: 2175 | F38: 2175 | G38: 2027-06-30
A39: 135 | B39: Household 135 | C39: 1050 | D39: Occupied | E39: 2175 | F39: 2175 | G39: 2027-07-31
A40: 136 | B40: Vacant | C40: 1050 | D40: Vacant | F40: 2175
A42: TOTALS / Derived
A43: space_count (units) | B43: =COUNTA(A5:A40) -> 36
A44: occupied_count | B44: =COUNTIF(D5:D40,"Occupied") -> 33
...

Sheet T12_Historical
A1: T12 Historical Income Statement (Sep-2025 through Aug-2026)
A2: Source: T12-Statement.pdf p.1-2
A4: Account | B4: Sep-25 | C4: Oct-25 | D4: Nov-25 | E4: Dec-25 | F4: Jan-26 | G4: Feb-26 | H4: Mar-26 | I4: Apr-26 | J4: May-26 | K4: Jun-26 | L4: Jul-26 | M4: Aug-26 | N4: Annual | O4: Source note
A5: Gross potential base rent | B5: 65800 | C5: 67200 | D5: 68600 | E5: 69300 | F5: 70700 | G5: 72100 | H5: 72800 | I5: 74200 | J5: 72100 | K5: 70700 | L5: 68600 | M5: 67900 | N5: =SUM(B5:M5) -> 840000 | O5: T12 p.1-2, Annual col = 840,000
A6: Vacancy loss | B6: -3360 | C6: -3430 | D6: -3465 | E6: -3535 | F6: -3605 | G6: -3640 | H6: -3710 | I6: -3605 | J6: -3535 | K6: -3430 | L6: -3395 | M6: -3290 | N6: =SUM(B6:M6) -> -42000 | O6: Negative revenue
A7: Concessions | B7: -980 | C7: -990 | D7: -1010 | E7: -1030 | F7: -1040 | G7: -1060 | H7: -1030 | I7: -1010 | J7: -980 | K7: -970 | L7: -940 | M7: -960 | N7: =SUM(B7:M7) -> -12000
A8: Bad debt | B8: -371 | C8: -379 | D8: -386 | E8: -390 | F8: -398 | G8: -386 | H8: -379 | I8: -368 | J8: -364 | K8: -352 | L8: -360 | M8: -367 | N8: =SUM(B8:M8) -> -4500
A9: Other income / recoveries | B9: 3333 | C9: 3399 | D9: 3432 | E9: 3498 | F9: 3399 | G9: 3333 | H9: 3234 | I9: 3201 | J9: 3102 | K9: 3168 | L9: 3234 | M9: 3267 | N9: =SUM(B9:M9) -> 39600 | O9: Reimbursements/other
A10: Real estate taxes | B10: 9270 | C10: 9360 | D10: 9540 | E10: 9270 | F10: 9090 | G10: 8820 | H10: 8730 | I10: 8460 | J10: 8640 | K10: 8820 | L10: 8910 | M10: 9090 | N10: =SUM(B10:M10) -> 108000
A11: Property insurance | B11: 2704 | C11: 2756 | D11: 2678 | E11: 2626 | F11: 2548 | G11: 2522 | H11: 2444 | I11: 2496 | J11: 2548 | K11: 2574 | L11: 2626 | M11: 2678 | N11: =SUM(B11:M11) -> 31200
A12: Utilities | B12: 2544 | C12: 2472 | D12: 2424 | E12: 2352 | F12: 2328 | G12: 2256 | H12: 2304 | I12: 2352 | J12: 2376 | K12: 2424 | L12: 2472 | M12: 2496 | N12: =SUM(B12:M12) -> 28800
A13: Repairs and maintenance | B13: 3966 | C13: 3888 | D13: 3773 | E13: 3734 | F13: 3619 | G13: 3696 | H13: 3773 | I13: 3812 | J13: 3888 | K13: 3966 | L13: 4004 | M13: 4081 | N13: =SUM(B13:M13) -> 46200 | O13: Includes $6k one-time casualty
A14: Payroll / contract labor | B14: 3535 | C14: 3430 | D14: 3395 | E14: 3290 | F14: 3360 | G14: 3430 | H14: 3465 | I14: 3535 | J14: 3605 | K14: 3640 | L14: 3710 | M14: 3605 | N14: =SUM(B14:M14) -> 42000
A15: Administrative / legal | B15: 1764 | C15: 1746 | D15: 1692 | E15: 1728 | F15: 1764 | G15: 1782 | H15: 1818 | I15: 1854 | J15: 1872 | K15: 1908 | L15: 1854 | M15: 1818 | N15: =SUM(B15:M15) -> 21600
A16: Management fee | B16: 2425 | C16: 2350 | D16: 2400 | E16: 2450 | F16: 2475 | G16: 2525 | H16: 2575 | I16: 2600 | J16: 2650 | K16: 2575 | L16: 2525 | M16: 2450 | N16: =SUM(B16:M16) -> 30000
A17: Replacement reserves (below NOI) | B17: 846 | C17: 864 | D17: 882 | E17: 891 | F17: 909 | G17: 927 | H17: 936 | I17: 954 | J17: 927 | K17: 909 | L17: 882 | M17: 873 | N17: =SUM(B17:M17) -> 10800 | O17: Below NOI
A18: Capital improvements (below cash flow) | B18: 4960 | C18: 5063 | D18: 5115 | E18: 5218 | F18: 5322 | G18: 5373 | H18: 5477 | I18: 5322 | J18: 5218 | K18: 5063 | L18: 5012 | M18: 4857 | N18: =SUM(B18:M18) -> 62000 | O18: Below cash flow
A19: Loan principal and interest (below CF) | B19: 24010 | C19: 24255 | D19: 24745 | E19: 25235 | F19: 25480 | G19: 25970 | H19: 25235 | I19: 24745 | J19: 24010 | K19: 23765 | L19: 23030 | M19: 23520 | N19: =SUM(B19:M19) -> 294000 | O19: Below cash flow
A20: Depreciation (noncash) | B20: 14850 | C20: 15150 | D20: 15450 | E20: 15600 | F20: 15900 | G20: 15450 | H20: 15150 | I20: 14700 | J20: 14550 | K20: 14100 | L20: 14400 | M20: 14700 | N20: =SUM(B20:M20) -> 180000 | O20: Noncash — not operating
A22: T12 EGI | N22: =N5+N6+N7+N8+N9 -> 821100
A23: T12 Operating Expenses | N23: =SUM(N10:N16) -> 307800
A24: T12 NOI (before reserves) | N24: =N22-N23 -> 513300
A25: T12 Replacement reserves | N25: =N17 -> 10800
A26: T12 NCF (after reserves) | N26: =N24-N25 -> 502500

Sheet Underwriting
A1: Underwritten Cash Flow (linked to Inputs)
A2: All rates and assumptions per Property-and-Plan
A4: Line | B4: Amount | C4: Formula / Basis
A5: UW Gross Potential Base Rent | B5: =UW_GPR -> 864000 | C5: Inputs B10
A6: Less: combined revenue loss (vacancy/concessions/bad debt) | B6: =-UW_RevLoss*UW_GPR -> -51840 | C6: =-6% x uw gpr -> #VALUE!
A7: Plus: other income / recoveries | B7: =UW_OtherInc -> 42000 | C7: Inputs B12
A8: Underwritten EGI (uw_egi) | B8: =B5+B6+B7 -> 854160 | C8: GPR - loss + other
A10: UW Operating Expenses
A11: Real estate taxes | B11: =Inputs!B36 -> 112000 | C11: Inputs B36
A12: Property insurance | B12: =Inputs!B37 -> 33600 | C12: Renewal quote
A13: Utilities | B13: =Inputs!B38 -> 28800 | C13: T12 actual
A14: Repairs & maintenance (T12 less $6k one-time) | B14: =Inputs!B39 -> 40200 | C14: Inputs B39
A15: Payroll / contract labor | B15: =Inputs!B40 -> 42000 | C15: T12 actual
A16: Administrative / legal | B16: =Inputs!B41 -> 21600 | C16: T12 actual
A17: Management fee (uw_management_fee) | B17: =MAX(MgmtFloor,MgmtPct*B8) -> 30000 | C17: MAX(T12 $30,000; 3% x EGI)
A19: Total UW OpEx (uw_operating_expenses) | B19: =SUM(B11:B17) -> 308200 | C19: Excludes reserves/capex/debt/depr.
A22: UW NOI before reserves (uw_noi_before_reserves) | B22: =B8-B19 -> 545960
A23: Less: Replacement reserves ($300/unit) | B23: =ReservesPerUnit*UnitCount -> 10800
A24: UW NCF after reserves (uw_ncf) | B24: =B22-B23 -> 535160

Sheet Loan_Sizing
A1: Loan Sizing — LTV / DSCR / Debt Yield
A3: Field | B3: Value | C3: Formula / Basis
A5: UW NOI (before reserves) | B5: =UW_NOI_BR -> 545960 | C5: From Underwriting
A6: Cap Rate | B6: =CapRate -> 0.0575 | C6: Inputs
A7: Indicative Value (capitalization_value) | B7: =B5/B6 -> 9494956.5 | C7: NOI / Cap
A9: Sizing Rate | B9: =SizingRate -> 0.0625 | C9: Greater of Contract & 6.25%
A10: Contract Rate | B10: =ContractRate -> 0.059 | C10: Inputs
A11: Amortization (years) | B11: =AmortYears -> 30
A12: Monthly rate (sizing) | B12: =B9/12 -> 0.0052083333
A13: Number of payments | B13: =B11*12 -> 360
A14: Monthly payment factor | B14: =B12/(1-(1+B12)^-B13) -> 0.006157172
A15: Annual debt constant (sizing) — annual_debt_constant | B15: =B14*12 -> 0.073886064
A17: Constraints
A18: ltv_limit (LTV_Max * Value) | B18: =LTV_Max*B7 -> 6171721.7
A19: dscr_limit (NCF / DSCR_Min / ADC) | B19: =UW_NCF/DSCR_Min/B15 -> 5794435.1
A20: debt_yield_limit (NCF / DY_Min) | B20: =UW_NCF/DY_Min -> 6296000
A22: maximum_loan (min of the three) | B22: =MIN(B18:B20) -> 5794435.1
A23: binding_constraint | B23: =IF(B22=B18,"LTV",IF(B22=B19,"DSCR","Debt yield")) -> DSCR
A25: sizing_annual_debt_service (loan x ADC) | B25: =B22*B15 -> 428128
A26: sizing_dscr (NCF / Sizing ADS) | B26: =UW_NCF/B25 -> 1.25
A27: sizing_debt_yield (NCF / Loan) | B27: =UW_NCF/B22 -> 0.09235758
A29: first_year_debt_service (IO — Loan x Contract rate) | B29: =B22*B10 -> 341871.67 | C29: First 24 mo. IO; year-1 DS = interest only
A31: Sources & Uses
A32: Loan proceeds | B32: =B22 -> 5794435.1
A33: Less: Existing debt payoff | B33: =-Payoff -> -3300000
A34: Less: Origination fee (0.75% of loan) | B34: =-OrigFeePct*B22 -> -43458.263
A35: Less: Fixed closing costs | B35: =-ClosingCosts -> -45000
A36: cash_to_borrower (net; negative = cash-in) | B36: =SUM(B32:B35) -> 2405976.8

Sheet Sensitivity
A1: Sensitivity — Downside cases
A2: Per Property-and-Plan: EGI -5% & +100 bps sizing (cap unchanged); separately +50 bps cap
A4: Base Case
A5: UW EGI | B5: =UW_EGI -> 854160
A6: UW NOI (before reserves) | B6: =UW_NOI_BR -> 545960
A7: UW NCF | B7: =UW_NCF -> 535160
A8: Sizing rate | B8: =SizingRate -> 0.0625
A9: Cap rate | B9: =CapRate -> 0.0575
A10: Max loan | B10: =MaxLoan -> 5794435.1
A11: Binding | B11: =Loan_Sizing!B23 -> DSCR
A14: Combined downside (EGI -5%, +100 bps sizing, cap unchanged)
A15: Stress EGI (95% of UW) | B15: =UW_EGI*0.95 -> 811452
A16: Stress management fee (MAX floor, 3% stress EGI) | B16: =MAX(MgmtFloor,MgmtPct*B15) -> 30000
A17: Other OpEx (unchanged) | B17: =Underwriting!B19-Underwriting!B17 -> 278200
A18: Stress OpEx (total) | B18: =B16+B17 -> 308200
A19: stress_uw_noi (before reserves) | B19: =B15-B18 -> 503252
A20: Stress replacement reserves (unchanged) | B20: =ReservesPerUnit*UnitCount -> 10800
A21: Stress NCF | B21: =B19-B20 -> 492452
A23: Stress sizing rate (+100 bps) | B23: =SizingRate+0.01 -> 0.0725
A24: Stress monthly rate | B24: =B23/12 -> 0.0060416667
A25: Stress ADC (sizing) | B25: =(B24/(1-(1+B24)^-(AmortYears*12)))*12 -> 0.081861154
A27: Stress value (Stress NOI / Cap; cap unchanged) | B27: =B19/CapRate -> 8752208.7
A28: Stress LTV limit | B28: =LTV_Max*B27 -> 5688935.7
A29: Stress DSCR limit (Stress NCF / DSCR_Min / Stress ADC) | B29: =B21/DSCR_Min/B25 -> 4812558.6
A30: Stress DY limit (Stress NCF / DY_Min) | B30: =B21/DY_Min -> 5793552.9
A31: stress_maximum_loan | B31: =MIN(B28:B30) -> 4812558.6
A32: Stress binding | B32: =IF(B31=B28,"LTV",IF(B31=B29,"DSCR","Debt yield")) -> DSCR
A35: Cap rate +50 bps (base income, unchanged sizing)
A36: Cap rate +50 bps | B36: =CapRate+0.005 -> 0.0625
A37: Alt value | B37: =UW_NOI_BR/B36 -> 8735360
A38: Alt LTV limit | B38: =LTV_Max*B37 -> 5677984
A39: DSCR limit (unchanged rates/NCF) | B39: =UW_NCF/DSCR_Min/ADC_Sizing -> 5794435.1
A40: DY limit (unchanged NCF) | B40: =UW_NCF/DY_Min -> 6296000
A41: Alt max loan | B41: =MIN(B38:B40) -> 5677984
A42: Alt binding | B42: =IF(B41=B38,"LTV",IF(B41=B39,"DSCR","Debt yield")) -> LTV

Sheet Reported_Fields
A1: Reported Analysis Fields
A3: Field ID | B3: Value / Formula | C3: Format | D3: Source / Basis
A4: space_count | B4: =Rent_Roll!B43 -> 36 | C4: #,##0 | D4: Rent-Roll.xlsx units 101-136
A5: occupied_count | B5: =Rent_Roll!B44 -> 33 | C5: #,##0 | D5: COUNTIF status Occupied
A6: total_area_sf | B6: =Rent_Roll!B45 -> 31800 | C6: #,##0 | D6: SUM(area)
A7: occupied_area_sf | B7: =Rent_Roll!B46 -> 28950 | C7: #,##0 | D7: SUMIF occupied
A8: occupancy_count_pct | B8: =Rent_Roll!B47*100 -> 91.666667 | C8: 0.0000 | D8: =occupied_count / space_count x 100 -> #VALUE!
A9: occupancy_area_pct | B9: =Rent_Roll!B48*100 -> 91.037736 | C9: 0.0000 | D9: =occupied_area_sf / total_area_sf x 100 -> #VALUE!
A10: rent_roll_monthly_base | B10: =Rent_Roll!B49 -> 62275 | C10: "$"#,##0.00;[Red]("$"#,##0.00) | D10: SUM rent roll monthly base (occupied only)
A11: effective_monthly_base | B11: =Rent_Roll!B51 -> 62275 | C11: "$"#,##0.00;[Red]("$"#,##0.00) | D11: Lease-101 rent $1,675 matches rent roll; no amendments
A12: t12_egi | B12: =T12_Historical!N22 -> 821100 | C12: "$"#,##0.00;[Red]("$"#,##0.00) | D12: Sum revenue lines
A13: t12_operating_expenses | B13: =T12_Historical!N23 -> 307800 | C13: "$"#,##0.00;[Red]("$"#,##0.00) | D13: Sum OpEx (excl. reserves/capex/debt/depr.)
A14: t12_noi_before_reserves | B14: =T12_Historical!N24 -> 513300 | C14: "$"#,##0.00;[Red]("$"#,##0.00) | D14: EGI - OpEx
A15: t12_reserves | B15: =T12_Historical!N25 -> 10800 | C15: "$"#,##0.00;[Red]("$"#,##0.00) | D15: T12 reserves line
A16: t12_ncf | B16: =T12_Historical!N26 -> 502500 | C16: "$"#,##0.00;[Red]("$"#,##0.00) | D16: NOI - reserves
A17: uw_egi | B17: =Underwriting!B8 -> 854160 | C17: "$"#,##0.00;[Red]("$"#,##0.00) | D17: GPR - loss + other
A18: uw_management_fee | B18: =Underwriting!B17 -> 30000 | C18: "$"#,##0.00;[Red]("$"#,##0.00) | D18: MAX(T12 $30k, 3% x UW EGI)
A19: uw_operating_expenses | B19: =Underwriting!B19 -> 308200 | C19: "$"#,##0.00;[Red]("$"#,##0.00) | D19: Sum of OpEx incl. lender mgmt
A20: uw_noi_before_reserves | B20: =Underwriting!B22 -> 545960 | C20: "$"#,##0.00;[Red]("$"#,##0.00) | D20: UW EGI - UW OpEx
A21: uw_reserves | B21: =Underwriting!B23 -> 10800 | C21: "$"#,##0.00;[Red]("$"#,##0.00) | D21: $300/unit x 36 units
A22: uw_ncf | B22: =Underwriting!B24 -> 535160 | C22: "$"#,##0.00;[Red]("$"#,##0.00) | D22: UW NOI - reserves
A23: capitalization_value | B23: =Loan_Sizing!B7 -> 9494956.5 | C23: "$"#,##0.00;[Red]("$"#,##0.00) | D23: UW NOI / 5.75%
A24: contract_rate | B24: =ContractRate -> 0.059 | C24: 0.00% | D24: 5.90% (Lender-Terms)
A25: sizing_rate | B25: =SizingRate -> 0.0625 | C25: 0.00% | D25: Greater of contract & 6.25%
A26: annual_debt_constant | B26: =Loan_Sizing!B15 -> 0.073886064 | C26: 0.00000000 | D26: 30-yr, monthly amort at sizing rate
A27: ltv_limit | B27: =Loan_Sizing!B18 -> 6171721.7 | C27: "$"#,##0.00;[Red]("$"#,##0.00) | D27: 65% x value
A28: dscr_limit | B28: =Loan_Sizing!B19 -> 5794435.1 | C28: "$"#,##0.00;[Red]("$"#,##0.00) | D28: NCF / 1.25 / ADC
A29: debt_yield_limit | B29: =Loan_Sizing!B20 -> 6296000 | C29: "$"#,##0.00;[Red]("$"#,##0.00) | D29: NCF / 8.50%
A30: maximum_loan | B30: =Loan_Sizing!B22 -> 5794435.1 | C30: "$"#,##0.00;[Red]("$"#,##0.00) | D30: MIN of three constraints
A31: binding_constraint | B31: =Loan_Sizing!B23 -> DSCR | C31: General | D31: LTV/DSCR/Debt yield
A32: sizing_annual_debt_service | B32: =Loan_Sizing!B25 -> 428128 | C32: "$"#,##0.00;[Red]("$"#,##0.00) | D32: Max loan x ADC
A33: sizing_dscr | B33: =Loan_Sizing!B26 -> 1.25 | C33: 0.0000"x" | D33: NCF / Sizing ADS
A34: sizing_debt_yield | B34: =Loan_Sizing!B27 -> 0.09235758 | C34: 0.00% | D34: NCF / Max loan
A35: first_year_debt_service | B35: =Loan_Sizing!B29 -> 341871.67 | C35: "$"#,##0.00;[Red]("$"#,##0.00) | D35: IO year — Loan x contract rate
A36: cash_to_borrower | B36: =Loan_Sizing!B36 -> 2405976.8 | C36: "$"#,##0.00;[Red]("$"#,##0.00) | D36: Loan - payoff - orig fee - closing
A37: stress_uw_noi | B37: =Sensitivity!B19 -> 503252 | C37: "$"#,##0.00;[Red]("$"#,##0.00) | D37: EGI -5%, mgmt recalc, other OpEx unchanged
A38: stress_maximum_loan | B38: =Sensitivity!B31 -> 4812558.6 | C38: "$"#,##0.00;[Red]("$"#,##0.00) | D38: EGI -5% AND sizing +100 bps; cap unchanged
A39: subject_lease_monthly_rent | B39: 1675 | C39: "$"#,##0.00;[Red]("$"#,##0.00) | D39: Lease-File §3 (unit 101)
A40: subject_lease_expiry | B40: 2027-07-31 | C40: @ | D40: Lease-File §2 (unit 101)
A41: subject_lease_deposit | B41: 1675 | C41: "$"#,##0.00;[Red]("$"#,##0.00) | D41: Lease-File §4 (unit 101)
...
