Workbook

Sheet Cover
A1: Falcon Distribution — Reconciled Underwriting Workbook (v2, revised)
A3: Property | B3: Falcon Distribution
A4: Market | B4: Indianapolis, IN
A5: Asset type | B5: Industrial
A6: Version | B6: v2 — revision applied 2026-09-01 (revision-notice.pdf)
A7: Analysis as-of date | B7: 2026-09-01 (revised certified roll)
A8: Prior version | B8: v1 dated 2026-08-31 preserved in audit archive (Falcon_Distribution_UW.xlsx v1)
A9: Prepared by | B9: Lev — Underwriting
A10: Sources | B10: Packet documents only — no external research
A11: Notice | B11: Original fictional evaluation material; no real transaction
A12: Approved copy (preserved verbatim) | B12: Source-backed analysis. Assumptions remain subject to diligence.
A14: Change log (v1 → v2)
A15: Suite 002 rent | B15: $14,600 → $14,825/mo (+$225)
A16: Selected roll date | B16: 2026-08-31 → 2026-09-01
A17: Sizing rate (input) | B17: 7.00% → 7.75% (+75 bps)
A18: Cap rate (input) | B18: 6.2500% → 6.5000% (+25 bps)
A19: GPR | B19: $1,401,900 → $1,404,600
A20: UW EGI | B20: $1,334,605 → $1,337,170
A21: UW NOI (pre-reserve) | B21: $901,782.85 → $904,270.90
A22: UW NCF | B22: $899,382.85 → $901,870.90
A23: Capitalization value | B23: $14,428,525.60 → $13,911,860.00
A24: Maximum loan | B24: $9,012,270 → $8,392,555 (binding: DSCR, unchanged)
A25: Net cash-out | B25: $1,077,147 → $463,629 (still positive)
A26: Unaffected — occupancy | B26: unit_occupancy 0.8750; area_occupancy 0.8750; total_units 8; occupied 7; total SF 176,060
... A29: Unaffected — risks | B29: All 8 risk flags unchanged in polarity

Sheet Inputs
A1: Named driver inputs (edit yellow cells) — v2 revised
A2: Field | B2: Value | C2: Unit | D2: Notes / source
A3: gross_potential_rent | B3: 1404600 | C3: USD/yr | D3: REVISED: all-suite scheduled monthly rent on 2026-09-01 revised certified roll × 12, before Suite 001 amendment. Was $1,401,900.
A4: cap_rate | B4: 0.065 | C4: decimal | D4: REVISED: prior 6.2500% + 25 bps per revision-notice.pdf.
A5: sizing_rate | B5: 0.0775 | C5: decimal | D5: REVISED: prior 7.0000% + 75 bps per revision-notice.pdf. Floor still binds (> 6.10% note rate).
A7: Prescribed assumptions (unchanged from v1 except where noted)
A8: economic_loss_pct | B8: 0.05 | C8: decimal | D8: 5% economic loss on GPR.
A9: other_income_per_unit | B9: 350 | C9: USD/unit/yr | D9: Annual other income.
A10: mgmt_pct_of_egi | B10: 0.03 | C10: decimal | D10: Management fee = 3% of UW EGI.
A11: reserve_per_unit | B11: 300 | C11: USD/unit/yr | D11: Replacement reserve.
A12: uw_tax | B12: 147294 | C12: USD/yr | D12: Prescribed taxes.
A13: uw_insurance | B13: 49098 | C13: USD/yr | D13: Prescribed insurance.
A14: uw_other_opex | B14: 196392 | C14: USD/yr | D14: Prescribed other recurring opex.
A15: ltv_limit | B15: 0.65 | C15: decimal | D15: Max LTV constraint.
A16: dscr_limit | B16: 1.25 | C16: ratio | D16: Min DSCR constraint.
A17: debt_yield_limit | B17: 0.09 | C17: decimal | D17: Min NCF debt yield.
A18: amort_years | B18: 30 | C18: years | D18: Monthly amortization.
A19: note_rate | B19: 0.061 | C19: decimal | D19: Contract note rate (informational).
... A23: total_units | B23: 8 | C23: count | D23: From certified roll.

Sheet RentRoll
A1: Revised certified rent roll as of 2026-09-01 (rent-roll-revised.xlsx)
A2: Suite | B2: Unit type | C2: Group | D2: Area SF | E2: Possession | F2: Monthly rent | G2: Annual rent | H2: Occupied SF | I2: In-place monthly (occ)
A3: 001 | B3: Small suite | C3: A | D3: 21880 | E3: active | F3: 14450 | G3: =F3*12 -> 173400 | H3: =IF(E3="active",D3,0) -> 21880 | I3: =IF(E3="active",F3,0) -> 14450
A4: 002 | B4: Standard suite | C4: B | D4: 22000 | E4: active | F4: 14825 | G4: =F4*12 -> 177900 | H4: =IF(E4="active",D4,0) -> 22000 | I4: =IF(E4="active",F4,0) -> 14825
A5: 003 | B5: Large suite | C5: C | D5: 22210 | E5: active | F5: 14875 | G5: =F5*12 -> 178500 | H5: =IF(E5="active",D5,0) -> 22210 | I5: =IF(E5="active",F5,0) -> 14875
A6: 004 | B6: Small suite | C6: A | D6: 21880 | E6: active | F6: 14450 | G6: =F6*12 -> 173400 | H6: =IF(E6="active",D6,0) -> 21880 | I6: =IF(E6="active",F6,0) -> 14450
A7: 005 | B7: Standard suite | C7: B | D7: 22000 | E7: active | F7: 14600 | G7: =F7*12 -> 175200 | H7: =IF(E7="active",D7,0) -> 22000 | I7: =IF(E7="active",F7,0) -> 14600
A8: 006 | B8: Large suite | C8: C | D8: 22210 | E8: active | F8: 14875 | G8: =F8*12 -> 178500 | H8: =IF(E8="active",D8,0) -> 22210 | I8: =IF(E8="active",F8,0) -> 14875
A9: 007 | B9: Small suite | C9: A | D9: 21880 | E9: active | F9: 14450 | G9: =F9*12 -> 173400 | H9: =IF(E9="active",D9,0) -> 21880 | I9: =IF(E9="active",F9,0) -> 14450
A10: 008 | B10: Standard suite | C10: B | D10: 22000 | E10: vacant | F10: 14600 | G10: =F10*12 -> 175200 | H10: =IF(E10="active",D10,0) -> 0 | I10: =IF(E10="active",F10,0) -> 0
A11: Totals | D11: =SUM(D3:D10) -> 176060 | F11: =SUM(F3:F10) -> 117125 | G11: =SUM(G3:G10) -> 1405500 | H11: =SUM(H3:H10) -> 154060 | I11: =SUM(I3:I10) -> 102525
A13: Reconciled counts (formulas driven from roll above)
A14: total_units | B14: =COUNTA(A3:A10) -> 8 | C14: count
A15: occupied_units | B15: =COUNTIF(E3:E10,"active") -> 7 | C15: count
A16: pending_units | B16: =COUNTIF(E3:E10,"pending") -> 0 | C16: count
A17: vacant_units | B17: =COUNTIF(E3:E10,"vacant") -> 1 | C17: count
A18: total_area_sf | B18: =SUM(D3:D10) -> 176060 | C18: SF
A19: occupied_area_sf | B19: =SUMIF(E3:E10,"active",D3:D10) -> 154060 | C19: SF
A20: unit_occupancy | B20: =B15/B14 -> 0.875 | C20: decimal
A21: area_occupancy | B21: =B19/B18 -> 0.8750426 | C21: decimal
A22: unit_001_monthly_rent | B22: =F3 -> 14450 | C22: USD/mo
A23: annual_in_place_rent | B23: =SUM(I3:I10)*12 -> 1230300 | C23: USD/yr
A26: Unit mix by manager group (A=Small, B=Standard, C=Large)
A27: Group | B27: Units | C27: Occupied | D27: Area SF
A28: A | B28: =COUNTIF(C3:C10,"A") -> 3 | C28: =COUNTIFS(C3:C10,"A",E3:E10,"active") -> 3 | D28: =SUMIF(C3:C10,"A",D3:D10) -> 65640
A29: B | B29: =COUNTIF(C3:C10,"B") -> 3 | C29: =COUNTIFS(C3:C10,"B",E3:E10,"active") -> 2 | D29: =SUMIF(C3:C10,"B",D3:D10) -> 66000
A30: C | B30: =COUNTIF(C3:C10,"C") -> 2 | C30: =COUNTIFS(C3:C10,"C",E3:E10,"active") -> 2 | D30: =SUMIF(C3:C10,"C",D3:D10) -> 44420

Sheet UW
A1: Underwriting — EGI to NCF and capitalization (v2)
A2: Line | B2: Value | C2: Unit | D2: Formula / source
A3: gross_potential_rent | B3: =Inputs!B3 -> 1404600 | C3: USD/yr | D3: Named input — REVISED per revision-notice.pdf.
A4: economic_loss | B4: =-Inputs!B8*B3 -> -70230 | C4: USD/yr | D4: 5% × GPR.
A5: other_income | B5: =Inputs!B9*Inputs!B23 -> 2800 | C5: USD/yr | D5: $350 × total units (unchanged).
A6: uw_egi | B6: =B3+B4+B5 -> 1337170 | C6: USD/yr | D6: GPR − economic loss + other income; reimbursements already in GPR.
A8: Operating expenses (annual)
A9: uw_tax | B9: =Inputs!B12 -> 147294 | C9: USD/yr | D9: Prescribed (unchanged).
A10: uw_insurance | B10: =Inputs!B13 -> 49098 | C10: USD/yr | D10: Prescribed (unchanged).
A11: uw_other_operating_exp | B11: =Inputs!B14 -> 196392 | C11: USD/yr | D11: Prescribed other recurring (unchanged).
A12: uw_management_fee | B12: =Inputs!B10*B6 -> 40115.1 | C12: USD/yr | D12: 3% of UW EGI.
A13: uw_total_operating_exp | B13: =SUM(B9:B12) -> 432899.1 | C13: USD/yr | D13: Sum.
A15: NOI, reserves, NCF, capitalization
A16: uw_noi | B16: =B6-B13 -> 904270.9 | C16: USD/yr | D16: EGI − total opex (before reserves).
A17: replacement_reserves | B17: =Inputs!B11*Inputs!B23 -> 2400 | C17: USD/yr | D17: $300 × total units.
A18: uw_ncf | B18: =B16-B17 -> 901870.9 | C18: USD/yr | D18: NOI − reserves.
A19: cap_rate | B19: =Inputs!B4 -> 0.065 | C19: decimal | D19: Named input — REVISED to 6.5000%.
A20: capitalization_value | B20: =B16/B19 -> 13911860 | C20: USD | D20: NOI (before reserves) ÷ cap rate.

Sheet Debt
A1: Debt sizing — LTV, DSCR, Debt Yield; Sources & Uses (v2)
A2: Line | B2: Value | C2: Unit | D2: Formula / source
A3: sizing_rate | B3: =Inputs!B5 -> 0.0775 | C3: decimal | D3: REVISED to 7.75% (prior 7.00% + 75 bps). Still > note rate → floor binds.
A4: note_rate | B4: =Inputs!B19 -> 0.061 | C4: decimal | D4: Contract rate (informational, unchanged).
A5: amort_years | B5: =Inputs!B18 -> 30 | C5: years | D5: 30-yr monthly (unchanged).
A6: monthly_rate | B6: =B3/12 -> 0.0064583333 | C6: decimal | D6: Sizing rate ÷ 12.
A7: n_periods | B7: =B5*12 -> 360 | C7: months | D7: Amort years × 12.
A8: annual_debt_constant | B8: =12*(B6*(1+B6)^B7)/((1+B6)^B7-1) -> 0.085969469 | C8: decimal | D8: Annualized level-payment constant per $1 loan (~0.0859692 at 7.75%).
A9: ncf_for_sizing | B9: =UW!B18 -> 901870.9 | C9: USD/yr | D9: NCF after reserves.
A10: noi_for_sizing | B10: =UW!B16 -> 904270.9 | C10: USD/yr | D10: NOI before reserves.
A11: cap_value | B11: =UW!B20 -> 13911860 | C11: USD | D11: Capitalization value.
A12: ltv_limit | B12: =Inputs!B15 -> 0.65 | C12: decimal | D12: Max LTV (unchanged).
A13: dscr_limit | B13: =Inputs!B16 -> 1.25 | C13: ratio | D13: Min DSCR (unchanged).
A14: debt_yield_limit | B14: =Inputs!B17 -> 0.09 | C14: decimal | D14: Min NCF DY (unchanged).
A15: max_loan_ltv | B15: =B12*B11 -> 9042709 | C15: USD | D15: LTV × cap value.
A16: max_loan_dscr | B16: =B9/(B13*B8) -> 8392476.1 | C16: USD | D16: NCF ÷ (DSCR × annual constant).
A17: max_loan_debt_yield | B17: =B9/B14 -> 10020788 | C17: USD | D17: NCF ÷ DY.
A18: maximum_loan | B18: =MIN(B15,B16,B17) -> 8392476.1 | C18: USD | D18: Minimum of the three.
A19: binding_constraint | B19: =IF(B18=B15,"LTV",IF(B18=B16,"DSCR","Debt Yield")) -> DSCR | C19: text | D19: Which test is binding.
A22: Sources & Uses
A23: Sources: sized loan | B23: =B18 -> 8392476.1 | C23: USD | D23: Constrained maximum loan.
A24: Sources: sponsor equity | B24: =MAX(0,-B29) -> 0 | C24: USD | D24: Additional equity if net cash-out is negative.
A25: Uses: existing payoff | B25: =Inputs!B22 -> 7800000 | C25: USD | D25: Existing loan payoff (unchanged).
A26: Uses: closing costs | B26: =Inputs!B21 -> 45000 | C26: USD | D26: Prescribed (unchanged).
A27: Uses: origination fee | B27: =Inputs!B20*B18 -> 83924.761 | C27: USD | D27: 1% × sized loan.
A28: Uses: cash to sponsor | B28: =MAX(0,B29) -> 463551.36 | C28: USD | D28: Positive net cash-out returned to sponsor.
A29: net_cash_out | B29: =B18-Inputs!B22-Inputs!B21-Inputs!B20*B18 -> 463551.36 | C29: USD | D29: Loan − payoff − closing − origination. Negative = additional equity required.
A31: Sizing diagnostics
A32: DSCR at sized loan | B32: =B9/(B18*B8) -> 1.25
A33: LTV at sized loan | B33: =B18/B11 -> 0.60326054
A34: Debt yield at sized loan | B34: =B9/B18 -> 0.10746184

Sheet Sensitivity
A1: Two-way sensitivity — Maximum loan ($) by sizing rate × cap rate (v2)
A2: Rows: sizing rate; Columns: cap rate. Base case highlighted.
A4: Sizing rate \ Cap rate | B4: 0.06 | C4: 0.0625 | D4: 0.065 | E4: 0.0675 | F4: 0.07 | G4: 0.075 | H4: 0.08
A5: 0.065 | B5: =MIN(Inputs!$B$15*(UW!$B$16/B$4),UW!$B$18/(Inputs!$B$16*(12*(($A5/12)*(1+$A5/12)^360)/((1+$A5/12)^360-1))),UW!$B$18/Inputs!$B$17) -> 9512382.3 | C5: =MIN(Inputs!$B$15*(UW!$B$16/C$4),UW!$B$18/(Inputs!$B$16*(12*(($A5/12)*(1+$A5/12)^360)/((1+$A5/12)^360-1))),UW!$B$18/Inputs!$B$17) -> 9404417.4 | D5: =MIN(Inputs!$B$15*(UW!$B$16/D$4),UW!$B$18/(Inputs!$B$16*(12*(($A5/12)*(1+$A5/12)^360)/((1+$A5/12)^360-1))),UW!$B$18/Inputs!$B$17) -> 9042709 | E5: =MIN(Inputs!$B$15*(UW!$B$16/E$4),UW!$B$18/(Inputs!$B$16*(12*(($A5/12)*(1+$A5/12)^360)/((1+$A5/12)^360-1))),UW!$B$18/Inputs!$B$17) -> 8707793.9 | F5: =MIN(Inputs!$B$15*(UW!$B$16/F$4),UW!$B$18/(Inputs!$B$16*(12*(($A5/12)*(1+$A5/12)^360)/((1+$A5/12)^360-1))),UW!$B$18/Inputs!$B$17) -> 8396801.2 | G5: =MIN(Inputs!$B$15*(UW!$B$16/G$4),UW!$B$18/(Inputs!$B$16*(12*(($A5/12)*(1+$A5/12)^360)/((1+$A5/12)^360-1))),UW!$B$18/Inputs!$B$17) -> 7837014.5 | H5: =MIN(Inputs!$B$15*(UW!$B$16/H$4),UW!$B$18/(Inputs!$B$16*(12*(($A5/12)*(1+$A5/12)^360)/((1+$A5/12)^360-1))),UW!$B$18/Inputs!$B$17) -> 7347201.1
A6: 0.07 | B6: =MIN(Inputs!$B$15*(UW!$B$16/B$4),UW!$B$18/(Inputs!$B$16*(12*(($A6/12)*(1+$A6/12)^360)/((1+$A6/12)^360-1))),UW!$B$18/Inputs!$B$17) -> 9037201.4 | C6: =MIN(Inputs!$B$15*(UW!$B$16/C$4),UW!$B$18/(Inputs!$B$16*(12*(($A6/12)*(1+$A6/12)^360)/((1+$A6/12)^360-1))),UW!$B$18/Inputs!$B$17) -> 9037201.4 | D6: =MIN(Inputs!$B$15*(UW!$B$16/D$4),UW!$B$18/(Inputs!$B$16*(12*(($A6/12)*(1+$A6/12)^360)/((1+$A6/12)^360-1))),UW!$B$18/Inputs!$B$17) -> 9037201.4 | E6: =MIN(Inputs!$B$15*(UW!$B$16/E$4),UW!$B$18/(Inputs!$B$16*(12*(($A6/12)*(1+$A6/12)^360)/((1+$A6/12)^360-1))),UW!$B$18/Inputs!$B$17) -> 8707793.9 | F6: =MIN(Inputs!$B$15*(UW!$B$16/F$4),UW!$B$18/(Inputs!$B$16*(12*(($A6/12)*(1+$A6/12)^360)/((1+$A6/12)^360-1))),UW!$B$18/Inputs!$B$17) -> 8396801.2 | G6: =MIN(Inputs!$B$15*(UW!$B$16/G$4),UW!$B$18/(Inputs!$B$16*(12*(($A6/12)*(1+$A6/12)^360)/((1+$A6/12)^360-1))),UW!$B$18/Inputs!$B$17) -> 7837014.5 | H6: =MIN(Inputs!$B$15*(UW!$B$16/H$4),UW!$B$18/(Inputs!$B$16*(12*(($A6/12)*(1+$A6/12)^360)/((1+$A6/12)^360-1))),UW!$B$18/Inputs!$B$17) -> 7347201.1
A7: 0.075 | B7: =MIN(Inputs!$B$15*(UW!$B$16/B$4),UW!$B$18/(Inputs!$B$16*(12*(($A7/12)*(1+$A7/12)^360)/((1+$A7/12)^360-1))),UW!$B$18/Inputs!$B$17) -> 8598895.8 | C7: =MIN(Inputs!$B$15*(UW!$B$16/C$4),UW!$B$18/(Inputs!$B$16*(12*(($A7/12)*(1+$A7/12)^360)/((1+$A7/12)^360-1))),UW!$B$18/Inputs!$B$17) -> 8598895.8 | D7: =MIN(Inputs!$B$15*(UW!$B$16/D$4),UW!$B$18/(Inputs!$B$16*(12*(($A7/12)*(1+$A7/12)^360)/((1+$A7/12)^360-1))),UW!$B$18/Inputs!$B$17) -> 8598895.8 | E7: =MIN(Inputs!$B$15*(UW!$B$16/E$4),UW!$B$18/(Inputs!$B$16*(12*(($A7/12)*(1+$A7/12)^360)/((1+$A7/12)^360-1))),UW!$B$18/Inputs!$B$17) -> 8598895.8 | F7: =MIN(Inputs!$B$15*(UW!$B$16/F$4),UW!$B$18/(Inputs!$B$16*(12*(($A7/12)*(1+$A7/12)^360)/((1+$A7/12)^360-1))),UW!$B$18/Inputs!$B$17) -> 8396801.2 | G7: =MIN(Inputs!$B$15*(UW!$B$16/G$4),UW!$B$18/(Inputs!$B$16*(12*(($A7/12)*(1+$A7/12)^360)/((1+$A7/12)^360-1))),UW!$B$18/Inputs!$B$17) -> 7837014.5 | H7: =MIN(Inputs!$B$15*(UW!$B$16/H$4),UW!$B$18/(Inputs!$B$16*(12*(($A7/12)*(1+$A7/12)^360)/((1+$A7/12)^360-1))),UW!$B$18/Inputs!$B$17) -> 7347201.1
A8: 0.0775 | B8: =MIN(Inputs!$B$15*(UW!$B$16/B$4),UW!$B$18/(Inputs!$B$16*(12*(($A8/12)*(1+$A8/12)^360)/((1+$A8/12)^360-1))),UW!$B$18/Inputs!$B$17) -> 8392476.1 | C8: =MIN(Inputs!$B$15*(UW!$B$16/C$4),UW!$B$18/(Inputs!$B$16*(12*(($A8/12)*(1+$A8/12)^360)/((1+$A8/12)^360-1))),UW!$B$18/Inputs!$B$17) -> 8392476.1 | D8: =MIN(Inputs!$B$15*(UW!$B$16/D$4),UW!$B$18/(Inputs!$B$16*(12*(($A8/12)*(1+$A8/12)^360)/((1+$A8/12)^360-1))),UW!$B$18/Inputs!$B$17) -> 8392476.1 | E8: =MIN(Inputs!$B$15*(UW!$B$16/E$4),UW!$B$18/(Inputs!$B$16*(12*(($A8/12)*(1+$A8/12)^360)/((1+$A8/12)^360-1))),UW!$B$18/Inputs!$B$17) -> 8392476.1 | F8: =MIN(Inputs!$B$15*(UW!$B$16/F$4),UW!$B$18/(Inputs!$B$16*(12*(($A8/12)*(1+$A8/12)^360)/((1+$A8/12)^360-1))),UW!$B$18/Inputs!$B$17) -> 8392476.1 | G8: =MIN(Inputs!$B$15*(UW!$B$16/G$4),UW!$B$18/(Inputs!$B$16*(12*(($A8/12)*(1+$A8/12)^360)/((1+$A8/12)^360-1))),UW!$B$18/Inputs!$B$17) -> 7837014.5 | H8: =MIN(Inputs!$B$15*(UW!$B$16/H$4),UW!$B$18/(Inputs!$B$16*(12*(($A8/12)*(1+$A8/12)^360)/((1+$A8/12)^360-1))),UW!$B$18/Inputs!$B$17) -> 7347201.1
A9: 0.08 | B9: =MIN(Inputs!$B$15*(UW!$B$16/B$4),UW!$B$18/(Inputs!$B$16*(12*(($A9/12)*(1+$A9/12)^360)/((1+$A9/12)^360-1))),UW!$B$18/Inputs!$B$17) -> 8194007.8 | C9: =MIN(Inputs!$B$15*(UW!$B$16/C$4),UW!$B$18/(Inputs!$B$16*(12*(($A9/12)*(1+$A9/12)^360)/((1+$A9/12)^360-1))),UW!$B$18/Inputs!$B$17) -> 8194007.8 | D9: =MIN(Inputs!$B$15*(UW!$B$16/D$4),UW!$B$18/(Inputs!$B$16*(12*(($A9/12)*(1+$A9/12)^360)/((1+$A9/12)^360-1))),UW!$B$18/Inputs!$B$17) -> 8194007.8 | E9: =MIN(Inputs!$B$15*(UW!$B$16/E$4),UW!$B$18/(Inputs!$B$16*(12*(($A9/12)*(1+$A9/12)^360)/((1+$A9/12)^360-1))),UW!$B$18/Inputs!$B$17) -> 8194007.8 | F9: =MIN(Inputs!$B$15*(UW!$B$16/F$4),UW!$B$18/(Inputs!$B$16*(12*(($A9/12)*(1+$A9/12)^360)/((1+$A9/12)^360-1))),UW!$B$18/Inputs!$B$17) -> 8194007.8 | G9: =MIN(Inputs!$B$15*(UW!$B$16/G$4),UW!$B$18/(Inputs!$B$16*(12*(($A9/12)*(1+$A9/12)^360)/((1+$A9/12)^360-1))),UW!$B$18/Inputs!$B$17) -> 7837014.5 | H9: =MIN(Inputs!$B$15*(UW!$B$16/H$4),UW!$B$18/(Inputs!$B$16*(12*(($A9/12)*(1+$A9/12)^360)/((1+$A9/12)^360-1))),UW!$B$18/Inputs!$B$17) -> 7347201.1
A10: 0.085 | B10: =MIN(Inputs!$B$15*(UW!$B$16/B$4),UW!$B$18/(Inputs!$B$16*(12*(($A10/12)*(1+$A10/12)^360)/((1+$A10/12)^360-1))),UW!$B$18/Inputs!$B$17) -> 7819439.8 | C10: =MIN(Inputs!$B$15*(UW!$B$16/C$4),UW!$B$18/(Inputs!$B$16*(12*(($A10/12)*(1+$A10/12)^360)/((1+$A10/12)^360-1))),UW!$B$18/Inputs!$B$17) -> 7819439.8 | D10: =MIN(Inputs!$B$15*(UW!$B$16/D$4),UW!$B$18/(Inputs!$B$16*(12*(($A10/12)*(1+$A10/12)^360)/((1+$A10/12)^360-1))),UW!$B$18/Inputs!$B$17) -> 7819439.8 | E10: =MIN(Inputs!$B$15*(UW!$B$16/E$4),UW!$B$18/(Inputs!$B$16*(12*(($A10/12)*(1+$A10/12)^360)/((1+$A10/12)^360-1))),UW!$B$18/Inputs!$B$17) -> 7819439.8 | F10: =MIN(Inputs!$B$15*(UW!$B$16/F$4),UW!$B$18/(Inputs!$B$16*(12*(($A10/12)*(1+$A10/12)^360)/((1+$A10/12)^360-1))),UW!$B$18/Inputs!$B$17) -> 7819439.8 | G10: =MIN(Inputs!$B$15*(UW!$B$16/G$4),UW!$B$18/(Inputs!$B$16*(12*(($A10/12)*(1+$A10/12)^360)/((1+$A10/12)^360-1))),UW!$B$18/Inputs!$B$17) -> 7819439.8 | H10: =MIN(Inputs!$B$15*(UW!$B$16/H$4),UW!$B$18/(Inputs!$B$16*(12*(($A10/12)*(1+$A10/12)^360)/((1+$A10/12)^360-1))),UW!$B$18/Inputs!$B$17) -> 7347201.1
A11: 0.09 | B11: =MIN(Inputs!$B$15*(UW!$B$16/B$4),UW!$B$18/(Inputs!$B$16*(12*(($A11/12)*(1+$A11/12)^360)/((1+$A11/12)^360-1))),UW!$B$18/Inputs!$B$17) -> 7472413.2 | C11: =MIN(Inputs!$B$15*(UW!$B$16/C$4),UW!$B$18/(Inputs!$B$16*(12*(($A11/12)*(1+$A11/12)^360)/((1+$A11/12)^360-1))),UW!$B$18/Inputs!$B$17) -> 7472413.2 | D11: =MIN(Inputs!$B$15*(UW!$B$16/D$4),UW!$B$18/(Inputs!$B$16*(12*(($A11/12)*(1+$A11/12)^360)/((1+$A11/12)^360-1))),UW!$B$18/Inputs!$B$17) -> 7472413.2 | E11: =MIN(Inputs!$B$15*(UW!$B$16/E$4),UW!$B$18/(Inputs!$B$16*(12*(($A11/12)*(1+$A11/12)^360)/((1+$A11/12)^360-1))),UW!$B$18/Inputs!$B$17) -> 7472413.2 | F11: =MIN(Inputs!$B$15*(UW!$B$16/F$4),UW!$B$18/(Inputs!$B$16*(12*(($A11/12)*(1+$A11/12)^360)/((1+$A11/12)^360-1))),UW!$B$18/Inputs!$B$17) -> 7472413.2 | G11: =MIN(Inputs!$B$15*(UW!$B$16/G$4),UW!$B$18/(Inputs!$B$16*(12*(($A11/12)*(1+$A11/12)^360)/((1+$A11/12)^360-1))),UW!$B$18/Inputs!$B$17) -> 7472413.2 | H11: =MIN(Inputs!$B$15*(UW!$B$16/H$4),UW!$B$18/(Inputs!$B$16*(12*(($A11/12)*(1+$A11/12)^360)/((1+$A11/12)^360-1))),UW!$B$18/Inputs!$B$17) -> 7347201.1

Sheet HistoricalVsUW
A1: Historical T12 vs. Underwritten (v2) — with definitions
A2: Line | B2: Historical T12 | C2: Underwritten | D2: Delta | E2: Definition / note
A3: Rental & ancillary collections (T12) | B3: 1262520 | C3: =UW!B6 -> 1337170 | D3: =C3-B3 -> 74650 | E3: Historical is cash collections (incl. reimbursements). UW is EGI on revised roll.
A4: Real estate tax expense | B4: 147294 | C4: =UW!B9 -> 147294 | D4: =C4-B4 -> 0 | E4: Prescribed = historical.
A5: Insurance expense | B5: 49098 | C5: =UW!B10 -> 49098 | D5: =C5-B5 -> 0 | E5: Prescribed = historical.
A6: Other recurring operating expenses | B6: 196392 | C6: =UW!B11 -> 196392 | D6: =C6-B6 -> 0 | E6: Prescribed = historical.
A7: Management fee | B7: 0 | C7: =UW!B12 -> 40115.1 | D7: =C7-B7 -> 40115.1 | E7: None booked historically; UW = 3% × EGI.
A8: Reported / underwritten NOI (pre-reserve) | B8: 869736 | C8: =UW!B16 -> 904270.9 | D8: =C8-B8 -> 34534.9 | E8: Different definitions — historical is cash; UW is scheduled per revised roll.
A9: Replacement reserves | B9: 0 | C9: =UW!B17 -> 2400 | D9: =C9-B9 -> 2400 | E9: Not booked historically; UW = $300/unit.
A10: Net Cash Flow (NCF) after reserves | B10: unknown (not reported historically) | C10: =UW!B18 -> 901870.9 | D10: n/a | E10: Historical NCF is not reported in the operating statement.

Sheet Reported
A1: Reported fields — v1 vs. v2 with evidence
A2: Field id | B2: v1 value | C2: v2 value | D2: Unit | E2: Evidence filename | F2: Page/cell | G2: Change note
A3: total_units | B3: 8 | C3: =RentRoll!B14 -> 8 | D3: count | E3: rent-roll-revised.xlsx | F3: Rent Roll!A5:A12 | G3: Unchanged.
A4: occupied_units | B4: 7 | C4: =RentRoll!B15 -> 7 | D4: count | E4: rent-roll-revised.xlsx | F4: Rent Roll!D5:D12 | G4: Unchanged — 008 still vacant.
A5: pending_units | B5: 0 | C5: =RentRoll!B16 -> 0 | D5: count | E5: rent-roll-revised.xlsx | F5: Rent Roll!D5:D12 | G5: Unchanged — no pending on revised roll.
A6: total_area_sf | B6: 176060 | C6: =RentRoll!B18 -> 176060 | D6: SF | E6: rent-roll-revised.xlsx | F6: Rent Roll!C5:C12 | G6: Unchanged.
A7: occupied_area_sf | B7: 154060 | C7: =RentRoll!B19 -> 154060 | D7: SF | E7: rent-roll-revised.xlsx | F7: Rent Roll!C5:C12,D5:D12 | G7: Unchanged.
A8: unit_occupancy | B8: 0.875 | C8: =RentRoll!B20 -> 0.875 | D8: decimal | E8: rent-roll-revised.xlsx | F8: Rent Roll!A5:A12,D5:D12 | G8: Unchanged.
A9: area_occupancy | B9: 0.875 | C9: =RentRoll!B21 -> 0.8750426 | D9: decimal | E9: rent-roll-revised.xlsx | F9: Rent Roll!C5:C12,D5:D12 | G9: Unchanged.
A10: annual_in_place_rent | B10: 1227600 | C10: =RentRoll!B23 -> 1230300 | D10: USD/yr | E10: rent-roll-revised.xlsx | F10: Rent Roll!E5:E12,D5:D12 | G10: Increased by $2,700/yr — Suite 002 +$225/mo.
A11: unit_001_monthly_rent | B11: 14450 | C11: =RentRoll!B22 -> 14450 | D11: USD/mo | E11: rent-roll-revised.xlsx; lease-001.pdf | F11: Rent Roll!E5; lease p.1 | G11: Unchanged — Suite 001 amendment still applies.
A12: gross_potential_rent | B12: 1401900 | C12: =UW!B3 -> 1404600 | D12: USD/yr | E12: underwriting-instructions.pdf; rent-roll-revised.xlsx | F12: instr. p.1 ¶2; roll E5:E12 | G12: Increased by $2,700/yr (Suite 002 +$225 × 12).
A13: uw_egi | B13: 1334605 | C13: =UW!B6 -> 1337170 | D13: USD/yr | E13: underwriting-instructions.pdf | F13: p.1 ¶2 | G13: Follows revised GPR (Δ +$2,565 after 5% loss).
A14: uw_tax | B14: 147294 | C14: =UW!B9 -> 147294 | D14: USD/yr | E14: underwriting-instructions.pdf | F14: p.1 ¶3 | G14: Unchanged.
A15: uw_insurance | B15: 49098 | C15: =UW!B10 -> 49098 | D15: USD/yr | E15: underwriting-instructions.pdf | F15: p.1 ¶3 | G15: Unchanged.
A16: uw_operating_expenses | B16: 432822.15 | C16: =UW!B13 -> 432899.1 | D16: USD/yr | E16: underwriting-instructions.pdf | F16: p.1 ¶3 | G16: Δ mgmt fee only (+$76.95 on higher EGI).
A17: uw_noi | B17: 901782.85 | C17: =UW!B16 -> 904270.9 | D17: USD/yr | E17: underwriting-instructions.pdf | F17: p.1 ¶3 | G17: Increased by $2,488.05.
A18: uw_ncf | B18: 899382.85 | C18: =UW!B18 -> 901870.9 | D18: USD/yr | E18: underwriting-instructions.pdf | F18: p.1 ¶3 | G18: Increased by $2,488.05.
A19: sizing_rate | B19: 0.07 | C19: =Inputs!B5 -> 0.0775 | D19: decimal | E19: revision-notice.pdf | F19: p.1 ¶2 | G19: +75 bps → 7.75%. Floor still binding vs 6.10% note rate.
A20: cap_rate | B20: 0.0625 | C20: =Inputs!B4 -> 0.065 | D20: decimal | E20: revision-notice.pdf | F20: p.1 ¶2 | G20: +25 bps → 6.5000%.
A21: capitalization_value | B21: 14428526 | C21: =UW!B20 -> 13911860 | D21: USD | E21: computed | F21: UW!B20 | G21: Fell to ~$13.91M — higher cap rate outweighs higher NOI.
A22: ltv_limit | B22: 0.65 | C22: =Inputs!B15 -> 0.65 | D22: decimal | E22: underwriting-instructions.pdf | F22: p.1 ¶4 | G22: Unchanged.
A23: dscr_limit | B23: 1.25 | C23: =Inputs!B16 -> 1.25 | D23: ratio | E23: underwriting-instructions.pdf | F23: p.1 ¶4 | G23: Unchanged.
A24: debt_yield_limit | B24: 0.09 | C24: =Inputs!B17 -> 0.09 | D24: decimal | E24: underwriting-instructions.pdf | F24: p.1 ¶4 | G24: Unchanged.
A25: maximum_loan | B25: 9012269.9 | C25: =Debt!B18 -> 8392476.1 | D25: USD | E25: computed | F25: Debt!B18 | G25: Fell — higher sizing rate raises debt constant → DSCR cap tighter. Still DSCR-binding.
A26: net_cash_out | B26: 1077147.2 | C26: =Debt!B29 -> 463551.36 | D26: USD | E26: computed | F26: Debt!B29 | G26: Reduced but still positive → no shortfall.
A27: insurance_policy_limit | B27: 2000000 | C27: 2000000 | D27: USD | E27: insurance.pdf | F27: p.1 ¶1 | G27: Unchanged.
A28: selected_roll_date | B28: 2026-08-31 | C28: 2026-09-01 | D28: date | E28: rent-roll-revised.xlsx | F28: Rent Roll!B2 | G28: Revised roll effective 2026-09-01.
A29: reported_t12_noi | B29: 869736 | C29: 869736 | D29: USD/yr | E29: operating-statement.pdf | F29: p.1 table | G29: Unchanged — historical T12 not restated.
A30: type_a_units | B30: 3 | C30: =RentRoll!B28 -> 3 | D30: count | E30: rent-roll-revised.xlsx; manager-cover.pdf | F30: Rent Roll!B5:B12; cover p.1 | G30: Unchanged.
A31: type_a_occupied | B31: 3 | C31: =RentRoll!C28 -> 3 | D31: count | E31: rent-roll-revised.xlsx | F31: Rent Roll!D5:D12 | G31: Unchanged.
A32: type_b_units | B32: 3 | C32: =RentRoll!B29 -> 3 | D32: count | E32: rent-roll-revised.xlsx; manager-cover.pdf | F32: Rent Roll!B5:B12; cover p.1 | G32: Unchanged.
A33: type_b_occupied | B33: 2 | C33: =RentRoll!C29 -> 2 | D33: count | E33: rent-roll-revised.xlsx | F33: Rent Roll!D5:D12 | G33: Unchanged.
A34: type_c_units | B34: 2 | C34: =RentRoll!B30 -> 2 | D34: count | E34: rent-roll-revised.xlsx; manager-cover.pdf | F34: Rent Roll!B5:B12; cover p.1 | G34: Unchanged.
A35: type_c_occupied | B35: 2 | C35: =RentRoll!C30 -> 2 | D35: count | E35: rent-roll-revised.xlsx | F35: Rent Roll!D5:D12 | G35: Unchanged.
A36: risk_pending_in_occupancy | B36: present | C36: present | D36: flag | E36: manager-cover.pdf; rent-roll-revised.xlsx | F36: cover p.1; Rent Roll!D5:D12 | G36: Same manager headline conflict persists.
A37: risk_near_term_rollover | B37: absent | C37: absent | D37: flag | E37: rent-roll-revised.xlsx | F37: Rent Roll!F5:F12 | G37: All expirations 2029-08-31, still > 12 months.
A38: risk_missing_insurance | B38: absent | C38: absent | D38: flag | E38: insurance.pdf | F38: p.1 | G38: Policy declaration still present.
A39: risk_capital_in_opex | B39: absent | C39: absent | D39: flag | E39: operating-statement.pdf | F39: p.1 table | G39: Historical ledger unchanged.
A40: risk_unsigned_rent_change | B40: absent | C40: absent | D40: flag | E40: lease-correspondence.pdf; revision-notice.pdf | F40: corr. p.1; notice p.1 | G40: Suite 002 change delivered via revised certified roll (an executed manager document); no unsigned proposal in packet.
...

Sheet SourceRegister
A1: Source register (v2) — every fact cited
A2: Filename | B2: Page/cell | C2: Field(s) cited | D2: Note
A3: revision-notice.pdf | B3: p.1 | C3: sizing_rate, cap_rate, GPR, selected_roll_date | D3: 2026-09-01 revision. +75 bps sizing, +25 bps cap, use revised roll. Preserve approved copy.
A4: rent-roll-revised.xlsx | B4: Rent Roll!B2 | C4: selected_roll_date | D4: Controlling revised roll effective 2026-09-01. Supersedes 2026-08-31 certified.
A5: rent-roll-revised.xlsx | B5: Rent Roll!A5:G12 | C5: unit mix, occupancy, in-place rent, Suite 002 rent | D5: Suite 002 = $14,825/mo (prior $14,600, +$225). All other lines unchanged.
A6: rent-roll-certified.xlsx | B6: Rent Roll!B2 | C6: (prior version) | D6: 2026-08-31 certified — preserved in v1 audit archive.
A7: rent-roll-archive.xlsx | B7: Rent Roll!B2 | C7: (archive) | D7: 2026-06-30 stale — not used.
A8: lease-001.pdf | B8: p.1 | C8: unit_001_monthly_rent | D8: Executed amendment: $14,450/mo continues to apply (revision notice reaffirms).
A9: lease-correspondence.pdf | B9: p.1 | C9: risk_unsigned_rent_change | D9: PM confirms no unsigned amendments/concessions.
A10: insurance.pdf | B10: p.1 | C10: insurance_policy_limit, risk_missing_insurance | D10: GL aggregate $2,000,000; expense $49,098 separate. Unchanged.
A11: operating-statement.pdf | B11: p.1 table | C11: reported_t12_noi, risk_capital_in_opex | D11: T12 through 2026-08-31 unchanged; roof capitalized.
A12: manager-cover.pdf | B12: p.1 | C12: group mapping, risk_pending_in_occupancy, approved copy | D12: A/B/C = Small/Standard/Large; approved copy preserved verbatim.
A13: underwriting-instructions.pdf | B13: p.1 | C13: opex, mgmt %, reserves, LTV/DSCR/DY, note rate, payoff, closing | D13: All base rules unchanged by revision.
A14: diligence-status.pdf | B14: p.1 | C14: (qualifications) | D14: Legal/enviro/PCA/title routine pending; no findings of defect asserted.
