Workbook

Sheet Rent Roll
A1: Beacon Plaza - Certified Rent Roll as of 2026-08-31 (source: rent-roll-certified.xlsx)
A3: Suite | B3: Unit type | C3: Group | D3: Area SF | E3: Possession | F3: Monthly rent | G3: Expiration | H3: Occupied? | I3: Occ. area SF | J3: Annual in-place
A4: 001 | B4: Small suite | C4: A | D4: 5380 | E4: active | F4: 11050 | G4: 2027-02-28 | H4: =IF(E4="active",1,0) | I4: =H4*D4 | J4: =H4*F4*12
A5: 002 | B5: Standard suite | C5: B | D5: 5500 | E5: active | F5: 11200 | G5: 2029-08-31 | H5: =IF(E5="active",1,0) | I5: =H5*D5 | J5: =H5*F5*12
A6: 003 | B6: Large suite | C6: C | D6: 5710 | E6: active | F6: 11475 | G6: 2029-08-31 | H6: =IF(E6="active",1,0) | I6: =H6*D6 | J6: =H6*F6*12
A7: 004 | B7: Small suite | C7: A | D7: 5380 | E7: active | F7: 11050 | G7: 2029-08-31 | H7: =IF(E7="active",1,0) | I7: =H7*D7 | J7: =H7*F7*12
A8: 005 | B8: Standard suite | C8: B | D8: 5500 | E8: active | F8: 11200 | G8: 2029-08-31 | H8: =IF(E8="active",1,0) | I8: =H8*D8 | J8: =H8*F8*12
A9: 006 | B9: Large suite | C9: C | D9: 5710 | E9: active | F9: 11475 | G9: 2029-08-31 | H9: =IF(E9="active",1,0) | I9: =H9*D9 | J9: =H9*F9*12
A10: 007 | B10: Small suite | C10: A | D10: 5380 | E10: active | F10: 11050 | G10: 2029-08-31 | H10: =IF(E10="active",1,0) | I10: =H10*D10 | J10: =H10*F10*12
A11: 008 | B11: Standard suite | C11: B | D11: 5500 | E11: active | F11: 11200 | G11: 2029-08-31 | H11: =IF(E11="active",1,0) | I11: =H11*D11 | J11: =H11*F11*12
A12: 009 | B12: Large suite | C12: C | D12: 5710 | E12: active | F12: 11475 | G12: 2029-08-31 | H12: =IF(E12="active",1,0) | I12: =H12*D12 | J12: =H12*F12*12
A13: 010 | B13: Small suite | C13: A | D13: 5380 | E13: pending | F13: 11050 | G13: 2029-08-31 | H13: =IF(E13="active",1,0) | I13: =H13*D13 | J13: =H13*F13*12
A14: 011 | B14: Standard suite | C14: B | D14: 5500 | E14: vacant | F14: 11200 | G14: 2029-08-31 | H14: =IF(E14="active",1,0) | I14: =H14*D14 | J14: =H14*F14*12
A15: 012 | B15: Large suite | C15: C | D15: 5710 | E15: vacant | F15: 11475 | G15: 2029-08-31 | H15: =IF(E15="active",1,0) | I15: =H15*D15 | J15: =H15*F15*12
A16: Totals | D16: =SUM(D4:D15) | F16: =SUM(F4:F15) | H16: =SUM(H4:H15) | I16: =SUM(I4:I15) | J16: =SUM(J4:J15)
A18: Roll statistics
A19: Total units / suites | B19: =COUNTA(A4:A15)
A20: Occupied units (active possession) | B20: =COUNTIF(E4:E15,"active")
A21: Pending units (not in possession) | B21: =COUNTIF(E4:E15,"pending")
A22: Vacant units | B22: =COUNTIF(E4:E15,"vacant")
A23: Total area SF | B23: =D16
A24: Occupied area SF | B24: =I16
A25: Unit occupancy (decimal) | B25: =B20/B19
A26: Area occupancy (decimal) | B26: =B24/B23
A27: Annual in-place rent (active suites x 12) | B27: =J16
A28: All-suite scheduled monthly rent | B28: =F16
A29: All-suite scheduled annual rent (GPR basis) | B29: =F16*12
A30: Suite 001 monthly rent (lease-001.pdf p.1 agrees) | B30: =F4
A32: Group mix (manager mapping: A=Small, B=Standard, C=Large)
A33: Group | B33: Units | C33: Occupied | D33: Area SF
A34: A | B34: =COUNTIF($C$4:$C$15,"A") | C34: =SUMIF($C$4:$C$15,"A",$H$4:$H$15) | D34: =SUMIF($C$4:$C$15,"A",$D$4:$D$15)
A35: B | B35: =COUNTIF($C$4:$C$15,"B") | C35: =SUMIF($C$4:$C$15,"B",$H$4:$H$15) | D35: =SUMIF($C$4:$C$15,"B",$D$4:$D$15)
A36: C | B36: =COUNTIF($C$4:$C$15,"C") | C36: =SUMIF($C$4:$C$15,"C",$H$4:$H$15) | D36: =SUMIF($C$4:$C$15,"C",$D$4:$D$15)
A38: Near-term rollover: Suite 001 expires 2027-02-28, within 12 months of 2026-08-31. All other active expiries 2029-08-31.

Sheet UW
A1: Beacon Plaza - Underwriting, Valuation and Debt Sizing
A3: Inputs | B3: Value | C3: Source
A4: Gross potential rent (annual, all suites) | B4: 1537860 | C4: rent-roll-certified.xlsx E5:E16 x 12; underwriting-instructions.pdf p.1
A5: Other income (annual, $350 x 12 suites) | B5: 4200 | C5: underwriting-instructions.pdf p.1
A6: Economic loss (decimal) | B6: 0.05 | C6: underwriting-instructions.pdf p.1
A7: Capitalization rate (decimal) | B7: 0.075 | C7: underwriting-instructions.pdf p.1
A8: Sizing rate (greater of note rate and floor) | B8: 0.0675 | C8: MAX(note 6.75%, floor 6.00%); underwriting-instructions.pdf p.1
A9: Note rate | B9: 0.0675 | C9: underwriting-instructions.pdf p.1
A10: Underwriting rate floor | B10: 0.06 | C10: underwriting-instructions.pdf p.1
A11: Amortization (years) | B11: 30 | C11: underwriting-instructions.pdf p.1
A12: Maximum LTV | B12: 0.6 | C12: underwriting-instructions.pdf p.1
A13: Minimum DSCR | B13: 1.25 | C13: underwriting-instructions.pdf p.1
A14: Minimum NCF debt yield | B14: 0.09 | C14: underwriting-instructions.pdf p.1
A15: Unit / suite count | B15: ='Rent Roll'!B19 | C15: rent-roll-certified.xlsx A5:A16
A16: Real estate taxes | B16: 169974 | C16: underwriting-instructions.pdf p.1; operating-statement.pdf p.1
A17: Insurance expense | B17: 56658 | C17: underwriting-instructions.pdf p.1; operating-statement.pdf p.1
A18: Other recurring operating expenses | B18: 226632 | C18: underwriting-instructions.pdf p.1
A19: Management fee (% of EGI) | B19: 0.03 | C19: underwriting-instructions.pdf p.1
A20: Replacement reserve per suite | B20: 300 | C20: underwriting-instructions.pdf p.1
A21: Origination fee (% of loan) | B21: 0.01 | C21: underwriting-instructions.pdf p.1
A22: Third-party closing costs | B22: 45000 | C22: underwriting-instructions.pdf p.1
A23: Existing loan payoff | B23: 6500000 | C23: underwriting-instructions.pdf p.1
A25: Underwritten cash flow
A26: Gross potential rent | B26: =B4
A27: Less economic loss (5%) | B27: =B4*B6
A28: Other income | B28: =B5
A29: Effective gross income (uw_egi) | B29: =B26-B27+B28
A30: Real estate taxes (uw_tax) | B30: =B16
A31: Insurance (uw_insurance) | B31: =B17
A32: Other recurring expenses | B32: =B18
A33: Management fee | B33: =B29*B19
A34: Total operating expenses (uw_operating_expenses) | B34: =SUM(B30:B33)
A35: NOI before reserves (uw_noi) | B35: =B29-B34
A36: Replacement reserves | B36: =B15*B20
A37: Net cash flow after reserves (uw_ncf) | B37: =B35-B36
A38: Expense ratio (opex / EGI) | B38: =B34/B29
A40: Valuation and debt sizing
A41: Capitalized value (NOI before reserves / cap rate) | B41: =B35/B7
A42: LTV constraint loan | B42: =B41*B12
A43: Maximum annual debt service at min DSCR | B43: =B37/B13
...

Sheet Historical
A1: Historical T12 vs Underwritten (definitions differ)
A3: Line | B3: T12 actual 2025-09-01 to 2026-08-31 | C3: Underwritten | D3: Note
A4: Rental and ancillary collections / EGI | B4: 1456920 | C4: =UW!B29 | D4: Collections are actual cash, not an annualized roll
A5: Real estate taxes | B5: 169974 | C5: =UW!B30
A6: Insurance | B6: 56658 | C6: =UW!B31
A7: Other recurring operating expenses | B7: 226632 | C7: =UW!B32
A8: Roof replacement booked in repairs | B8: 0 | C8: 0 | D8: Capital item reported as $0 in repairs; no reclass required
A9: Management fee | C9: =UW!B33 | D9: Not separately reported in T12 (unknown)
A10: Total operating expenses | B10: =SUM(B5:B8) | C10: =UW!B34
A11: NOI before reserves | B11: =B4-B10 | C11: =UW!B35
A12: Reported NOI per statement | B12: 1003656 | D12: operating-statement.pdf p.1; ties to computed T12 NOI
A13: Replacement reserves | C13: =UW!B36
A14: Net cash flow after reserves | C14: =UW!B37
A16: Blank cells are not reported in the source and remain unknown (distinct from zero).

Sheet Sensitivity
A1: Maximum loan sensitivity - cap rate (columns) vs sizing rate (rows)
A2: Sizing rate \ Cap rate | B2: 0.07 | C2: 0.075 | D2: 0.08 | E2: 0.085
A3: 0.06 | B3: =MIN(UW!$B$35/B$2*UW!$B$12,UW!$B$37/UW!$B$14,(UW!$B$37/UW!$B$13/12)*(1-(1+$A3/12)^(-UW!$B$11*12))/($A3/12)) | C3: =MIN(UW!$B$35/C$2*UW!$B$12,UW!$B$37/UW!$B$14,(UW!$B$37/UW!$B$13/12)*(1-(1+$A3/12)^(-UW!$B$11*12))/($A3/12)) | D3: =MIN(UW!$B$35/D$2*UW!$B$12,UW!$B$37/UW!$B$14,(UW!$B$37/UW!$B$13/12)*(1-(1+$A3/12)^(-UW!$B$11*12))/($A3/12)) | E3: =MIN(UW!$B$35/E$2*UW!$B$12,UW!$B$37/UW!$B$14,(UW!$B$37/UW!$B$13/12)*(1-(1+$A3/12)^(-UW!$B$11*12))/($A3/12))
A4: 0.0675 | B4: =MIN(UW!$B$35/B$2*UW!$B$12,UW!$B$37/UW!$B$14,(UW!$B$37/UW!$B$13/12)*(1-(1+$A4/12)^(-UW!$B$11*12))/($A4/12)) | C4: =MIN(UW!$B$35/C$2*UW!$B$12,UW!$B$37/UW!$B$14,(UW!$B$37/UW!$B$13/12)*(1-(1+$A4/12)^(-UW!$B$11*12))/($A4/12)) | D4: =MIN(UW!$B$35/D$2*UW!$B$12,UW!$B$37/UW!$B$14,(UW!$B$37/UW!$B$13/12)*(1-(1+$A4/12)^(-UW!$B$11*12))/($A4/12)) | E4: =MIN(UW!$B$35/E$2*UW!$B$12,UW!$B$37/UW!$B$14,(UW!$B$37/UW!$B$13/12)*(1-(1+$A4/12)^(-UW!$B$11*12))/($A4/12))
A5: 0.075 | B5: =MIN(UW!$B$35/B$2*UW!$B$12,UW!$B$37/UW!$B$14,(UW!$B$37/UW!$B$13/12)*(1-(1+$A5/12)^(-UW!$B$11*12))/($A5/12)) | C5: =MIN(UW!$B$35/C$2*UW!$B$12,UW!$B$37/UW!$B$14,(UW!$B$37/UW!$B$13/12)*(1-(1+$A5/12)^(-UW!$B$11*12))/($A5/12)) | D5: =MIN(UW!$B$35/D$2*UW!$B$12,UW!$B$37/UW!$B$14,(UW!$B$37/UW!$B$13/12)*(1-(1+$A5/12)^(-UW!$B$11*12))/($A5/12)) | E5: =MIN(UW!$B$35/E$2*UW!$B$12,UW!$B$37/UW!$B$14,(UW!$B$37/UW!$B$13/12)*(1-(1+$A5/12)^(-UW!$B$11*12))/($A5/12))
A6: 0.085 | B6: =MIN(UW!$B$35/B$2*UW!$B$12,UW!$B$37/UW!$B$14,(UW!$B$37/UW!$B$13/12)*(1-(1+$A6/12)^(-UW!$B$11*12))/($A6/12)) | C6: =MIN(UW!$B$35/C$2*UW!$B$12,UW!$B$37/UW!$B$14,(UW!$B$37/UW!$B$13/12)*(1-(1+$A6/12)^(-UW!$B$11*12))/($A6/12)) | D6: =MIN(UW!$B$35/D$2*UW!$B$12,UW!$B$37/UW!$B$14,(UW!$B$37/UW!$B$13/12)*(1-(1+$A6/12)^(-UW!$B$11*12))/($A6/12)) | E6: =MIN(UW!$B$35/E$2*UW!$B$12,UW!$B$37/UW!$B$14,(UW!$B$37/UW!$B$13/12)*(1-(1+$A6/12)^(-UW!$B$11*12))/($A6/12))
A8: Each cell is the minimum of the LTV, DSCR and debt-yield constrained loan amounts using underwritten NOI/NCF from the UW sheet.

Sheet Source Register
A1: Source register
A2: Document | B2: Location | C2: Fact used / status
A3: rent-roll-certified.xlsx | B3: Rent Roll A2:G16 | C3: Controlling roll dated 2026-08-31: 12 suites, 66,360 SF, statuses, rents, expirations
A4: rent-roll-archive.xlsx | B4: Rent Roll A2:G16 | C4: Stale 2026-06-30 archive with lower rents; superseded, not used
A5: lease-001.pdf | B5: p.1 | C5: Suite 001 executed lease: $11,050/mo, expiry 2027-02-28, 5,380 SF, no free rent
A6: lease-correspondence.pdf | B6: p.1 | C6: Manager confirmation 2026-08-31: no amendments or concessions affect Suite 001
A7: operating-statement.pdf | B7: p.1 | C7: T12 collections 1,456,920; tax/insurance/other expenses; reported NOI 1,003,656; roof capital $0 in repairs
A8: insurance.pdf | B8: p.1 | C8: GL aggregate limit $2,000,000; 2026-07-01 to 2027-06-30; distinct from expense
A9: underwriting-instructions.pdf | B9: p.1 | C9: All underwriting, capitalization, sizing and sources/uses assumptions
A10: manager-cover.pdf | B10: p.1 | C10: Manager headline 10 of 12 leased (includes pending); A/B/C group mapping; certified detail controls
A11: diligence-status.pdf | B11: p.1 | C11: Legal, environmental, PCA and title reviews incomplete; no defect findings
A12: Not supplied | B12: n/a | C12: Photos, asking price, market sales/rent comps, sponsor history, tenant financials, monthly T12 detail: unknown
