Workbook
Name CapRate: Assumptions!$C$7
Name ContractRate: Assumptions!$C$8
Name SizingFloor: Assumptions!$C$9
Name SizingRate: Assumptions!$C$10
Name AmortYears: Assumptions!$C$11
Name IOMonths: Assumptions!$C$12
Name Maturity: Assumptions!$C$13
Name LTVmax: Assumptions!$C$14
Name DSCRmin: Assumptions!$C$15
Name DYmin: Assumptions!$C$16
Name OrigFeePct: Assumptions!$C$17
Name ExistingPayoff: Assumptions!$C$18
Name FixedCosts: Assumptions!$C$19
Name ResPerUnit: Assumptions!$C$20
Name UW_GPR: Assumptions!$C$21
Name RevLossPct: Assumptions!$C$22
Name OtherInc: Assumptions!$C$23
Name MgmtPct: Assumptions!$C$24
Name MgmtDollarFloor: Assumptions!$C$25
Name TotalUnits: Assumptions!$C$26
Name UW_EGI: Underwriting!$D$10
Name UW_OpEx: Underwriting!$D$20
Name UW_MgmtFee: Underwriting!$D$19
Name UW_NOI: Underwriting!$D$22
Name UW_Reserves: Underwriting!$D$23
Name UW_NCF: Underwriting!$D$24
Name CapValue: Underwriting!$H$20
Name T12_EGI: Underwriting!$C$10
Name T12_OpEx: Underwriting!$C$20
Name T12_NOI: Underwriting!$C$22
Name T12_NCF: Underwriting!$C$24
Name ADC: 'Loan Sizing'!$C$11
Name MaxLoan: 'Loan Sizing'!$C$17

Sheet README
A1: Cedar Landing — Refinance Underwriting Workbook
A2: As-of: 2026-08-31 | Fictional scenario — internal analyst workbook
A4: How to use
A5: 1) All editable assumptions are on the 'Assumptions' sheet, shaded YELLOW. Change any yellow cell and every other sheet recalculates.
A6: 2) The 'Underwriting' sheet computes T12 historical, underwritten scenario, and capitalization value.
A7: 3) The 'Loan Sizing' sheet solves LTV / DSCR / Debt Yield constraints, picks the binding minimum, and returns Sources & Uses and cash to borrower.
A8: 4) The 'Sensitivity' sheet runs (a) EGI −5% + sizing rate +100 bps combined downside (cap rate unchanged) and (b) cap rate +50 bps standalone.
A9: 5) The 'Rent Roll' sheet holds the unit-level detail supporting the in-place monthly base.
A10: 6) Yellow = editable input · Green = calculated output · Orange = binding constraint highlight.
A11: 7) Every sizing formula uses named ranges (see Formulas tab in Excel > Name Manager) so the intent is auditable.
A13: Input & Output Map
A14: Sheet | B14: Cell / Range | C14: Item | D14: Type
A15: Assumptions | B15: C7 | C15: Cap rate | D15: INPUT
A16: Assumptions | B16: C8 | C16: Contract rate | D16: INPUT
A17: Assumptions | B17: C9 | C17: Sizing rate floor | D17: INPUT
A18: Assumptions | B18: C10 | C18: Sizing rate (effective) | D18: OUTPUT
A19: Assumptions | B19: C11 | C19: Amortization (years) | D19: INPUT
A20: Assumptions | B20: C12 | C20: IO months | D20: INPUT
A21: Assumptions | B21: C13 | C21: Maturity (months) | D21: INPUT
A22: Assumptions | B22: C14 | C22: LTV max | D22: INPUT
A23: Assumptions | B23: C15 | C23: DSCR min | D23: INPUT
A24: Assumptions | B24: C16 | C24: Debt yield min | D24: INPUT
A25: Assumptions | B25: C17 | C25: Origination fee % | D25: INPUT
... A47: Sensitivity | B47: G22 | C47: Cap+50 bps max loan | D47: OUTPUT

Sheet Assumptions
A1: Editable Assumptions — change any yellow cell
B3: All assumptions from lender term sheet, property plan, and T12 packet.
B5: Item | C5: Value | E5: Source / note
B7: Cap rate | C7: 0.0575 | E7: Lender-Terms.pdf p.1 — valuation cap
B8: Contract rate | C8: 0.0625 | E8: Lender-Terms.pdf p.1 — fixed contract rate
B9: Sizing rate floor | C9: 0.065 | E9: Lender-Terms.pdf p.1 — underwriting floor
B10: Sizing rate (effective) | C10: =MAX(C8,C9) | E10: =greater of contract rate and sizing floor
B11: Amortization (years) | C11: 30 | E11: Lender-Terms.pdf p.1
B12: IO months | C12: 36 | E12: Lender-Terms.pdf p.1
B13: Maturity (months) | C13: 60 | E13: Lender-Terms.pdf p.1
B14: LTV max | C14: 0.6 | E14: Lender-Terms.pdf p.1
B15: DSCR min | C15: 1.3 | E15: Lender-Terms.pdf p.1 — NCF / amortizing DS at sizing rate
B16: Debt yield min | C16: 0.09 | E16: Lender-Terms.pdf p.1 — NCF / max loan
B17: Origination fee (% of loan) | C17: 0.01 | E17: Lender-Terms.pdf p.1
B18: Existing debt payoff | C18: 4500000 | E18: Property-and-Plan.pdf p.1
B19: Fixed closing costs | C19: 65000 | E19: Property-and-Plan.pdf p.1
B20: Replacement reserves ($/unit/yr) | C20: 325 | E20: Property-and-Plan.pdf p.2
B21: Underwritten GPR | C21: 1056000 | E21: Property-and-Plan.pdf p.2 — scenario
B22: Revenue loss % of GPR | C22: 0.07 | E22: Property-and-Plan.pdf p.2 — vacancy+conc+bad debt
... B26: Total units | C26: 48 | E26: Rent-Roll.xlsx

Sheet Underwriting
A1: Historical T12 vs Underwritten Scenario
B3: T12 = Sep-2025 to Aug-2026 (T12-Statement.pdf). UW = scenario per Property-and-Plan.pdf p.2.
B5: Line | C5: T12 Actual | D5: UW Scenario | E5: Delta | G5: Summary Output | H5: Value
B6: REVENUE
B7: Gross potential base rent | C7: 1036800 | D7: =UW_GPR | E7: =D7-C7 | G7: Historical T12 EGI | H7: =C10
B8: Vacancy / concessions / bad debt | C8: -375600 | D8: =-UW_GPR*RevLossPct | E8: =D8-C8 | G8: Historical T12 OpEx | H8: =C20
B9: Other income / recoveries | C9: 30000 | D9: =OtherInc | E9: =D9-C9 | G9: Historical NOI before res. | H9: =C22
B10: Effective Gross Income (EGI) | C10: =C7+C8+C9 | D10: =D7+D8+D9 | E10: =D10-C10 | G10: Historical NCF (after res.) | H10: =C24
B12: OPERATING EXPENSES | G12: Underwritten EGI | H12: =D10
B13: Real estate taxes | C13: 132000 | D13: 138000 | E13: =D13-C13 | G13: Underwritten Mgmt fee | H13: =D19
B14: Property insurance | C14: 40800 | D14: 45600 | E14: =D14-C14 | G14: Underwritten OpEx (pre-res.) | H14: =D20
B15: Utilities | C15: 33600 | D15: 33600 | E15: =D15-C15 | G15: Underwritten NOI (pre-res.) | H15: =D22
B16: Repairs & maintenance | C16: 54000 | D16: 42000 | E16: =D16-C16 | G16: Underwritten Reserves | H16: =D23
B17: Payroll / contract labor | C17: 55200 | D17: 55200 | E17: =D17-C17 | G17: Underwritten NCF (post-res.) | H17: =D24
B18: Administrative / legal | C18: 27600 | D18: 27600 | E18: =D18-C18
B19: Management fee (greater of T12 or 3.50% EGI) | C19: 28000 | D19: =MAX(MgmtDollarFloor,D10*MgmtPct) | E19: =D19-C19 | G19: Cap rate | H19: =CapRate
B20: Total operating expenses | C20: =SUM(C13:C19) | D20: =SUM(D13:D19) | E20: =D20-C20 | G20: Capitalization value | H20: =D22/CapRate
B22: NOI before reserves | C22: =C10-C20 | D22: =D10-D20 | E22: =D22-C22
B23: Replacement reserves | C23: 14400 | D23: =TotalUnits*ResPerUnit | E23: =D23-C23
B24: Net Cash Flow (after reserves) | C24: =C22-C23 | D24: =D22-D23 | E24: =D24-C24
G32: Underwritten NOI before reserves | H32: =UW_NOI
G34: Underwritten NCF | H34: =UW_NCF
G37: Capitalization value | H37: =CapValue

Sheet Loan Sizing
A1: Loan Sizing — LTV / DSCR / Debt Yield
B3: Sizing follows lender-terms conventions exactly: LTV on UW NOI/cap; DSCR on UW NCF over amortizing DS at sizing rate; DY on UW NCF over loan.
B5: Rate & amortization inputs
B6: Contract rate | C6: =ContractRate | E6: Sources & Uses
B7: Sizing rate | C7: =SizingRate | E7: SOURCES
B8: Amortization (years) | C8: =AmortYears | E8: New first mortgage | F8: =MaxLoan
B9: Monthly amort factor | C9: =(SizingRate/12)/(1-(1+SizingRate/12)^(-AmortYears*12)) | E9: Sponsor cash (if any) | F9: =MAX(0,-F19)
B10: Annual debt constant | E10: Total sources | F10: =SUM(F8:F9)
B11: = 12 × monthly factor | C11: =C9*12
E12: USES
B13: LTV max loan = LTVmax × CapValue | C13: =LTVmax*CapValue | E13: Existing debt payoff | F13: =ExistingPayoff
B14: DSCR max loan = UW NCF / (DSCRmin × ADC) | C14: =UW_NCF/(DSCRmin*ADC) | E14: Origination fee | F14: =MaxLoan*OrigFeePct
B15: DY max loan = UW NCF / DYmin | C15: =UW_NCF/DYmin | E15: Fixed closing costs | F15: =FixedCosts
E16: Cash to borrower (out) | F16: =MAX(0,F19)
B17: MAXIMUM LOAN (min of three) | C17: =MIN(C13:C15) | E17: Total uses | F17: =SUM(F13:F16)
B18: Binding constraint | C18: =INDEX({"LTV","DSCR","Debt yield"},MATCH(C17,C13:C15,0))
E19: Cash to / (from) borrower | F19: =MaxLoan-ExistingPayoff-MaxLoan*OrigFeePct-FixedCosts
B20: Sizing metrics at maximum loan
B21: Annual DS (amortizing, sizing rate) | C21: =MaxLoan*ADC
B22: Sizing DSCR (NCF / amort DS) | C22: =UW_NCF/C21
B23: Sizing debt yield (NCF / loan) | C23: =UW_NCF/MaxLoan
B24: Actual LTV (loan / cap value) | C24: =MaxLoan/CapValue
B25: First-year contractual DS (IO @ contract rate) | C25: =MaxLoan*ContractRate
B31: Cash to / (from) borrower (negative = cash-in) | C31: =F19

Sheet Sensitivity
A1: Sensitivity — combined downside & cap-rate shock
B3: A. Combined downside: EGI −5% AND sizing rate +100 bps (cap rate held constant) | E3: B. Cap rate +50 bps (standalone) — NOI and sizing rate unchanged
B5: Stressed EGI | C5: =UW_EGI*0.95 | E5: Stressed cap rate | F5: =CapRate+0.005
B6: Stressed mgmt fee | C6: =MAX(MgmtDollarFloor,C5*MgmtPct) | E6: Stressed cap value | F6: =UW_NOI/F5
B7: Stressed OpEx (ex. mgmt) + stressed mgmt | C7: =(UW_OpEx-UW_MgmtFee)+C6
B8: Stressed NOI (before reserves) | C8: =C5-C7 | E8: LTV limit | F8: =LTVmax*F6
B9: Stressed NCF (after reserves) | C9: =C8-UW_Reserves | E9: DSCR limit (unchanged) | F9: =UW_NCF/(DSCRmin*ADC)
E10: DY limit (unchanged) | F10: =UW_NCF/DYmin
B11: Stressed cap value (cap rate unchanged) | C11: =C8/CapRate
B12: Stressed sizing rate (+100 bps) | C12: =SizingRate+0.01 | E12: Cap+50 MAX LOAN | F12: =MIN(F8:F10)
B13: Stressed annual debt constant | C13: =12*((C12/12)/(1-(1+C12/12)^(-AmortYears*12))) | E13: Binding | F13: =INDEX({"LTV","DSCR","Debt yield"},MATCH(F12,F8:F10,0))
B15: LTV limit | C15: =LTVmax*C11 | E15: Δ vs base (max loan) | F15: =F12-MaxLoan
B16: DSCR limit | C16: =C9/(DSCRmin*C13)
B17: DY limit | C17: =C9/DYmin
B19: Combined-downside MAX LOAN | C19: =MIN(C15:C17)
B20: Binding | C20: =INDEX({"LTV","DSCR","Debt yield"},MATCH(C19,C15:C17,0))
B22: Δ vs base (max loan) | C22: =C19 | E22: → Cap+50 MAX LOAN (anchor) | F22: =F12 | G22: =F12
B23: → Combined-downside MAX LOAN (anchor)

Sheet Rent Roll
A1: Rent Roll — as of 2026-08-31
B3: Unit | C3: Tenant | D3: Area SF | E3: Status | F3: Monthly base | G3: Market rent | H3: Lease expiry
B4: 101 | C4: Household 101 | D4: 700 | E4: Occupied | F4: 1575 | G4: 1575
B5: 102 | C5: Household 102 | D5: 700 | E5: Occupied | F5: 1575 | G5: 1575
B6: 103 | C6: Household 103 | D6: 700 | E6: Occupied | F6: 1575 | G6: 1575
B7: 104 | C7: Household 104 | D7: 700 | E7: Occupied | F7: 1575 | G7: 1575
B8: 105 | C8: Household 105 | D8: 700 | E8: Occupied | F8: 1575 | G8: 1575
B9: 106 | C9: Household 106 | D9: 700 | E9: Occupied | F9: 1575 | G9: 1575
B10: 107 | C10: Household 107 | D10: 700 | E10: Occupied | F10: 1575 | G10: 1575
B11: 108 | C11: Household 108 | D11: 700 | E11: Occupied | F11: 1575 | G11: 1575
B12: 109 | C12: Household 109 | D12: 700 | E12: Occupied | F12: 1575 | G12: 1575
B13: 110 | C13: Household 110 | D13: 700 | E13: Occupied | F13: 1575 | G13: 1575
B14: 111 | C14: Household 111 | D14: 700 | E14: Occupied | F14: 1575 | G14: 1575
B15: 112 | C15: Household 112 | D15: 700 | E15: Occupied | F15: 1575 | G15: 1575
... B27: 124 | C27: Household 124 | D27: 700 | E27: Occupied | F27: 1575 | G27: 1575
B28: 125 | C28: Household 125 | D28: 1100 | E28: Occupied | F28: 2025 | G28: 2025 | H28: 2026-09-30
B29: 126 | C29: Household 126 | D29: 1100 | E29: Occupied | F29: 2025 | G29: 2025 | H29: 2026-10-31
B30: 127 | C30: Household 127 | D30: 1100 | E30: Occupied | F30: 2025 | G30: 2025 | H30: 2026-11-30
B31: 128 | C31: Household 128 | D31: 1100 | E31: Occupied | F31: 2025 | G31: 2025 | H31: 2026-12-31
B32: 129 | C32: Household 129 | D32: 1100 | E32: Occupied | F32: 2025 | G32: 2025 | H32: 2027-01-31
B33: 130 | C33: Household 130 | D33: 1100 | E33: Occupied | F33: 2025 | G33: 2025 | H33: 2027-02-28
B34: 131 | C34: Household 131 | D34: 1100 | E34: Occupied | F34: 2025 | G34: 2025 | H34: 2027-03-31
B35: 132 | C35: Household 132 | D35: 1100 | E35: Occupied | F35: 2025 | G35: 2025 | H35: 2027-04-30
B36: 133 | C36: Household 133 | D36: 1100 | E36: Occupied | F36: 2025 | G36: 2025 | H36: 2027-05-31
B37: 134 | C37: Vacant | D37: 1100 | E37: Vacant | G37: 2025
B38: 135 | C38: Vacant | D38: 1100 | E38: Vacant | G38: 2025
B39: 136 | C39: Vacant | D39: 1100 | E39: Vacant | G39: 2025
B40: 137 | C40: Vacant | D40: 1100 | E40: Vacant | G40: 2025
B41: 138 | C41: Vacant | D41: 1100 | E41: Vacant | G41: 2025
B42: 139 | C42: Vacant | D42: 1100 | E42: Vacant | G42: 2025
B43: 140 | C43: Vacant | D43: 1100 | E43: Vacant | G43: 2025
B44: 141 | C44: Vacant | D44: 1100 | E44: Vacant | G44: 2025
B45: 142 | C45: Vacant | D45: 1100 | E45: Vacant | G45: 2025
B46: 143 | C46: Vacant | D46: 1100 | E46: Vacant | G46: 2025
B47: 144 | C47: Vacant | D47: 1100 | E47: Vacant | G47: 2025
B48: 145 | C48: Vacant | D48: 1100 | E48: Vacant | G48: 2025
... B51: 148 | C51: Vacant | D51: 1100 | E51: Vacant | G51: 2025
B53: Totals | D53: =SUM(D4:D51) | F53: =SUM(F4:F51)
B54: Occupied units | D54: =COUNTIF(E4:E51,"Occupied")
B55: Vacant units | D55: =COUNTIF(E4:E51,"Vacant")
...

Sheet Field IDs
A1: Requested Analysis Fields
B3: Field ID | C3: Value | D3: Basis / source
B4: space_count | C4: 48 | D4: Rent-Roll.xlsx — 48 unit rows (101-148)
B5: occupied_count | C5: 33 | D5: Rent-Roll.xlsx — Status='Occupied'
B6: total_area_sf | C6: 43200 | D6: 24×700 + 24×1100
B7: occupied_area_sf | C7: 26700 | D7: 24×700 + 9×1100
B8: occupancy_count_pct | C8: =100*33/48 | D8: =68.75%
B9: occupancy_area_pct | C9: =100*26700/43200 | D9: =61.8056%
B10: rent_roll_monthly_base | C10: =24*1575+9*2025 | D10: occupied units only; vacants blank
B11: effective_monthly_base | C11: =24*1575+9*2025 | D11: Lease-File p.1 confirms unit 101 rent = $1,575/mo; no amendments in packet
B12: t12_egi | C12: =T12_EGI | D12: T12-Statement.pdf p.2 annual
B13: t12_operating_expenses | C13: =T12_OpEx | D13: T12 opex ex reserves/capex/debt/depreciation
B14: t12_noi_before_reserves | C14: =T12_NOI | D14: T12 EGI − OpEx
B15: t12_reserves | C15: 14400 | D15: T12 replacement reserves (below-NOI)
B16: t12_ncf | C16: =T12_NCF | D16: T12 NOI − reserves
B17: uw_egi | C17: =UW_EGI | D17: UW_GPR × (1-RevLoss) + OtherInc
B18: uw_management_fee | C18: =UW_MgmtFee | D18: MAX(T12 $28,000; 3.50% × UW EGI)
B19: uw_operating_expenses | C19: =UW_OpEx | D19: Per Property-and-Plan p.2 line-item instructions
B20: uw_noi_before_reserves | C20: =UW_NOI | D20: UW EGI − UW OpEx
B21: uw_reserves | C21: =UW_Reserves | D21: 48 units × $325
B22: uw_ncf | C22: =UW_NCF | D22: UW NOI − reserves
B23: capitalization_value | C23: =CapValue | D23: UW NOI ÷ 5.75% cap
B24: contract_rate | C24: =ContractRate | D24: Lender-Terms p.1
B25: sizing_rate | C25: =SizingRate | D25: MAX(contract, 6.50% floor)
B26: annual_debt_constant | C26: =ADC | D26: 30-yr amort, monthly pmts, sizing rate
B27: ltv_limit | C27: ='Loan Sizing'!C13 | D27: 60% × CapValue
B28: dscr_limit | C28: ='Loan Sizing'!C14 | D28: UW NCF ÷ (1.30 × ADC)
B29: debt_yield_limit | C29: ='Loan Sizing'!C15 | D29: UW NCF ÷ 9%
B30: maximum_loan | C30: =MaxLoan | D30: MIN of three
B31: binding_constraint | C31: ='Loan Sizing'!C18 | D31: DSCR at base case
B32: sizing_annual_debt_service | C32: ='Loan Sizing'!C21 | D32: MaxLoan × ADC
B33: sizing_dscr | C33: ='Loan Sizing'!C22 | D33: =1.30x by construction
B34: sizing_debt_yield | C34: ='Loan Sizing'!C23 | D34: =UW NCF ÷ MaxLoan
B35: first_year_debt_service | C35: ='Loan Sizing'!C25 | D35: IO for 36 mo — MaxLoan × ContractRate
B36: cash_to_borrower | C36: ='Loan Sizing'!F19 | D36: MaxLoan − payoff − orig fee − closing
B37: stress_uw_noi | C37: =Sensitivity!C8 | D37: Combined-downside NOI
B38: stress_maximum_loan | C38: =Sensitivity!C19 | D38: Combined-downside MAX LOAN
B39: subject_lease_monthly_rent | C39: 1575 | D39: Lease-File.pdf §3
B40: subject_lease_expiry | C40: 2027-06-30 | D40: Lease-File.pdf §2 (initial term)
B41: subject_lease_deposit | C41: 1200 | D41: Lease-File.pdf §4
...
