Workbook

Sheet UW Rev
A1: Magnolia Terrace - Underwriting (Revised 2026-09-01)
A3: As of date | B3: 2026-09-01
A4: Gross potential rent (annual) | B4: 977100
A5: Economic loss % | B5: 0.05
A6: Cap rate | B6: 0.065
A7: Total units/suites | B7: 48
A8: Other income per unit (annual) | B8: 350
A9: Other income (annual) | B9: =B7*B8
A10: Real estate tax expense | B10: 102312
A11: Insurance expense | B11: 34104
A12: Other recurring opex | B12: 136416
A13: Management fee % of EGI | B13: 0.03
A14: Replacement reserve per unit (annual) | B14: 300
A15: Existing payoff | B15: 4200000
A16: Closing costs | B16: 45000
A17: Origination fee % | B17: 0.01
A18: Max LTV | B18: 0.65
A19: Min DSCR | B19: 1.25
A20: Min debt yield | B20: 0.09
A21: Amortization (years) | B21: 30
... A24: Sizing rate (used) | B24: 0.07
A26: Gross potential rent (annual) | B26: =B4
A27: Economic loss | B27: =B26*B5
A28: Other income (annual) | B28: =B9
A29: Underwritten EGI | B29: =B26-B27+B28
A31: Management fee | B31: =B29*B13
A32: Real estate tax expense | B32: =B10
A33: Insurance expense | B33: =B11
A34: Other recurring opex | B34: =B12
A35: Total opex before reserves | B35: =SUM(B31:B34)
A36: UW NOI (before reserves) | B36: =B29-B35
A37: Replacement reserves | B37: =B7*B14
A38: UW NCF (after reserves) | B38: =B36-B37
A39: Capitalization value | B39: =B36/B6
A41: LTV limit | B41: =B39*B18
A42: Monthly sizing rate | B42: =B24/12
A43: Term (months) | B43: =B21*12
A44: Payment per $1 (PMT monthly) | B44: =-PMT(B42,B43,1)
A45: ADS at DSCR (annual) | B45: =B38/B19
A46: DSCR limit | B46: =B45/12/B44
...

Sheet Sensitivity Rev
A1: Maximum Loan Sensitivity (Revised)
A3: Cap rate ↓ | Sizing rate → | B3: 0.07 | C3: 0.075 | D3: 0.08
A4: 0.055 | B4: =MIN(('UW Rev'!B36/A4)*'UW Rev'!B18, ('UW Rev'!B38/'UW Rev'!B19)/12/(-PMT(B3/12,'UW Rev'!B43,1)), 'UW Rev'!B38/'UW Rev'!B20) | C4: =MIN(('UW Rev'!B36/A4)*'UW Rev'!B18, ('UW Rev'!B38/'UW Rev'!B19)/12/(-PMT(C3/12,'UW Rev'!B43,1)), 'UW Rev'!B38/'UW Rev'!B20) | D4: =MIN(('UW Rev'!B36/A4)*'UW Rev'!B18, ('UW Rev'!B38/'UW Rev'!B19)/12/(-PMT(D3/12,'UW Rev'!B43,1)), 'UW Rev'!B38/'UW Rev'!B20)
A5: 0.06 | B5: =MIN(('UW Rev'!B36/A5)*'UW Rev'!B18, ('UW Rev'!B38/'UW Rev'!B19)/12/(-PMT(B3/12,'UW Rev'!B43,1)), 'UW Rev'!B38/'UW Rev'!B20) | C5: =MIN(('UW Rev'!B36/A5)*'UW Rev'!B18, ('UW Rev'!B38/'UW Rev'!B19)/12/(-PMT(C3/12,'UW Rev'!B43,1)), 'UW Rev'!B38/'UW Rev'!B20) | D5: =MIN(('UW Rev'!B36/A5)*'UW Rev'!B18, ('UW Rev'!B38/'UW Rev'!B19)/12/(-PMT(D3/12,'UW Rev'!B43,1)), 'UW Rev'!B38/'UW Rev'!B20)
A6: 0.065 | B6: =MIN(('UW Rev'!B36/A6)*'UW Rev'!B18, ('UW Rev'!B38/'UW Rev'!B19)/12/(-PMT(B3/12,'UW Rev'!B43,1)), 'UW Rev'!B38/'UW Rev'!B20) | C6: =MIN(('UW Rev'!B36/A6)*'UW Rev'!B18, ('UW Rev'!B38/'UW Rev'!B19)/12/(-PMT(C3/12,'UW Rev'!B43,1)), 'UW Rev'!B38/'UW Rev'!B20) | D6: =MIN(('UW Rev'!B36/A6)*'UW Rev'!B18, ('UW Rev'!B38/'UW Rev'!B19)/12/(-PMT(D3/12,'UW Rev'!B43,1)), 'UW Rev'!B38/'UW Rev'!B20)
A8: Max Loan ($)

Sheet Sources Rev
A1: Source register (Revised)
A3: Document | B3: Location (page / cell) | C3: Key data used
A4: revision-notice.pdf | B4: p.1 | C4: Suite 045 now active at +$225/mo; increase sizing rate +75 bps; cap rate +25 bps; new roll date 2026-09-01; other rules unchanged
A5: rent-roll-revised.xlsx | B5: B2; A5:G52 | C5: Certified roll superseding prior: 45 active, 3 vacant; Unit 045 now active at $2,150/mo
